Workbook

Sheet Resumo
A1: Cruzamento | B1: Rua Padre Machado x Rua Hermenegildo Lima | Itamaracá
A2: Data | B2: 46142
A3: Coordenadas Geográficas | B3: -7.74776,-34.82463
A4: Relatório
A5: Total | B5: =Dados!R15 -> 1631
A6: Máximo em um hora | B6: =MAX(Dados!D15:Q15) -> 176
A7: Mulher | B7: =Dados!S20 -> 0.17719191
A8: Crianças e adolescentes | B8: =Dados!S21 -> 0.091968118
A9: Capacete | B9: =Dados!S22 -> 0.0030656039
A10: Caronas | B10: =Dados!S51 -> 0.025137952
A11: Cargueiras | B11: =Dados!S52 -> 0.23482526
A12: Serviço | B12: =Dados!S53 -> 0.0055180871
A13: Contramão | B13: =Dados!S54 -> 0.055180871
A14: Calçada | B14: =Dados!S32 -> 0.064990803

Sheet Dados
A1: , | B1: Dados quantitativos e sentido de deslocamento
B2: ORIGEM | C2: DESTINO | D2: 6 | E2: 7 | F2: 8 | G2: 9 | H2: 10 | I2: 11 | J2: 12 | K2: 13 | L2: 14 | M2: 15 | N2: 16 | O2: 17 | P2: 18 | Q2: 19 | R2: TOTAL | S2: %
B3: Jaguaribe | C3: Biquinha | D3: 1 | E3: 7 | F3: 14 | G3: 14 | H3: 16 | I3: 15 | J3: 15 | K3: 4 | L3: 13 | M3: 14 | N3: 14 | O3: 22 | P3: 14 | Q3: 8 | R3: =SUM(D3:Q3) -> 171 | S3: =R3/$R$15 -> 0.10484365
B4: Jaguaribe | C4: Forte Orange | D4: 22 | E4: 30 | F4: 36 | G4: 21 | H4: 26 | I4: 22 | J4: 14 | K4: 19 | L4: 22 | M4: 20 | N4: 20 | O4: 22 | P4: 17 | Q4: 15 | R4: =SUM(D4:Q4) -> 306 | S4: =R4/$R$15 -> 0.18761496
B5: Jaguaribe | C5: Mar | D5: 3 | E5: 5 | F5: 6 | G5: 4 | H5: 2 | I5: 1 | J5: 2 | K5: 0 | L5: 3 | M5: 3 | N5: 1 | O5: 2 | P5: 0 | Q5: 0 | R5: =SUM(D5:Q5) -> 32 | S5: =R5/$R$15 -> 0.019619865
B6: Mar | C6: Jaguaribe | D6: 1 | E6: 9 | F6: 11 | G6: 4 | H6: 6 | I6: 8 | J6: 2 | K6: 2 | L6: 2 | M6: 2 | N6: 5 | O6: 2 | P6: 2 | Q6: 0 | R6: =SUM(D6:Q6) -> 56 | S6: =R6/$R$15 -> 0.034334764
B7: Mar | C7: Biquinha | D7: 2 | E7: 3 | F7: 6 | G7: 7 | H7: 5 | I7: 9 | J7: 6 | K7: 2 | L7: 3 | M7: 5 | N7: 5 | O7: 4 | P7: 4 | Q7: 0 | R7: =SUM(D7:Q7) -> 61 | S7: =R7/$R$15 -> 0.037400368
B8: Mar | C8: Forte Orange | D8: 3 | E8: 4 | F8: 6 | G8: 5 | H8: 9 | I8: 14 | J8: 2 | K8: 3 | L8: 4 | M8: 3 | N8: 2 | O8: 2 | P8: 1 | Q8: 0 | R8: =SUM(D8:Q8) -> 58 | S8: =R8/$R$15 -> 0.035561006
B9: Forte Orange | C9: Mar | D9: 3 | E9: 9 | F9: 6 | G9: 7 | H9: 6 | I9: 6 | J9: 3 | K9: 2 | L9: 2 | M9: 4 | N9: 4 | O9: 2 | P9: 0 | Q9: 0 | R9: =SUM(D9:Q9) -> 54 | S9: =R9/$R$15 -> 0.033108522
B10: Forte Orange | C10: Jaguaribe | D10: 17 | E10: 32 | F10: 37 | G10: 29 | H10: 29 | I10: 15 | J10: 24 | K10: 17 | L10: 22 | M10: 17 | N10: 24 | O10: 43 | P10: 24 | Q10: 15 | R10: =SUM(D10:Q10) -> 345 | S10: =R10/$R$15 -> 0.21152667
B11: Forte Orange | C11: Biquinha | D11: 4 | E11: 4 | F11: 6 | G11: 10 | H11: 1 | I11: 15 | J11: 13 | K11: 9 | L11: 12 | M11: 18 | N11: 14 | O11: 31 | P11: 19 | Q11: 9 | R11: =SUM(D11:Q11) -> 165 | S11: =R11/$R$15 -> 0.10116493
B12: Biquinha | C12: Forte Orange | D12: 11 | E12: 15 | F12: 16 | G12: 13 | H12: 16 | I12: 9 | J12: 13 | K12: 3 | L12: 8 | M12: 4 | N12: 21 | O12: 15 | P12: 11 | Q12: 5 | R12: =SUM(D12:Q12) -> 160 | S12: =R12/$R$15 -> 0.098099326
B13: Biquinha | C13: Mar | D13: 7 | E13: 5 | F13: 10 | G13: 11 | H13: 2 | I13: 10 | J13: 2 | K13: 0 | L13: 5 | M13: 3 | N13: 6 | O13: 1 | P13: 1 | Q13: 0 | R13: =SUM(D13:Q13) -> 63 | S13: =R13/$R$15 -> 0.038626609
B14: Biquinha | C14: Jaguaribe | D14: 7 | E14: 4 | F14: 22 | G14: 18 | H14: 10 | I14: 13 | J14: 7 | K14: 7 | L14: 10 | M14: 12 | N14: 19 | O14: 16 | P14: 11 | Q14: 4 | R14: =SUM(D14:Q14) -> 160 | S14: =R14/$R$15 -> 0.098099326
C15: TOTAL | D15: =SUM(D3:D14) -> 81 | E15: =SUM(E3:E14) -> 127 | F15: =SUM(F3:F14) -> 176 | G15: =SUM(G3:G14) -> 143 | H15: =SUM(H3:H14) -> 128 | I15: =SUM(I3:I14) -> 137 | J15: =SUM(J3:J14) -> 103 | K15: =SUM(K3:K14) -> 68 | ... Q15: =SUM(Q3:Q14) -> 56 | R15: =SUM(R$3:R$14) -> 1631
C16: Percentual | D16: =D15/$R$15 -> 0.049662784 | E16: =E15/$R$15 -> 0.07786634 | F16: =F15/$R$15 -> 0.10790926 | G16: =G15/$R$15 -> 0.087676272 | H16: =H15/$R$15 -> 0.07847946 | I16: =I15/$R$15 -> 0.083997548 | J16: =J15/$R$15 -> 0.063151441 | K16: =K15/$R$15 -> 0.041692213 | ... Q16: =Q15/$R$15 -> 0.034334764 | R16: =SUM(D16:Q16) -> 1
C18: Dados qualitativos padrões
C19: Característica | D19: 6 | E19: 7 | F19: 8 | G19: 9 | H19: 10 | I19: 11 | J19: 12 | K19: 13 | L19: 14 | M19: 15 | N19: 16 | O19: 17 | P19: 18 | Q19: 19 | R19: TOTAL | S19: %
C20: Mulher | D20: 10 | E20: 21 | F20: 39 | G20: 35 | H20: 28 | I20: 34 | J20: 17 | K20: 11 | L20: 22 | M20: 19 | N20: 16 | O20: 18 | P20: 12 | Q20: 7 | R20: =SUM(D20:Q20) -> 289 | S20: =R20/$R$15 -> 0.17719191
C21: Crianças e adolescentes | D21: 4 | E21: 15 | F21: 4 | G21: 8 | H21: 14 | I21: 9 | J21: 16 | K21: 8 | L21: 8 | M21: 8 | N21: 13 | O21: 20 | P21: 15 | Q21: 8 | R21: =SUM(D21:Q21) -> 150 | S21: =R21/$R$15 -> 0.091968118
C22: Capacete | D22: 0 | E22: 1 | F22: 0 | G22: 1 | H22: 2 | I22: 1 | J22: 0 | K22: 0 | L22: 0 | M22: 0 | N22: 0 | O22: 0 | P22: 0 | Q22: 0 | R22: =SUM(D22:Q22) -> 5 | S22: =R22/$R$15 -> 0.0030656039
C23: Carona criança | D23: 4 | E23: 3 | F23: 1 | G23: 2 | H23: 3 | I23: 5 | J23: 5 | K23: 2 | L23: 3 | M23: 1 | N23: 1 | O23: 0 | P23: 0 | Q23: 0 | R23: =SUM(D23:Q23) -> 30 | S23: =R23/$R$15 -> 0.018393624
C24: Carona mulher | D24: 1 | E24: 2 | F24: 1 | G24: 0 | H24: 1 | I24: 0 | J24: 0 | K24: 0 | L24: 1 | M24: 1 | N24: 2 | O24: 0 | P24: 2 | Q24: 0 | R24: =SUM(D24:Q24) -> 11 | S24: =R24/$R$15 -> 0.0067443286
C25: Carona homem | D25: 0 | E25: 0 | F25: 0 | G25: 0 | H25: 0 | I25: 0 | J25: 0 | K25: 0 | L25: 0 | M25: 0 | N25: 0 | O25: 0 | P25: 0 | Q25: 0 | R25: =SUM(D25:Q25) -> 0 | S25: =R25/$R$15 -> 0
C26: Cargueira tradicional | D26: 6 | E26: 15 | F26: 5 | G26: 12 | H26: 12 | I26: 12 | J26: 5 | K26: 2 | L26: 9 | M26: 8 | N26: 14 | O26: 12 | P26: 8 | Q26: 2 | R26: =SUM(D26:Q26) -> 122 | S26: =R26/$R$15 -> 0.074800736
C27: Adaptada a carga | D27: 16 | E27: 27 | F27: 45 | G27: 37 | H27: 20 | I27: 20 | J27: 17 | K27: 11 | L27: 15 | M27: 15 | N27: 16 | O27: 15 | P27: 3 | Q27: 4 | R27: =SUM(D27:Q27) -> 261 | S27: =R27/$R$15 -> 0.16002452
C28: Serviço | D28: 0 | E28: 0 | F28: 0 | G28: 2 | H28: 1 | I28: 0 | J28: 2 | K28: 1 | L28: 0 | M28: 0 | N28: 1 | O28: 1 | P28: 1 | Q28: 0 | R28: =SUM(D28:Q28) -> 9 | S28: =R28/$R$15 -> 0.0055180871
C29: Serviço APP | D29: 0 | E29: 0 | F29: 0 | G29: 0 | H29: 0 | I29: 0 | J29: 0 | K29: 0 | L29: 0 | M29: 0 | N29: 0 | O29: 0 | P29: 0 | Q29: 0 | R29: =SUM(D29:Q29) -> 0 | S29: =R29/$R$15 -> 0
C30: Contramão | D30: 6 | E30: 1 | F30: 5 | G30: 1 | H30: 3 | I30: 2 | J30: 7 | K30: 1 | L30: 7 | M30: 6 | N30: 6 | O30: 7 | P30: 3 | Q30: 3 | R30: =SUM(D30:Q30) -> 58 | S30: =R30/$R$15 -> 0.035561006
C31: Contramão para conversão | D31: 1 | E31: 1 | F31: 0 | G31: 0 | H31: 1 | I31: 0 | J31: 2 | K31: 3 | L31: 4 | M31: 1 | N31: 2 | O31: 7 | P31: 9 | Q31: 1 | R31: =SUM(D31:Q31) -> 32 | S31: =R31/$R$15 -> 0.019619865
C32: Calçada | D32: 3 | E32: 11 | F32: 6 | G32: 0 | H32: 12 | I32: 7 | J32: 13 | K32: 2 | L32: 7 | M32: 7 | N32: 15 | O32: 8 | P32: 8 | Q32: 7 | R32: =SUM(D32:Q32) -> 106 | S32: =R32/$R$15 -> 0.064990803
C35: Dados qualitativos das observações
C36: Característica | D36: 6 | E36: 7 | F36: 8 | G36: 9 | H36: 10 | I36: 11 | J36: 12 | K36: 13 | L36: 14 | M36: 15 | N36: 16 | O36: 17 | P36: 18 | Q36: 19 | R36: TOTAL | S36: %
C37: Bike PE | R37: =SUM(D37:Q37) -> 0 | S37: =R37/$R$15 -> 0
C38: Empurrando | D38: 2 | F38: 8 | G38: 12 | H38: 15 | I38: 10 | J38: 8 | K38: 5 | L38: 4 | M38: 12 | N38: 8 | O38: 8 | P38: 1 | Q38: 1 | R38: =SUM(D38:Q38) -> 94 | S38: =R38/$R$15 -> 0.057633354
C39: Triciclo | F39: 1 | G39: 2 | N39: 1 | O39: 1 | R39: =SUM(D39:Q39) -> 5 | S39: =R39/$R$15 -> 0.0030656039
C40: Carroça | R40: =SUM(D40:Q40) -> 0 | S40: =R40/$R$15 -> 0
C41: Elétrica | E41: 2 | G41: 3 | H41: 4 | I41: 4 | R41: =SUM(D41:Q41) -> 13 | S41: =R41/$R$15 -> 0.0079705702
C42: Motorizada | H42: 2 | I42: 1 | M42: 2 | O42: 1 | Q42: 1 | R42: =SUM(D42:Q42) -> 7 | S42: =R42/$R$15 -> 0.0042918455
C43: Skate e outros patináveis | R43: =SUM(D43:Q43) -> 0 | S43: =R43/$R$15 -> 0
...

Sheet CONFFLUXO
A1: =Fluxo!A2 -> TOTAL | F1: 2 | G1: {=TRANSPOSE(Dados!2:2)}
F2: 3 | G2: ORIGEM
A3: =Dados!B3 -> Jaguaribe | B3: =Dados!C3 -> Biquinha | F3: 4 | G3: DESTINO | Q3: =HLOOKUP($A$1,Dados!$D$2:$S$14,F1,0) -> 171
A4: =Dados!B4 -> Jaguaribe | B4: =Dados!C4 -> Forte Orange | F4: 5 | G4: 6 | Q4: =HLOOKUP($A$1,Dados!$D$2:$S$14,F2,0) -> 306
A5: =Dados!B5 -> Jaguaribe | B5: =Dados!C5 -> Mar | F5: 6 | G5: 7 | Q5: =HLOOKUP($A$1,Dados!$D$2:$S$14,F3,0) -> 32
A6: =Dados!B6 -> Mar | B6: =Dados!C6 -> Jaguaribe | F6: 7 | G6: 8 | Q6: =HLOOKUP($A$1,Dados!$D$2:$S$14,F4,0) -> 56
A7: =Dados!B7 -> Mar | B7: =Dados!C7 -> Biquinha | F7: 8 | G7: 9 | Q7: =HLOOKUP($A$1,Dados!$D$2:$S$14,F5,0) -> 61
A8: =Dados!B8 -> Mar | B8: =Dados!C8 -> Forte Orange | F8: 9 | G8: 10 | Q8: =HLOOKUP($A$1,Dados!$D$2:$S$14,F6,0) -> 58
A9: =Dados!B9 -> Forte Orange | B9: =Dados!C9 -> Mar | F9: 10 | G9: 11 | Q9: =HLOOKUP($A$1,Dados!$D$2:$S$14,F7,0) -> 54
A10: =Dados!B10 -> Forte Orange | B10: =Dados!C10 -> Jaguaribe | F10: 11 | G10: 12 | Q10: =HLOOKUP($A$1,Dados!$D$2:$S$14,F8,0) -> 345
A11: =Dados!B11 -> Forte Orange | B11: =Dados!C11 -> Biquinha | F11: 12 | G11: 13 | Q11: =HLOOKUP($A$1,Dados!$D$2:$S$14,F9,0) -> 165
A12: =Dados!B12 -> Biquinha | B12: =Dados!C12 -> Forte Orange | F12: 13 | G12: 14 | Q12: =HLOOKUP($A$1,Dados!$D$2:$S$14,F10,0) -> 160
A13: =Dados!B13 -> Biquinha | B13: =Dados!C13 -> Mar | G13: 15 | Q13: =HLOOKUP($A$1,Dados!$D$2:$S$14,F11,0) -> 63
A14: =Dados!B14 -> Biquinha | B14: =Dados!C14 -> Jaguaribe | G14: 16 | Q14: =HLOOKUP($A$1,Dados!$D$2:$S$14,F12,0) -> 160
G15: 17
G16: 18
G17: 19
G18: TOTAL
G19: %

Sheet Gráficos
A1: Ciclistas por hora
A2: Horário início | B2: =Dados!D2 -> 6 | C2: =Dados!E2 -> 7 | D2: =Dados!F2 -> 8 | E2: =Dados!G2 -> 9 | F2: =Dados!H2 -> 10 | G2: =Dados!I2 -> 11 | H2: =Dados!J2 -> 12 | I2: =Dados!K2 -> 13 | ... O2: =Dados!Q2 -> 19
A3: Homens | B3: =Dados!D15-B4-B5 -> 67 | C3: =Dados!E15-C4-C5 -> 91 | D3: =Dados!F15-D4-D5 -> 133 | E3: =Dados!G15-E4-E5 -> 100 | F3: =Dados!H15-F4-F5 -> 86 | G3: =Dados!I15-G4-G5 -> 94 | H3: =Dados!J15-H4-H5 -> 70 | I3: =Dados!K15-I4-I5 -> 49 | ... O3: =Dados!Q15-O4-O5 -> 41
A4: Mulheres | B4: =Dados!D20 -> 10 | C4: =Dados!E20 -> 21 | D4: =Dados!F20 -> 39 | E4: =Dados!G20 -> 35 | F4: =Dados!H20 -> 28 | G4: =Dados!I20 -> 34 | H4: =Dados!J20 -> 17 | I4: =Dados!K20 -> 11 | ... O4: =Dados!Q20 -> 7
A5: Crianças e adolescentes | B5: =Dados!D21 -> 4 | C5: =Dados!E21 -> 15 | D5: =Dados!F21 -> 4 | E5: =Dados!G21 -> 8 | F5: =Dados!H21 -> 14 | G5: =Dados!I21 -> 9 | H5: =Dados!J21 -> 16 | I5: =Dados!K21 -> 8 | ... O5: =Dados!Q21 -> 8
A7: Ciclistas por hora %
A8: Horário | B8: 6 | C8: 7 | D8: 8 | E8: 9 | F8: 10 | G8: 11 | H8: 12 | I8: 13 | J8: 14 | K8: 15 | L8: 16 | M8: 17 | N8: 18 | O8: 19
A9: Mulheres | B9: =B4/Dados!D$15 -> 0.12345679 | C9: =C4/Dados!E$15 -> 0.16535433 | D9: =D4/Dados!F$15 -> 0.22159091 | E9: =E4/Dados!G$15 -> 0.24475524 | F9: =F4/Dados!H$15 -> 0.21875 | G9: =G4/Dados!I$15 -> 0.24817518 | H9: =H4/Dados!J$15 -> 0.16504854 | I9: =I4/Dados!K$15 -> 0.16176471 | ... O9: =O4/Dados!Q$15 -> 0.125
A10: Crianças e adolescentes | B10: =B5/Dados!D$15 -> 0.049382716 | C10: =C5/Dados!E$15 -> 0.11811024 | D10: =D5/Dados!F$15 -> 0.022727273 | E10: =E5/Dados!G$15 -> 0.055944056 | F10: =F5/Dados!H$15 -> 0.109375 | G10: =G5/Dados!I$15 -> 0.065693431 | H10: =H5/Dados!J$15 -> 0.15533981 | I10: =I5/Dados!K$15 -> 0.11764706 | ... O10: =O5/Dados!Q$15 -> 0.14285714
A12: =Dados!C19 -> Característica | B12: =Dados!S19 -> %
A13: =Dados!C20 -> Mulher | B13: =Dados!S20 -> 0.17719191
A14: =Dados!C21 -> Crianças e adolescentes | B14: =Dados!S21 -> 0.091968118
A15: =Dados!C22 -> Capacete | B15: =Dados!S22 -> 0.0030656039
A16: Caronas | B16: =Dados!S51 -> 0.025137952
A17: =Dados!C35 -> Dados qualitativos das observações | B17: =Dados!S35
A18: =Dados!C54 -> Contramão | B18: =Dados!S54 -> 0.055180871
A19: =Dados!C32 -> Calçada | B19: =Dados!S32 -> 0.064990803
A20: =Dados!C52 -> Cargueiras | B20: =Dados!S52 -> 0.23482526

Sheet Fluxo
A1: HORÁRIO | E1: =UPPER(CONFFLUXO!A3) -> JAGUARIBE
A2: TOTAL | E2: =SUM(E3:G3) -> 509
E3: =CONFFLUXO!Q3 -> 171 | F3: =CONFFLUXO!Q4 -> 306 | G3: =CONFFLUXO!Q5 -> 32
A5: =UPPER(CONFFLUXO!A12) -> BIQUINHA | B5: =SUM(C5:C7) -> 383 | C5: =CONFFLUXO!Q14 -> 160 | I5: =CONFFLUXO!Q6 -> 56 | J5: =SUM(I5:I7) -> 175 | K5: =UPPER(CONFFLUXO!A6) -> MAR
C6: =CONFFLUXO!Q13 -> 63 | F6: =SUM(E3:G3,I5:I7,E9:G9,C5:C7) -> 1631 | I6: =CONFFLUXO!Q7 -> 61
C7: =CONFFLUXO!Q12 -> 160 | I7: =CONFFLUXO!Q8 -> 58
E9: =CONFFLUXO!Q11 -> 165 | F9: =CONFFLUXO!Q10 -> 345 | G9: =CONFFLUXO!Q9 -> 54
E10: =SUM(E9:G9) -> 564
E11: =UPPER(CONFFLUXO!A9) -> FORTE ORANGE | K11: =MAX(3:3,I:I,9:9,C:C) -> 345

Sheet Coordenadas
A1: Norte
A2: Leste
A3: Sul
A4: Oeste
