Workbook

Sheet Resumo
A1: Cruzamento | B1: Av. Cons. Rosa e Silva x Av. Dr. Malaquias
A2: Data | B2: 43593
A3: Coordenadas Geográficas | B3: -8.03812, -34.90057
A4: Relatório
A5: Total | B5: =Dados!Q15 -> 1024
A6: Máximo em um hora | B6: =MAX(Dados!C15:P15) -> 117
A7: Mulher | B7: =Dados!R20 -> 0.0625
A8: Crianças e adolescentes | B8: =Dados!R21 -> 0.022460938
A9: Capacete | B9: =Dados!R22 -> 0.13769531
A10: Caronas | B10: =Dados!R23 -> 0.010742188
A11: Cargueiras | B11: =Dados!R24 -> 0.049804688
A12: Serviço | B12: =Dados!R25 -> 0.047851562
A13: Contramão | B13: =Dados!R26 -> 0.11621094
A14: Calçada | B14: =Dados!R27 -> 0.05859375

Sheet Dados
A1: Dados quantitativos e sentido de deslocamento
A2: ORIGEM | B2: DESTINO | C2: 6 | D2: 7 | E2: 8 | F2: 9 | G2: 10 | H2: 11 | I2: 12 | J2: 13 | K2: 14 | L2: 15 | M2: 16 | N2: 17 | O2: 18 | P2: 19 | Q2: TOTAL | R2: %
A3: Jaqueira | B3: Graças | C3: =ROUND(IF(ISBLANK(Original!C3),'Base projeção'!C3*'Base projeção'!$A$16,Original!C3),0) -> 0 | D3: =ROUND(IF(ISBLANK(Original!D3),'Base projeção'!D3*'Base projeção'!$A$16,Original!D3),0) -> 4 | E3: =ROUND(IF(ISBLANK(Original!E3),'Base projeção'!E3*'Base projeção'!$A$16,Original!E3),0) -> 1 | F3: =ROUND(IF(ISBLANK(Original!F3),'Base projeção'!F3*'Base projeção'!$A$16,Original!F3),0) -> 0 | G3: =ROUND(IF(ISBLANK(Original!G3),'Base projeção'!G3*'Base projeção'!$A$16,Original!G3),0) -> 2 | H3: =ROUND(IF(ISBLANK(Original!H3),'Base projeção'!H3*'Base projeção'!$A$16,Original!H3),0) -> 4 | I3: =ROUND(IF(ISBLANK(Original!I3),'Base projeção'!I3*'Base projeção'!$A$16,Original!I3),0) -> 1 | J3: =ROUND(IF(ISBLANK(Original!J3),'Base projeção'!J3*'Base projeção'!$A$16,Original!J3),0) -> 0 | ... P3: =ROUND(IF(ISBLANK(Original!P3),'Base projeção'!P3*'Base projeção'!$A$16,Original!P3),0) -> 0 | Q3: =SUM(C3:P3) -> 15 | R3: =Q3/$Q$15 -> 0.014648438
A4: Jaqueira | B4: Aflitos | C4: =ROUND(IF(ISBLANK(Original!C4),'Base projeção'!C4*'Base projeção'!$A$16,Original!C4),0) -> 1 | D4: =ROUND(IF(ISBLANK(Original!D4),'Base projeção'!D4*'Base projeção'!$A$16,Original!D4),0) -> 2 | E4: =ROUND(IF(ISBLANK(Original!E4),'Base projeção'!E4*'Base projeção'!$A$16,Original!E4),0) -> 5 | F4: =ROUND(IF(ISBLANK(Original!F4),'Base projeção'!F4*'Base projeção'!$A$16,Original!F4),0) -> 0 | G4: =ROUND(IF(ISBLANK(Original!G4),'Base projeção'!G4*'Base projeção'!$A$16,Original!G4),0) -> 2 | H4: =ROUND(IF(ISBLANK(Original!H4),'Base projeção'!H4*'Base projeção'!$A$16,Original!H4),0) -> 2 | I4: =ROUND(IF(ISBLANK(Original!I4),'Base projeção'!I4*'Base projeção'!$A$16,Original!I4),0) -> 2 | J4: =ROUND(IF(ISBLANK(Original!J4),'Base projeção'!J4*'Base projeção'!$A$16,Original!J4),0) -> 0 | ... P4: =ROUND(IF(ISBLANK(Original!P4),'Base projeção'!P4*'Base projeção'!$A$16,Original!P4),0) -> 0 | Q4: =SUM(C4:P4) -> 19 | R4: =Q4/$Q$15 -> 0.018554688
A5: Jaqueira | B5: Rosarinho | C5: =ROUND(IF(ISBLANK(Original!C5),'Base projeção'!C5*'Base projeção'!$A$16,Original!C5),0) -> 0 | D5: =ROUND(IF(ISBLANK(Original!D5),'Base projeção'!D5*'Base projeção'!$A$16,Original!D5),0) -> 0 | E5: =ROUND(IF(ISBLANK(Original!E5),'Base projeção'!E5*'Base projeção'!$A$16,Original!E5),0) -> 1 | F5: =ROUND(IF(ISBLANK(Original!F5),'Base projeção'!F5*'Base projeção'!$A$16,Original!F5),0) -> 0 | G5: =ROUND(IF(ISBLANK(Original!G5),'Base projeção'!G5*'Base projeção'!$A$16,Original!G5),0) -> 1 | H5: =ROUND(IF(ISBLANK(Original!H5),'Base projeção'!H5*'Base projeção'!$A$16,Original!H5),0) -> 0 | I5: =ROUND(IF(ISBLANK(Original!I5),'Base projeção'!I5*'Base projeção'!$A$16,Original!I5),0) -> 1 | J5: =ROUND(IF(ISBLANK(Original!J5),'Base projeção'!J5*'Base projeção'!$A$16,Original!J5),0) -> 0 | ... P5: =ROUND(IF(ISBLANK(Original!P5),'Base projeção'!P5*'Base projeção'!$A$16,Original!P5),0) -> 0 | Q5: =SUM(C5:P5) -> 5 | R5: =Q5/$Q$15 -> 0.0048828125
A6: Rosarinho | B6: Jaqueira | C6: =ROUND(IF(ISBLANK(Original!C6),'Base projeção'!C6*'Base projeção'!$A$16,Original!C6),0) -> 0 | D6: =ROUND(IF(ISBLANK(Original!D6),'Base projeção'!D6*'Base projeção'!$A$16,Original!D6),0) -> 0 | E6: =ROUND(IF(ISBLANK(Original!E6),'Base projeção'!E6*'Base projeção'!$A$16,Original!E6),0) -> 4 | F6: =ROUND(IF(ISBLANK(Original!F6),'Base projeção'!F6*'Base projeção'!$A$16,Original!F6),0) -> 2 | G6: =ROUND(IF(ISBLANK(Original!G6),'Base projeção'!G6*'Base projeção'!$A$16,Original!G6),0) -> 1 | H6: =ROUND(IF(ISBLANK(Original!H6),'Base projeção'!H6*'Base projeção'!$A$16,Original!H6),0) -> 2 | I6: =ROUND(IF(ISBLANK(Original!I6),'Base projeção'!I6*'Base projeção'!$A$16,Original!I6),0) -> 8 | J6: =ROUND(IF(ISBLANK(Original!J6),'Base projeção'!J6*'Base projeção'!$A$16,Original!J6),0) -> 0 | ... P6: =ROUND(IF(ISBLANK(Original!P6),'Base projeção'!P6*'Base projeção'!$A$16,Original!P6),0) -> 2 | Q6: =SUM(C6:P6) -> 27 | R6: =Q6/$Q$15 -> 0.026367188
A7: Rosarinho | B7: Graças | C7: =ROUND(IF(ISBLANK(Original!C7),'Base projeção'!C7*'Base projeção'!$A$16,Original!C7),0) -> 22 | D7: =ROUND(IF(ISBLANK(Original!D7),'Base projeção'!D7*'Base projeção'!$A$16,Original!D7),0) -> 32 | E7: =ROUND(IF(ISBLANK(Original!E7),'Base projeção'!E7*'Base projeção'!$A$16,Original!E7),0) -> 18 | F7: =ROUND(IF(ISBLANK(Original!F7),'Base projeção'!F7*'Base projeção'!$A$16,Original!F7),0) -> 13 | G7: =ROUND(IF(ISBLANK(Original!G7),'Base projeção'!G7*'Base projeção'!$A$16,Original!G7),0) -> 12 | H7: =ROUND(IF(ISBLANK(Original!H7),'Base projeção'!H7*'Base projeção'!$A$16,Original!H7),0) -> 6 | I7: =ROUND(IF(ISBLANK(Original!I7),'Base projeção'!I7*'Base projeção'!$A$16,Original!I7),0) -> 2 | J7: =ROUND(IF(ISBLANK(Original!J7),'Base projeção'!J7*'Base projeção'!$A$16,Original!J7),0) -> 6 | ... P7: =ROUND(IF(ISBLANK(Original!P7),'Base projeção'!P7*'Base projeção'!$A$16,Original!P7),0) -> 7 | Q7: =SUM(C7:P7) -> 169 | R7: =Q7/$Q$15 -> 0.16503906
A8: Rosarinho | B8: Aflitos | C8: =ROUND(IF(ISBLANK(Original!C8),'Base projeção'!C8*'Base projeção'!$A$16,Original!C8),0) -> 0 | D8: =ROUND(IF(ISBLANK(Original!D8),'Base projeção'!D8*'Base projeção'!$A$16,Original!D8),0) -> 5 | E8: =ROUND(IF(ISBLANK(Original!E8),'Base projeção'!E8*'Base projeção'!$A$16,Original!E8),0) -> 5 | F8: =ROUND(IF(ISBLANK(Original!F8),'Base projeção'!F8*'Base projeção'!$A$16,Original!F8),0) -> 2 | G8: =ROUND(IF(ISBLANK(Original!G8),'Base projeção'!G8*'Base projeção'!$A$16,Original!G8),0) -> 1 | H8: =ROUND(IF(ISBLANK(Original!H8),'Base projeção'!H8*'Base projeção'!$A$16,Original!H8),0) -> 5 | I8: =ROUND(IF(ISBLANK(Original!I8),'Base projeção'!I8*'Base projeção'!$A$16,Original!I8),0) -> 4 | J8: =ROUND(IF(ISBLANK(Original!J8),'Base projeção'!J8*'Base projeção'!$A$16,Original!J8),0) -> 4 | ... P8: =ROUND(IF(ISBLANK(Original!P8),'Base projeção'!P8*'Base projeção'!$A$16,Original!P8),0) -> 1 | Q8: =SUM(C8:P8) -> 40 | R8: =Q8/$Q$15 -> 0.0390625
A9: Graças | B9: Aflitos | C9: =ROUND(IF(ISBLANK(Original!C9),'Base projeção'!C9*'Base projeção'!$A$16,Original!C9),0) -> 0 | D9: =ROUND(IF(ISBLANK(Original!D9),'Base projeção'!D9*'Base projeção'!$A$16,Original!D9),0) -> 1 | E9: =ROUND(IF(ISBLANK(Original!E9),'Base projeção'!E9*'Base projeção'!$A$16,Original!E9),0) -> 2 | F9: =ROUND(IF(ISBLANK(Original!F9),'Base projeção'!F9*'Base projeção'!$A$16,Original!F9),0) -> 4 | G9: =ROUND(IF(ISBLANK(Original!G9),'Base projeção'!G9*'Base projeção'!$A$16,Original!G9),0) -> 0 | H9: =ROUND(IF(ISBLANK(Original!H9),'Base projeção'!H9*'Base projeção'!$A$16,Original!H9),0) -> 2 | I9: =ROUND(IF(ISBLANK(Original!I9),'Base projeção'!I9*'Base projeção'!$A$16,Original!I9),0) -> 28 | J9: =ROUND(IF(ISBLANK(Original!J9),'Base projeção'!J9*'Base projeção'!$A$16,Original!J9),0) -> 0 | ... P9: =ROUND(IF(ISBLANK(Original!P9),'Base projeção'!P9*'Base projeção'!$A$16,Original!P9),0) -> 1 | Q9: =SUM(C9:P9) -> 46 | R9: =Q9/$Q$15 -> 0.044921875
A10: Graças | B10: Rosarinho | C10: =ROUND(IF(ISBLANK(Original!C10),'Base projeção'!C10*'Base projeção'!$A$16,Original!C10),0) -> 29 | D10: =ROUND(IF(ISBLANK(Original!D10),'Base projeção'!D10*'Base projeção'!$A$16,Original!D10),0) -> 26 | E10: =ROUND(IF(ISBLANK(Original!E10),'Base projeção'!E10*'Base projeção'!$A$16,Original!E10),0) -> 32 | F10: =ROUND(IF(ISBLANK(Original!F10),'Base projeção'!F10*'Base projeção'!$A$16,Original!F10),0) -> 25 | G10: =ROUND(IF(ISBLANK(Original!G10),'Base projeção'!G10*'Base projeção'!$A$16,Original!G10),0) -> 29 | H10: =ROUND(IF(ISBLANK(Original!H10),'Base projeção'!H10*'Base projeção'!$A$16,Original!H10),0) -> 41 | I10: =ROUND(IF(ISBLANK(Original!I10),'Base projeção'!I10*'Base projeção'!$A$16,Original!I10),0) -> 8 | J10: =ROUND(IF(ISBLANK(Original!J10),'Base projeção'!J10*'Base projeção'!$A$16,Original!J10),0) -> 17 | ... P10: =ROUND(IF(ISBLANK(Original!P10),'Base projeção'!P10*'Base projeção'!$A$16,Original!P10),0) -> 41 | Q10: =SUM(C10:P10) -> 256 | R10: =Q10/$Q$15 -> 0.25
A11: Graças | B11: Jaqueira | C11: =ROUND(IF(ISBLANK(Original!C11),'Base projeção'!C11*'Base projeção'!$A$16,Original!C11),0) -> 1 | D11: =ROUND(IF(ISBLANK(Original!D11),'Base projeção'!D11*'Base projeção'!$A$16,Original!D11),0) -> 5 | E11: =ROUND(IF(ISBLANK(Original!E11),'Base projeção'!E11*'Base projeção'!$A$16,Original!E11),0) -> 5 | F11: =ROUND(IF(ISBLANK(Original!F11),'Base projeção'!F11*'Base projeção'!$A$16,Original!F11),0) -> 11 | G11: =ROUND(IF(ISBLANK(Original!G11),'Base projeção'!G11*'Base projeção'!$A$16,Original!G11),0) -> 5 | H11: =ROUND(IF(ISBLANK(Original!H11),'Base projeção'!H11*'Base projeção'!$A$16,Original!H11),0) -> 8 | I11: =ROUND(IF(ISBLANK(Original!I11),'Base projeção'!I11*'Base projeção'!$A$16,Original!I11),0) -> 4 | J11: =ROUND(IF(ISBLANK(Original!J11),'Base projeção'!J11*'Base projeção'!$A$16,Original!J11),0) -> 6 | ... P11: =ROUND(IF(ISBLANK(Original!P11),'Base projeção'!P11*'Base projeção'!$A$16,Original!P11),0) -> 6 | Q11: =SUM(C11:P11) -> 66 | R11: =Q11/$Q$15 -> 0.064453125
A12: Aflitos | B12: Rosarinho | C12: =ROUND(IF(ISBLANK(Original!C12),'Base projeção'!C12*'Base projeção'!$A$16,Original!C12),0) -> 1 | D12: =ROUND(IF(ISBLANK(Original!D12),'Base projeção'!D12*'Base projeção'!$A$16,Original!D12),0) -> 2 | E12: =ROUND(IF(ISBLANK(Original!E12),'Base projeção'!E12*'Base projeção'!$A$16,Original!E12),0) -> 1 | F12: =ROUND(IF(ISBLANK(Original!F12),'Base projeção'!F12*'Base projeção'!$A$16,Original!F12),0) -> 1 | G12: =ROUND(IF(ISBLANK(Original!G12),'Base projeção'!G12*'Base projeção'!$A$16,Original!G12),0) -> 5 | H12: =ROUND(IF(ISBLANK(Original!H12),'Base projeção'!H12*'Base projeção'!$A$16,Original!H12),0) -> 5 | I12: =ROUND(IF(ISBLANK(Original!I12),'Base projeção'!I12*'Base projeção'!$A$16,Original!I12),0) -> 6 | J12: =ROUND(IF(ISBLANK(Original!J12),'Base projeção'!J12*'Base projeção'!$A$16,Original!J12),0) -> 2 | ... P12: =ROUND(IF(ISBLANK(Original!P12),'Base projeção'!P12*'Base projeção'!$A$16,Original!P12),0) -> 0 | Q12: =SUM(C12:P12) -> 28 | R12: =Q12/$Q$15 -> 0.02734375
A13: Aflitos | B13: Jaqueira | C13: =ROUND(IF(ISBLANK(Original!C13),'Base projeção'!C13*'Base projeção'!$A$16,Original!C13),0) -> 5 | D13: =ROUND(IF(ISBLANK(Original!D13),'Base projeção'!D13*'Base projeção'!$A$16,Original!D13),0) -> 1 | E13: =ROUND(IF(ISBLANK(Original!E13),'Base projeção'!E13*'Base projeção'!$A$16,Original!E13),0) -> 4 | F13: =ROUND(IF(ISBLANK(Original!F13),'Base projeção'!F13*'Base projeção'!$A$16,Original!F13),0) -> 2 | G13: =ROUND(IF(ISBLANK(Original!G13),'Base projeção'!G13*'Base projeção'!$A$16,Original!G13),0) -> 4 | H13: =ROUND(IF(ISBLANK(Original!H13),'Base projeção'!H13*'Base projeção'!$A$16,Original!H13),0) -> 5 | I13: =ROUND(IF(ISBLANK(Original!I13),'Base projeção'!I13*'Base projeção'!$A$16,Original!I13),0) -> 1 | J13: =ROUND(IF(ISBLANK(Original!J13),'Base projeção'!J13*'Base projeção'!$A$16,Original!J13),0) -> 4 | ... P13: =ROUND(IF(ISBLANK(Original!P13),'Base projeção'!P13*'Base projeção'!$A$16,Original!P13),0) -> 2 | Q13: =SUM(C13:P13) -> 307 | R13: =Q13/$Q$15 -> 0.29980469
A14: Aflitos | B14: Graças | C14: =ROUND(IF(ISBLANK(Original!C14),'Base projeção'!C14*'Base projeção'!$A$16,Original!C14),0) -> 0 | D14: =ROUND(IF(ISBLANK(Original!D14),'Base projeção'!D14*'Base projeção'!$A$16,Original!D14),0) -> 0 | E14: =ROUND(IF(ISBLANK(Original!E14),'Base projeção'!E14*'Base projeção'!$A$16,Original!E14),0) -> 1 | F14: =ROUND(IF(ISBLANK(Original!F14),'Base projeção'!F14*'Base projeção'!$A$16,Original!F14),0) -> 2 | G14: =ROUND(IF(ISBLANK(Original!G14),'Base projeção'!G14*'Base projeção'!$A$16,Original!G14),0) -> 4 | H14: =ROUND(IF(ISBLANK(Original!H14),'Base projeção'!H14*'Base projeção'!$A$16,Original!H14),0) -> 2 | I14: =ROUND(IF(ISBLANK(Original!I14),'Base projeção'!I14*'Base projeção'!$A$16,Original!I14),0) -> 1 | J14: =ROUND(IF(ISBLANK(Original!J14),'Base projeção'!J14*'Base projeção'!$A$16,Original!J14),0) -> 4 | ... P14: =ROUND(IF(ISBLANK(Original!P14),'Base projeção'!P14*'Base projeção'!$A$16,Original!P14),0) -> 1 | Q14: =SUM(C14:P14) -> 46 | R14: =Q14/$Q$15 -> 0.044921875
B15: TOTAL | C15: =SUM(C$3:C$14) -> 59 | D15: =SUM(D$3:D$14) -> 78 | E15: =SUM(E$3:E$14) -> 79 | F15: =SUM(F$3:F$14) -> 62 | G15: =SUM(G$3:G$14) -> 66 | H15: =SUM(H$3:H$14) -> 82 | I15: =SUM(I$3:I$14) -> 66 | J15: =SUM(J$3:J$14) -> 43 | ... Q15: =SUM(Q$3:Q$14) -> 1024
B16: Percentual | C16: =C15/$Q$15 -> 0.057617188 | D16: =D15/$Q$15 -> 0.076171875 | E16: =E15/$Q$15 -> 0.077148438 | F16: =F15/$Q$15 -> 0.060546875 | G16: =G15/$Q$15 -> 0.064453125 | H16: =H15/$Q$15 -> 0.080078125 | I16: =I15/$Q$15 -> 0.064453125 | J16: =J15/$Q$15 -> 0.041992188 | ... P16: =P15/$Q$15 -> 0.059570312 | Q16: =SUM(C16:P16) -> 1
A18: Dados qualitativos padrões
B19: Característica | C19: 6 | D19: 7 | E19: 8 | F19: 9 | G19: 10 | H19: 11 | I19: 12 | J19: 13 | K19: 14 | L19: 15 | M19: 16 | N19: 17 | O19: 18 | P19: 19 | Q19: TOTAL | R19: %
B20: Mulher | C20: =ROUND(IF(ISBLANK(Original!C20),'Base projeção'!C20*'Base projeção'!$A$16,Original!C20),0) -> 4 | D20: =ROUND(IF(ISBLANK(Original!D20),'Base projeção'!D20*'Base projeção'!$A$16,Original!D20),0) -> 0 | E20: =ROUND(IF(ISBLANK(Original!E20),'Base projeção'!E20*'Base projeção'!$A$16,Original!E20),0) -> 2 | F20: =ROUND(IF(ISBLANK(Original!F20),'Base projeção'!F20*'Base projeção'!$A$16,Original!F20),0) -> 7 | G20: =ROUND(IF(ISBLANK(Original!G20),'Base projeção'!G20*'Base projeção'!$A$16,Original!G20),0) -> 4 | H20: =ROUND(IF(ISBLANK(Original!H20),'Base projeção'!H20*'Base projeção'!$A$16,Original!H20),0) -> 4 | I20: =ROUND(IF(ISBLANK(Original!I20),'Base projeção'!I20*'Base projeção'!$A$16,Original!I20),0) -> 1 | J20: =ROUND(IF(ISBLANK(Original!J20),'Base projeção'!J20*'Base projeção'!$A$16,Original!J20),0) -> 7 | ... P20: =ROUND(IF(ISBLANK(Original!P20),'Base projeção'!P20*'Base projeção'!$A$16,Original!P20),0) -> 1 | Q20: =SUM(C20:P20) -> 64 | R20: =Q20/$Q$15 -> 0.0625
B21: Crianças e adolescentes | C21: =ROUND(IF(ISBLANK(Original!C21),'Base projeção'!C21*'Base projeção'!$A$16,Original!C21),0) -> 5 | D21: =ROUND(IF(ISBLANK(Original!D21),'Base projeção'!D21*'Base projeção'!$A$16,Original!D21),0) -> 4 | E21: =ROUND(IF(ISBLANK(Original!E21),'Base projeção'!E21*'Base projeção'!$A$16,Original!E21),0) -> 0 | F21: =ROUND(IF(ISBLANK(Original!F21),'Base projeção'!F21*'Base projeção'!$A$16,Original!F21),0) -> 0 | G21: =ROUND(IF(ISBLANK(Original!G21),'Base projeção'!G21*'Base projeção'!$A$16,Original!G21),0) -> 0 | H21: =ROUND(IF(ISBLANK(Original!H21),'Base projeção'!H21*'Base projeção'!$A$16,Original!H21),0) -> 1 | I21: =ROUND(IF(ISBLANK(Original!I21),'Base projeção'!I21*'Base projeção'!$A$16,Original!I21),0) -> 5 | J21: =ROUND(IF(ISBLANK(Original!J21),'Base projeção'!J21*'Base projeção'!$A$16,Original!J21),0) -> 7 | ... P21: =ROUND(IF(ISBLANK(Original!P21),'Base projeção'!P21*'Base projeção'!$A$16,Original!P21),0) -> 0 | Q21: =SUM(C21:P21) -> 23 | R21: =Q21/$Q$15 -> 0.022460938
B22: Capacete | C22: =ROUND(IF(ISBLANK(Original!C22),'Base projeção'!C22*'Base projeção'!$A$16,Original!C22),0) -> 11 | D22: =ROUND(IF(ISBLANK(Original!D22),'Base projeção'!D22*'Base projeção'!$A$16,Original!D22),0) -> 5 | E22: =ROUND(IF(ISBLANK(Original!E22),'Base projeção'!E22*'Base projeção'!$A$16,Original!E22),0) -> 8 | F22: =ROUND(IF(ISBLANK(Original!F22),'Base projeção'!F22*'Base projeção'!$A$16,Original!F22),0) -> 11 | G22: =ROUND(IF(ISBLANK(Original!G22),'Base projeção'!G22*'Base projeção'!$A$16,Original!G22),0) -> 10 | H22: =ROUND(IF(ISBLANK(Original!H22),'Base projeção'!H22*'Base projeção'!$A$16,Original!H22),0) -> 8 | I22: =ROUND(IF(ISBLANK(Original!I22),'Base projeção'!I22*'Base projeção'!$A$16,Original!I22),0) -> 8 | J22: =ROUND(IF(ISBLANK(Original!J22),'Base projeção'!J22*'Base projeção'!$A$16,Original!J22),0) -> 6 | ... P22: =ROUND(IF(ISBLANK(Original!P22),'Base projeção'!P22*'Base projeção'!$A$16,Original!P22),0) -> 18 | Q22: =SUM(C22:P22) -> 141 | R22: =Q22/$Q$15 -> 0.13769531
B23: Caronas | C23: =ROUND(IF(ISBLANK(Original!C23),'Base projeção'!C23*'Base projeção'!$A$16,Original!C23),0) -> 1 | D23: =ROUND(IF(ISBLANK(Original!D23),'Base projeção'!D23*'Base projeção'!$A$16,Original!D23),0) -> 0 | E23: =ROUND(IF(ISBLANK(Original!E23),'Base projeção'!E23*'Base projeção'!$A$16,Original!E23),0) -> 1 | F23: =ROUND(IF(ISBLANK(Original!F23),'Base projeção'!F23*'Base projeção'!$A$16,Original!F23),0) -> 1 | G23: =ROUND(IF(ISBLANK(Original!G23),'Base projeção'!G23*'Base projeção'!$A$16,Original!G23),0) -> 0 | H23: =ROUND(IF(ISBLANK(Original!H23),'Base projeção'!H23*'Base projeção'!$A$16,Original!H23),0) -> 1 | I23: =ROUND(IF(ISBLANK(Original!I23),'Base projeção'!I23*'Base projeção'!$A$16,Original!I23),0) -> 0 | J23: =ROUND(IF(ISBLANK(Original!J23),'Base projeção'!J23*'Base projeção'!$A$16,Original!J23),0) -> 0 | ... P23: =ROUND(IF(ISBLANK(Original!P23),'Base projeção'!P23*'Base projeção'!$A$16,Original!P23),0) -> 0 | Q23: =SUM(C23:P23) -> 11 | R23: =Q23/$Q$15 -> 0.010742188
B24: Cargueiras | C24: =ROUND(IF(ISBLANK(Original!C24),'Base projeção'!C24*'Base projeção'!$A$16,Original!C24),0) -> 1 | D24: =ROUND(IF(ISBLANK(Original!D24),'Base projeção'!D24*'Base projeção'!$A$16,Original!D24),0) -> 0 | E24: =ROUND(IF(ISBLANK(Original!E24),'Base projeção'!E24*'Base projeção'!$A$16,Original!E24),0) -> 2 | F24: =ROUND(IF(ISBLANK(Original!F24),'Base projeção'!F24*'Base projeção'!$A$16,Original!F24),0) -> 0 | G24: =ROUND(IF(ISBLANK(Original!G24),'Base projeção'!G24*'Base projeção'!$A$16,Original!G24),0) -> 1 | H24: =ROUND(IF(ISBLANK(Original!H24),'Base projeção'!H24*'Base projeção'!$A$16,Original!H24),0) -> 0 | I24: =ROUND(IF(ISBLANK(Original!I24),'Base projeção'!I24*'Base projeção'!$A$16,Original!I24),0) -> 0 | J24: =ROUND(IF(ISBLANK(Original!J24),'Base projeção'!J24*'Base projeção'!$A$16,Original!J24),0) -> 0 | ... P24: =ROUND(IF(ISBLANK(Original!P24),'Base projeção'!P24*'Base projeção'!$A$16,Original!P24),0) -> 0 | Q24: =SUM(C24:P24) -> 51 | R24: =Q24/$Q$15 -> 0.049804688
B25: Serviço | C25: =ROUND(IF(ISBLANK(Original!C25),'Base projeção'!C25*'Base projeção'!$A$16,Original!C25),0) -> 0 | D25: =ROUND(IF(ISBLANK(Original!D25),'Base projeção'!D25*'Base projeção'!$A$16,Original!D25),0) -> 0 | E25: =ROUND(IF(ISBLANK(Original!E25),'Base projeção'!E25*'Base projeção'!$A$16,Original!E25),0) -> 1 | F25: =ROUND(IF(ISBLANK(Original!F25),'Base projeção'!F25*'Base projeção'!$A$16,Original!F25),0) -> 0 | G25: =ROUND(IF(ISBLANK(Original!G25),'Base projeção'!G25*'Base projeção'!$A$16,Original!G25),0) -> 0 | H25: =ROUND(IF(ISBLANK(Original!H25),'Base projeção'!H25*'Base projeção'!$A$16,Original!H25),0) -> 0 | I25: =ROUND(IF(ISBLANK(Original!I25),'Base projeção'!I25*'Base projeção'!$A$16,Original!I25),0) -> 0 | J25: =ROUND(IF(ISBLANK(Original!J25),'Base projeção'!J25*'Base projeção'!$A$16,Original!J25),0) -> 1 | ... P25: =ROUND(IF(ISBLANK(Original!P25),'Base projeção'!P25*'Base projeção'!$A$16,Original!P25),0) -> 0 | Q25: =SUM(C25:P25) -> 49 | R25: =Q25/$Q$15 -> 0.047851562
B26: Contramão | C26: =ROUND(IF(ISBLANK(Original!C26),'Base projeção'!C26*'Base projeção'!$A$16,Original!C26),0) -> 2 | D26: =ROUND(IF(ISBLANK(Original!D26),'Base projeção'!D26*'Base projeção'!$A$16,Original!D26),0) -> 4 | E26: =ROUND(IF(ISBLANK(Original!E26),'Base projeção'!E26*'Base projeção'!$A$16,Original!E26),0) -> 8 | F26: =ROUND(IF(ISBLANK(Original!F26),'Base projeção'!F26*'Base projeção'!$A$16,Original!F26),0) -> 7 | G26: =ROUND(IF(ISBLANK(Original!G26),'Base projeção'!G26*'Base projeção'!$A$16,Original!G26),0) -> 6 | H26: =ROUND(IF(ISBLANK(Original!H26),'Base projeção'!H26*'Base projeção'!$A$16,Original!H26),0) -> 17 | I26: =ROUND(IF(ISBLANK(Original!I26),'Base projeção'!I26*'Base projeção'!$A$16,Original!I26),0) -> 16 | J26: =ROUND(IF(ISBLANK(Original!J26),'Base projeção'!J26*'Base projeção'!$A$16,Original!J26),0) -> 4 | ... P26: =ROUND(IF(ISBLANK(Original!P26),'Base projeção'!P26*'Base projeção'!$A$16,Original!P26),0) -> 2 | Q26: =SUM(C26:P26) -> 119 | R26: =Q26/$Q$15 -> 0.11621094
B27: Calçada | C27: =ROUND(IF(ISBLANK(Original!C27),'Base projeção'!C27*'Base projeção'!$A$16,Original!C27),0) -> 4 | D27: =ROUND(IF(ISBLANK(Original!D27),'Base projeção'!D27*'Base projeção'!$A$16,Original!D27),0) -> 1 | E27: =ROUND(IF(ISBLANK(Original!E27),'Base projeção'!E27*'Base projeção'!$A$16,Original!E27),0) -> 5 | F27: =ROUND(IF(ISBLANK(Original!F27),'Base projeção'!F27*'Base projeção'!$A$16,Original!F27),0) -> 6 | G27: =ROUND(IF(ISBLANK(Original!G27),'Base projeção'!G27*'Base projeção'!$A$16,Original!G27),0) -> 2 | H27: =ROUND(IF(ISBLANK(Original!H27),'Base projeção'!H27*'Base projeção'!$A$16,Original!H27),0) -> 5 | I27: =ROUND(IF(ISBLANK(Original!I27),'Base projeção'!I27*'Base projeção'!$A$16,Original!I27),0) -> 0 | J27: =ROUND(IF(ISBLANK(Original!J27),'Base projeção'!J27*'Base projeção'!$A$16,Original!J27),0) -> 0 | ... P27: =ROUND(IF(ISBLANK(Original!P27),'Base projeção'!P27*'Base projeção'!$A$16,Original!P27),0) -> 1 | Q27: =SUM(C27:P27) -> 60 | R27: =Q27/$Q$15 -> 0.05859375
A29: Dados qualitativos das observações
B30: Característica | C30: 6 | D30: 7 | E30: 8 | F30: 9 | G30: 10 | H30: 11 | I30: 12 | J30: 13 | K30: 14 | L30: 15 | M30: 16 | N30: 17 | O30: 18 | P30: 19 | Q30: TOTAL | R30: %
B31: Carona criança | C31: =ROUND(IF(ISBLANK(Original!C31),'Base projeção'!C31*'Base projeção'!$A$16,Original!C31),0) -> 4 | D31: =ROUND(IF(ISBLANK(Original!D31),'Base projeção'!D31*'Base projeção'!$A$16,Original!D31),0) -> 11 | E31: =ROUND(IF(ISBLANK(Original!E31),'Base projeção'!E31*'Base projeção'!$A$16,Original!E31),0) -> 8 | F31: =ROUND(IF(ISBLANK(Original!F31),'Base projeção'!F31*'Base projeção'!$A$16,Original!F31),0) -> 14 | G31: =ROUND(IF(ISBLANK(Original!G31),'Base projeção'!G31*'Base projeção'!$A$16,Original!G31),0) -> 16 | H31: =ROUND(IF(ISBLANK(Original!H31),'Base projeção'!H31*'Base projeção'!$A$16,Original!H31),0) -> 14 | I31: =ROUND(IF(ISBLANK(Original!I31),'Base projeção'!I31*'Base projeção'!$A$16,Original!I31),0) -> 10 | J31: =ROUND(IF(ISBLANK(Original!J31),'Base projeção'!J31*'Base projeção'!$A$16,Original!J31),0) -> 8 | ... P31: =ROUND(IF(ISBLANK(Original!P31),'Base projeção'!P31*'Base projeção'!$A$16,Original!P31),0) -> 4 | Q31: =SUM(C31:P31) -> 91 | R31: =Q31/$Q$15 -> 0.088867188
B32: Carona mulher | C32: =ROUND(IF(ISBLANK(Original!C32),'Base projeção'!C32*'Base projeção'!$A$16,Original!C32),0) -> 0 | D32: =ROUND(IF(ISBLANK(Original!D32),'Base projeção'!D32*'Base projeção'!$A$16,Original!D32),0) -> 0 | E32: =ROUND(IF(ISBLANK(Original!E32),'Base projeção'!E32*'Base projeção'!$A$16,Original!E32),0) -> 0 | F32: =ROUND(IF(ISBLANK(Original!F32),'Base projeção'!F32*'Base projeção'!$A$16,Original!F32),0) -> 0 | G32: =ROUND(IF(ISBLANK(Original!G32),'Base projeção'!G32*'Base projeção'!$A$16,Original!G32),0) -> 0 | H32: =ROUND(IF(ISBLANK(Original!H32),'Base projeção'!H32*'Base projeção'!$A$16,Original!H32),0) -> 0 | I32: =ROUND(IF(ISBLANK(Original!I32),'Base projeção'!I32*'Base projeção'!$A$16,Original!I32),0) -> 0 | J32: =ROUND(IF(ISBLANK(Original!J32),'Base projeção'!J32*'Base projeção'!$A$16,Original!J32),0) -> 0 | ... P32: =ROUND(IF(ISBLANK(Original!P32),'Base projeção'!P32*'Base projeção'!$A$16,Original!P32),0) -> 0 | Q32: =SUM(C32:P32) -> 2 | R32: =Q32/$Q$15 -> 0.001953125
B33: Carona homem | C33: =ROUND(IF(ISBLANK(Original!C33),'Base projeção'!C33*'Base projeção'!$A$16,Original!C33),0) -> 0 | D33: =ROUND(IF(ISBLANK(Original!D33),'Base projeção'!D33*'Base projeção'!$A$16,Original!D33),0) -> 0 | E33: =ROUND(IF(ISBLANK(Original!E33),'Base projeção'!E33*'Base projeção'!$A$16,Original!E33),0) -> 0 | F33: =ROUND(IF(ISBLANK(Original!F33),'Base projeção'!F33*'Base projeção'!$A$16,Original!F33),0) -> 0 | G33: =ROUND(IF(ISBLANK(Original!G33),'Base projeção'!G33*'Base projeção'!$A$16,Original!G33),0) -> 0 | H33: =ROUND(IF(ISBLANK(Original!H33),'Base projeção'!H33*'Base projeção'!$A$16,Original!H33),0) -> 0 | I33: =ROUND(IF(ISBLANK(Original!I33),'Base projeção'!I33*'Base projeção'!$A$16,Original!I33),0) -> 0 | J33: =ROUND(IF(ISBLANK(Original!J33),'Base projeção'!J33*'Base projeção'!$A$16,Original!J33),0) -> 0 | ... P33: =ROUND(IF(ISBLANK(Original!P33),'Base projeção'!P33*'Base projeção'!$A$16,Original!P33),0) -> 0 | Q33: =SUM(C33:P33) -> 3 | R33: =Q33/$Q$15 -> 0.0029296875
B34: Cargueira | C34: =ROUND(IF(ISBLANK(Original!C34),'Base projeção'!C34*'Base projeção'!$A$16,Original!C34),0) -> 7 | D34: =ROUND(IF(ISBLANK(Original!D34),'Base projeção'!D34*'Base projeção'!$A$16,Original!D34),0) -> 8 | E34: =ROUND(IF(ISBLANK(Original!E34),'Base projeção'!E34*'Base projeção'!$A$16,Original!E34),0) -> 10 | F34: =ROUND(IF(ISBLANK(Original!F34),'Base projeção'!F34*'Base projeção'!$A$16,Original!F34),0) -> 11 | G34: =ROUND(IF(ISBLANK(Original!G34),'Base projeção'!G34*'Base projeção'!$A$16,Original!G34),0) -> 12 | H34: =ROUND(IF(ISBLANK(Original!H34),'Base projeção'!H34*'Base projeção'!$A$16,Original!H34),0) -> 13 | I34: =ROUND(IF(ISBLANK(Original!I34),'Base projeção'!I34*'Base projeção'!$A$16,Original!I34),0) -> 14 | J34: =ROUND(IF(ISBLANK(Original!J34),'Base projeção'!J34*'Base projeção'!$A$16,Original!J34),0) -> 16 | ... P34: =ROUND(IF(ISBLANK(Original!P34),'Base projeção'!P34*'Base projeção'!$A$16,Original!P34),0) -> 23 | Q34: =SUM(C34:P34) -> 141 | R34: =Q34/$Q$15 -> 0.13769531
B35: Adaptada a carga | C35: =ROUND(IF(ISBLANK(Original!C35),'Base projeção'!C35*'Base projeção'!$A$16,Original!C35),0) -> 0 | D35: =ROUND(IF(ISBLANK(Original!D35),'Base projeção'!D35*'Base projeção'!$A$16,Original!D35),0) -> 0 | E35: =ROUND(IF(ISBLANK(Original!E35),'Base projeção'!E35*'Base projeção'!$A$16,Original!E35),0) -> 0 | F35: =ROUND(IF(ISBLANK(Original!F35),'Base projeção'!F35*'Base projeção'!$A$16,Original!F35),0) -> 0 | G35: =ROUND(IF(ISBLANK(Original!G35),'Base projeção'!G35*'Base projeção'!$A$16,Original!G35),0) -> 0 | H35: =ROUND(IF(ISBLANK(Original!H35),'Base projeção'!H35*'Base projeção'!$A$16,Original!H35),0) -> 0 | I35: =ROUND(IF(ISBLANK(Original!I35),'Base projeção'!I35*'Base projeção'!$A$16,Original!I35),0) -> 0 | J35: =ROUND(IF(ISBLANK(Original!J35),'Base projeção'!J35*'Base projeção'!$A$16,Original!J35),0) -> 0 | ... P35: =ROUND(IF(ISBLANK(Original!P35),'Base projeção'!P35*'Base projeção'!$A$16,Original!P35),0) -> 1 | Q35: =SUM(C35:P35) -> 21 | R35: =Q35/$Q$15 -> 0.020507812
B36: Serviço | C36: =ROUND(IF(ISBLANK(Original!C36),'Base projeção'!C36*'Base projeção'!$A$16,Original!C36),0) -> 0 | D36: =ROUND(IF(ISBLANK(Original!D36),'Base projeção'!D36*'Base projeção'!$A$16,Original!D36),0) -> 0 | E36: =ROUND(IF(ISBLANK(Original!E36),'Base projeção'!E36*'Base projeção'!$A$16,Original!E36),0) -> 0 | F36: =ROUND(IF(ISBLANK(Original!F36),'Base projeção'!F36*'Base projeção'!$A$16,Original!F36),0) -> 0 | G36: =ROUND(IF(ISBLANK(Original!G36),'Base projeção'!G36*'Base projeção'!$A$16,Original!G36),0) -> 0 | H36: =ROUND(IF(ISBLANK(Original!H36),'Base projeção'!H36*'Base projeção'!$A$16,Original!H36),0) -> 0 | I36: =ROUND(IF(ISBLANK(Original!I36),'Base projeção'!I36*'Base projeção'!$A$16,Original!I36),0) -> 0 | J36: =ROUND(IF(ISBLANK(Original!J36),'Base projeção'!J36*'Base projeção'!$A$16,Original!J36),0) -> 0 | ... P36: =ROUND(IF(ISBLANK(Original!P36),'Base projeção'!P36*'Base projeção'!$A$16,Original!P36),0) -> 0 | Q36: =SUM(C36:P36) -> 18 | R36: =Q36/$Q$15 -> 0.017578125
B37: Serviço App | C37: =ROUND(IF(ISBLANK(Original!C37),'Base projeção'!C37*'Base projeção'!$A$16,Original!C37),0) -> 0 | D37: =ROUND(IF(ISBLANK(Original!D37),'Base projeção'!D37*'Base projeção'!$A$16,Original!D37),0) -> 1 | E37: =ROUND(IF(ISBLANK(Original!E37),'Base projeção'!E37*'Base projeção'!$A$16,Original!E37),0) -> 0 | F37: =ROUND(IF(ISBLANK(Original!F37),'Base projeção'!F37*'Base projeção'!$A$16,Original!F37),0) -> 0 | G37: =ROUND(IF(ISBLANK(Original!G37),'Base projeção'!G37*'Base projeção'!$A$16,Original!G37),0) -> 0 | H37: =ROUND(IF(ISBLANK(Original!H37),'Base projeção'!H37*'Base projeção'!$A$16,Original!H37),0) -> 1 | I37: =ROUND(IF(ISBLANK(Original!I37),'Base projeção'!I37*'Base projeção'!$A$16,Original!I37),0) -> 0 | J37: =ROUND(IF(ISBLANK(Original!J37),'Base projeção'!J37*'Base projeção'!$A$16,Original!J37),0) -> 0 | ... P37: =ROUND(IF(ISBLANK(Original!P37),'Base projeção'!P37*'Base projeção'!$A$16,Original!P37),0) -> 0 | Q37: =SUM(C37:P37) -> 31 | R37: =Q37/$Q$15 -> 0.030273438
B38: Contramao | C38: =ROUND(IF(ISBLANK(Original!C38),'Base projeção'!C38*'Base projeção'!$A$16,Original!C38),0) -> 0 | D38: =ROUND(IF(ISBLANK(Original!D38),'Base projeção'!D38*'Base projeção'!$A$16,Original!D38),0) -> 0 | E38: =ROUND(IF(ISBLANK(Original!E38),'Base projeção'!E38*'Base projeção'!$A$16,Original!E38),0) -> 0 | F38: =ROUND(IF(ISBLANK(Original!F38),'Base projeção'!F38*'Base projeção'!$A$16,Original!F38),0) -> 0 | G38: =ROUND(IF(ISBLANK(Original!G38),'Base projeção'!G38*'Base projeção'!$A$16,Original!G38),0) -> 4 | H38: =ROUND(IF(ISBLANK(Original!H38),'Base projeção'!H38*'Base projeção'!$A$16,Original!H38),0) -> 0 | I38: =ROUND(IF(ISBLANK(Original!I38),'Base projeção'!I38*'Base projeção'!$A$16,Original!I38),0) -> 0 | J38: =ROUND(IF(ISBLANK(Original!J38),'Base projeção'!J38*'Base projeção'!$A$16,Original!J38),0) -> 0 | ... P38: =ROUND(IF(ISBLANK(Original!P38),'Base projeção'!P38*'Base projeção'!$A$16,Original!P38),0) -> 0 | Q38: =SUM(C38:P38) -> 50 | R38: =Q38/$Q$15 -> 0.048828125
B39: Contramão para conversão | C39: =ROUND(IF(ISBLANK(Original!C39),'Base projeção'!C39*'Base projeção'!$A$16,Original!C39),0) -> 0 | D39: =ROUND(IF(ISBLANK(Original!D39),'Base projeção'!D39*'Base projeção'!$A$16,Original!D39),0) -> 0 | E39: =ROUND(IF(ISBLANK(Original!E39),'Base projeção'!E39*'Base projeção'!$A$16,Original!E39),0) -> 0 | F39: =ROUND(IF(ISBLANK(Original!F39),'Base projeção'!F39*'Base projeção'!$A$16,Original!F39),0) -> 0 | G39: =ROUND(IF(ISBLANK(Original!G39),'Base projeção'!G39*'Base projeção'!$A$16,Original!G39),0) -> 0 | H39: =ROUND(IF(ISBLANK(Original!H39),'Base projeção'!H39*'Base projeção'!$A$16,Original!H39),0) -> 0 | I39: =ROUND(IF(ISBLANK(Original!I39),'Base projeção'!I39*'Base projeção'!$A$16,Original!I39),0) -> 0 | J39: =ROUND(IF(ISBLANK(Original!J39),'Base projeção'!J39*'Base projeção'!$A$16,Original!J39),0) -> 0 | ... P39: =ROUND(IF(ISBLANK(Original!P39),'Base projeção'!P39*'Base projeção'!$A$16,Original!P39),0) -> 0 | Q39: =SUM(C39:P39) -> 7 | R39: =Q39/$Q$15 -> 0.0068359375
B40: Bike PE | C40: =ROUND(IF(ISBLANK(Original!C40),'Base projeção'!C40*'Base projeção'!$A$16,Original!C40),0) -> 0 | D40: =ROUND(IF(ISBLANK(Original!D40),'Base projeção'!D40*'Base projeção'!$A$16,Original!D40),0) -> 0 | E40: =ROUND(IF(ISBLANK(Original!E40),'Base projeção'!E40*'Base projeção'!$A$16,Original!E40),0) -> 0 | F40: =ROUND(IF(ISBLANK(Original!F40),'Base projeção'!F40*'Base projeção'!$A$16,Original!F40),0) -> 0 | G40: =ROUND(IF(ISBLANK(Original!G40),'Base projeção'!G40*'Base projeção'!$A$16,Original!G40),0) -> 0 | H40: =ROUND(IF(ISBLANK(Original!H40),'Base projeção'!H40*'Base projeção'!$A$16,Original!H40),0) -> 0 | I40: =ROUND(IF(ISBLANK(Original!I40),'Base projeção'!I40*'Base projeção'!$A$16,Original!I40),0) -> 0 | J40: =ROUND(IF(ISBLANK(Original!J40),'Base projeção'!J40*'Base projeção'!$A$16,Original!J40),0) -> 0 | ... P40: =ROUND(IF(ISBLANK(Original!P40),'Base projeção'!P40*'Base projeção'!$A$16,Original!P40),0) -> 0 | Q40: =SUM(C40:P40) -> 20 | R40: =Q40/$Q$15 -> 0.01953125
B41: Triciclo | C41: =ROUND(IF(ISBLANK(Original!C41),'Base projeção'!C41*'Base projeção'!$A$16,Original!C41),0) -> 0 | D41: =ROUND(IF(ISBLANK(Original!D41),'Base projeção'!D41*'Base projeção'!$A$16,Original!D41),0) -> 0 | E41: =ROUND(IF(ISBLANK(Original!E41),'Base projeção'!E41*'Base projeção'!$A$16,Original!E41),0) -> 0 | F41: =ROUND(IF(ISBLANK(Original!F41),'Base projeção'!F41*'Base projeção'!$A$16,Original!F41),0) -> 0 | G41: =ROUND(IF(ISBLANK(Original!G41),'Base projeção'!G41*'Base projeção'!$A$16,Original!G41),0) -> 0 | H41: =ROUND(IF(ISBLANK(Original!H41),'Base projeção'!H41*'Base projeção'!$A$16,Original!H41),0) -> 0 | I41: =ROUND(IF(ISBLANK(Original!I41),'Base projeção'!I41*'Base projeção'!$A$16,Original!I41),0) -> 0 | J41: =ROUND(IF(ISBLANK(Original!J41),'Base projeção'!J41*'Base projeção'!$A$16,Original!J41),0) -> 0 | ... P41: =ROUND(IF(ISBLANK(Original!P41),'Base projeção'!P41*'Base projeção'!$A$16,Original!P41),0) -> 0 | Q41: =SUM(C41:P41) -> 0 | R41: =Q41/$Q$15 -> 0
B42: Eletrica | C42: =ROUND(IF(ISBLANK(Original!C42),'Base projeção'!C42*'Base projeção'!$A$16,Original!C42),0) -> 0 | D42: =ROUND(IF(ISBLANK(Original!D42),'Base projeção'!D42*'Base projeção'!$A$16,Original!D42),0) -> 0 | E42: =ROUND(IF(ISBLANK(Original!E42),'Base projeção'!E42*'Base projeção'!$A$16,Original!E42),0) -> 0 | F42: =ROUND(IF(ISBLANK(Original!F42),'Base projeção'!F42*'Base projeção'!$A$16,Original!F42),0) -> 0 | G42: =ROUND(IF(ISBLANK(Original!G42),'Base projeção'!G42*'Base projeção'!$A$16,Original!G42),0) -> 0 | H42: =ROUND(IF(ISBLANK(Original!H42),'Base projeção'!H42*'Base projeção'!$A$16,Original!H42),0) -> 0 | I42: =ROUND(IF(ISBLANK(Original!I42),'Base projeção'!I42*'Base projeção'!$A$16,Original!I42),0) -> 0 | J42: =ROUND(IF(ISBLANK(Original!J42),'Base projeção'!J42*'Base projeção'!$A$16,Original!J42),0) -> 0 | ... P42: =ROUND(IF(ISBLANK(Original!P42),'Base projeção'!P42*'Base projeção'!$A$16,Original!P42),0) -> 0 | Q42: =SUM(C42:P42) -> 0 | R42: =Q42/$Q$15 -> 0
...

Sheet Original
A1: Dados quantitativos e sentido de deslocamento
A2: ORIGEM | B2: DESTINO | C2: 6 | D2: 7 | E2: 8 | F2: 9 | G2: 10 | H2: 11 | I2: 12 | J2: 13 | K2: 14 | L2: 15 | M2: 16 | N2: 17 | O2: 18 | P2: 19 | Q2: TOTAL | R2: %
A3: Jaqueira | B3: Graças | K3: 2 | L3: 0 | M3: 0 | N3: 0 | O3: 1 | Q3: =SUM(C3:P3) -> 3 | R3: =Q3/$Q$15 -> 0.0070093458
A4: Jaqueira | B4: Aflitos | K4: 1 | L4: 2 | M4: 0 | N4: 2 | O4: 0 | Q4: =SUM(C4:P4) -> 5 | R4: =Q4/$Q$15 -> 0.011682243
A5: Jaqueira | B5: Rosarinho | K5: 0 | L5: 2 | M5: 0 | N5: 0 | O5: 0 | Q5: =SUM(C5:P5) -> 2 | R5: =Q5/$Q$15 -> 0.0046728972
A6: Rosarinho | B6: Jaqueira | K6: 1 | L6: 0 | M6: 2 | N6: 3 | O6: 2 | Q6: =SUM(C6:P6) -> 8 | R6: =Q6/$Q$15 -> 0.018691589
A7: Rosarinho | B7: Graças | K7: 5 | L7: 9 | M7: 14 | N7: 14 | O7: 9 | Q7: =SUM(C7:P7) -> 51 | R7: =Q7/$Q$15 -> 0.11915888
A8: Rosarinho | B8: Aflitos | K8: 2 | L8: 5 | M8: 1 | N8: 2 | O8: 3 | Q8: =SUM(C8:P8) -> 13 | R8: =Q8/$Q$15 -> 0.030373832
A9: Graças | B9: Aflitos | K9: 2 | L9: 2 | M9: 0 | N9: 4 | O9: 0 | Q9: =SUM(C9:P9) -> 8 | R9: =Q9/$Q$15 -> 0.018691589
A10: Graças | B10: Rosarinho | K10: 0 | L10: 3 | M10: 2 | N10: 2 | O10: 1 | Q10: =SUM(C10:P10) -> 8 | R10: =Q10/$Q$15 -> 0.018691589
A11: Graças | B11: Jaqueira | K11: 1 | L11: 3 | M11: 5 | N11: 3 | O11: 3 | Q11: =SUM(C11:P11) -> 15 | R11: =Q11/$Q$15 -> 0.035046729
A12: Aflitos | B12: Rosarinho | K12: 2 | L12: 0 | M12: 0 | N12: 3 | O12: 0 | Q12: =SUM(C12:P12) -> 5 | R12: =Q12/$Q$15 -> 0.011682243
A13: Aflitos | B13: Jaqueira | K13: 37 | L13: 34 | M13: 67 | N13: 75 | O13: 66 | Q13: =SUM(C13:P13) -> 279 | R13: =Q13/$Q$15 -> 0.65186916
A14: Aflitos | B14: Graças | K14: 7 | L14: 6 | M14: 5 | N14: 9 | O14: 4 | Q14: =SUM(C14:P14) -> 31 | R14: =Q14/$Q$15 -> 0.072429907
B15: TOTAL | C15: =SUM(C$3:C$14) -> 0 | D15: =SUM(D$3:D$14) -> 0 | E15: =SUM(E$3:E$14) -> 0 | F15: =SUM(F$3:F$14) -> 0 | G15: =SUM(G$3:G$14) -> 0 | H15: =SUM(H$3:H$14) -> 0 | I15: =SUM(I$3:I$14) -> 0 | J15: =SUM(J$3:J$14) -> 0 | ... Q15: =SUM(Q$3:Q$14) -> 428
B16: Percentual | C16: =C15/$Q$15 -> 0 | D16: =D15/$Q$15 -> 0 | E16: =E15/$Q$15 -> 0 | F16: =F15/$Q$15 -> 0 | G16: =G15/$Q$15 -> 0 | H16: =H15/$Q$15 -> 0 | I16: =I15/$Q$15 -> 0 | J16: =J15/$Q$15 -> 0 | ... P16: =P15/$Q$15 -> 0 | Q16: =SUM(C16:P16) -> 1
A18: Dados qualitativos padrões
B19: Característica | C19: 6 | D19: 7 | E19: 8 | F19: 9 | G19: 10 | H19: 11 | I19: 12 | J19: 13 | K19: 14 | L19: 15 | M19: 16 | N19: 17 | O19: 18 | P19: 19 | Q19: TOTAL | R19: %
B20: Mulher | K20: 2 | L20: 7 | M20: 6 | N20: 9 | O20: 10 | Q20: =SUM(C20:P20) -> 34 | R20: =Q20/$Q$15 -> 0.079439252
B21: Crianças e adolescentes | K21: 0 | L21: 1 | M21: 0 | N21: 0 | O21: 0 | Q21: =SUM(C21:P21) -> 1 | R21: =Q21/$Q$15 -> 0.0023364486
B22: Capacete | K22: 3 | L22: 4 | M22: 11 | N22: 19 | O22: 19 | Q22: =SUM(C22:P22) -> 56 | R22: =Q22/$Q$15 -> 0.13084112
B23: Caronas | K23: =SUM(K31:K33) -> 1 | L23: =SUM(L31:L33) -> 1 | M23: =SUM(M31:M33) -> 1 | N23: =SUM(N31:N33) -> 2 | O23: =SUM(O31:O33) -> 2 | Q23: =SUM(C23:P23) -> 7 | R23: =Q23/$Q$15 -> 0.01635514
B24: Cargueiras | K24: =SUM(K34:K35) -> 5 | L24: =SUM(L34:L35) -> 13 | M24: =SUM(M34:M35) -> 10 | N24: =SUM(N34:N35) -> 12 | O24: =SUM(O34:O35) -> 7 | Q24: =SUM(C24:P24) -> 47 | R24: =Q24/$Q$15 -> 0.10981308
B25: Serviço | K25: =SUM(K36:K37) -> 11 | L25: =SUM(L36:L37) -> 7 | M25: =SUM(M36:M37) -> 14 | N25: =SUM(N36:N37) -> 9 | O25: =SUM(O36:O37) -> 6 | Q25: =SUM(C25:P25) -> 47 | R25: =Q25/$Q$15 -> 0.10981308
B26: Contramão | K26: =SUM(K38:K39) -> 9 | L26: =SUM(L38:L39) -> 16 | M26: =SUM(M38:M39) -> 10 | N26: =SUM(N38:N39) -> 12 | O26: =SUM(O38:O39) -> 6 | Q26: =SUM(C26:P26) -> 53 | R26: =Q26/$Q$15 -> 0.12383178
B27: Calçada | K27: 2 | L27: 6 | M27: 7 | N27: 16 | O27: 5 | Q27: =SUM(C27:P27) -> 36 | R27: =Q27/$Q$15 -> 0.08411215
A29: Dados qualitativos das observações
B30: Característica | C30: 6 | D30: 7 | E30: 8 | F30: 9 | G30: 10 | H30: 11 | I30: 12 | J30: 13 | K30: 14 | L30: 15 | M30: 16 | N30: 17 | O30: 18 | P30: 19 | Q30: TOTAL | R30: %
B31: Carona criança | K31: 0 | L31: 1 | M31: 1 | N31: 0 | O31: 0 | Q31: =SUM(C31:P31) -> 2 | R31: =Q31/$Q$15 -> 0.0046728972
B32: Carona mulher | K32: 0 | L32: 0 | M32: 0 | N32: 1 | O32: 1 | Q32: =SUM(C32:P32) -> 2 | R32: =Q32/$Q$15 -> 0.0046728972
B33: Carona homem | K33: 1 | L33: 0 | M33: 0 | N33: 1 | O33: 1 | Q33: =SUM(C33:P33) -> 3 | R33: =Q33/$Q$15 -> 0.0070093458
B34: Cargueira | K34: 5 | L34: 8 | M34: 8 | N34: 4 | O34: 2 | Q34: =SUM(C34:P34) -> 27 | R34: =Q34/$Q$15 -> 0.063084112
B35: Adaptada a carga | K35: 0 | L35: 5 | M35: 2 | N35: 8 | O35: 5
B36: Serviço | K36: 2 | L36: 7 | M36: 8 | N36: 0 | O36: 1 | Q36: =SUM(C36:P36) -> 18 | R36: =Q36/$Q$15 -> 0.042056075
B37: Serviço App | K37: 9 | L37: 0 | M37: 6 | N37: 9 | O37: 5
B38: Contramao | K38: 8 | L38: 14 | M38: 8 | N38: 12 | O38: 4 | Q38: =SUM(C38:P38) -> 46 | R38: =Q38/$Q$15 -> 0.10747664
B39: Contramão para conversão | K39: 1 | L39: 2 | M39: 2 | N39: 0 | O39: 2 | Q39: =SUM(C39:P39) -> 7 | R39: =Q39/$Q$15 -> 0.01635514
B40: Bike PE | K40: 1 | L40: 5 | N40: 4 | O40: 10 | Q40: =SUM(C40:P40) -> 20 | R40: =Q40/$Q$15 -> 0.046728972
B41: Triciclo | Q41: =SUM(C41:P41) -> 0 | R41: =Q41/$Q$15 -> 0
B42: Eletrica | Q42: =SUM(C42:P42) -> 0 | R42: =Q42/$Q$15 -> 0
...

Sheet Base projeção
A1: Dados quantitativos e sentido de deslocamento
A2: ORIGEM | B2: DESTINO | C2: 6 | D2: 7 | E2: 8 | F2: 9 | G2: 10 | H2: 11 | I2: 12 | J2: 13 | K2: 14 | L2: 15 | M2: 16 | N2: 17 | O2: 18 | P2: 19 | Q2: TOTAL | R2: %
A3: Jaqueira | B3: Rio Capibaribe | C3: 0 | D3: 3 | E3: 1 | F3: 0 | G3: 2 | H3: 3 | I3: 1 | J3: 0 | K3: 2 | L3: 1 | M3: 2 | N3: 4 | O3: 1 | P3: 0 | Q3: =SUM(C3:P3) -> 20 | R3: =Q3/$Q$15 -> 0.023337223
A4: Jaqueira | B4: Graças | C4: 1 | D4: 2 | E4: 4 | F4: 0 | G4: 2 | H4: 2 | I4: 2 | J4: 0 | K4: 1 | L4: 2 | M4: 1 | N4: 1 | O4: 0 | P4: 0 | Q4: =SUM(C4:P4) -> 18 | R4: =Q4/$Q$15 -> 0.021003501
A5: Jaqueira | B5: Rosarinho | C5: 0 | D5: 0 | E5: 1 | F5: 0 | G5: 1 | H5: 0 | I5: 1 | J5: 0 | K5: 0 | L5: 2 | M5: 1 | N5: 0 | O5: 0 | P5: 0 | Q5: =SUM(C5:P5) -> 6 | R5: =Q5/$Q$15 -> 0.0070011669
A6: Rosarinho | B6: Jaqueira | C6: 0 | D6: 0 | E6: 3 | F6: 2 | G6: 1 | H6: 2 | I6: 7 | J6: 0 | K6: 4 | L6: 2 | M6: 1 | N6: 3 | O6: 0 | P6: 2 | Q6: =SUM(C6:P6) -> 27 | R6: =Q6/$Q$15 -> 0.031505251
A7: Rosarinho | B7: Rio Capibaribe | C7: 18 | D7: 27 | E7: 15 | F7: 11 | G7: 10 | H7: 5 | I7: 2 | J7: 5 | K7: 13 | L7: 9 | M7: 12 | N7: 16 | O7: 11 | P7: 6 | Q7: =SUM(C7:P7) -> 160 | R7: =Q7/$Q$15 -> 0.18669778
A8: Rosarinho | B8: Graças | C8: 0 | D8: 4 | E8: 4 | F8: 2 | G8: 1 | H8: 4 | I8: 3 | J8: 3 | K8: 4 | L8: 3 | M8: 2 | N8: 1 | O8: 2 | P8: 1 | Q8: =SUM(C8:P8) -> 34 | R8: =Q8/$Q$15 -> 0.039673279
A9: Graças | B9: Rosarinho | C9: 0 | D9: 1 | E9: 2 | F9: 3 | G9: 0 | H9: 2 | I9: 23 | J9: 0 | K9: 0 | L9: 4 | M9: 2 | N9: 0 | O9: 4 | P9: 1 | Q9: =SUM(C9:P9) -> 42 | R9: =Q9/$Q$15 -> 0.049008168
A10: Graças | B10: Jaqueira | C10: 24 | D10: 22 | E10: 27 | F10: 21 | G10: 24 | H10: 34 | I10: 7 | J10: 14 | K10: 15 | L10: 17 | M10: 56 | N10: 59 | O10: 39 | P10: 34 | Q10: =SUM(C10:P10) -> 393 | R10: =Q10/$Q$15 -> 0.45857643
A11: Graças | B11: Rio Capibaribe | C11: 1 | D11: 4 | E11: 4 | F11: 9 | G11: 4 | H11: 7 | I11: 3 | J11: 5 | K11: 4 | L11: 5 | M11: 3 | N11: 6 | O11: 3 | P11: 5 | Q11: =SUM(C11:P11) -> 63 | R11: =Q11/$Q$15 -> 0.073512252
A12: Rio Capibaribe | B12: Graças | C12: 1 | D12: 2 | E12: 1 | F12: 1 | G12: 4 | H12: 4 | I12: 5 | J12: 2 | K12: 3 | L12: 3 | M12: 3 | N12: 3 | O12: 3 | P12: 0 | Q12: =SUM(C12:P12) -> 35 | R12: =Q12/$Q$15 -> 0.04084014
A13: Rio Capibaribe | B13: Rosarinho | C13: 4 | D13: 1 | E13: 3 | F13: 2 | G13: 3 | H13: 4 | I13: 1 | J13: 3 | K13: 2 | L13: 0 | M13: 2 | N13: 4 | O13: 0 | P13: 2 | Q13: =SUM(C13:P13) -> 31 | R13: =Q13/$Q$15 -> 0.036172695
A14: Rio Capibaribe | B14: Jaqueira | C14: 0 | D14: 0 | E14: 1 | F14: 2 | G14: 3 | H14: 2 | I14: 1 | J14: 3 | K14: 3 | L14: 1 | M14: 3 | N14: 6 | O14: 2 | P14: 1 | Q14: =SUM(C14:P14) -> 28 | R14: =Q14/$Q$15 -> 0.032672112
A15: AUMENTO | B15: TOTAL | C15: =SUM(C$3:C$14) -> 49 | D15: =SUM(D$3:D$14) -> 66 | E15: =SUM(E$3:E$14) -> 66 | F15: =SUM(F$3:F$14) -> 53 | G15: =SUM(G$3:G$14) -> 55 | H15: =SUM(H$3:H$14) -> 69 | I15: =SUM(I$3:I$14) -> 56 | J15: =SUM(J$3:J$14) -> 35 | ... Q15: =SUM(Q$3:Q$14) -> 857
A16: =Original!Q15/SUM(K15:O15) -> 1.2022472 | B16: Percentual | C16: =C15/$Q$15 -> 0.057176196 | D16: =D15/$Q$15 -> 0.077012835 | E16: =E15/$Q$15 -> 0.077012835 | F16: =F15/$Q$15 -> 0.061843641 | G16: =G15/$Q$15 -> 0.064177363 | H16: =H15/$Q$15 -> 0.080513419 | I16: =I15/$Q$15 -> 0.065344224 | J16: =J15/$Q$15 -> 0.04084014 | ... P16: =P15/$Q$15 -> 0.060676779 | Q16: =SUM(C16:P16) -> 1
A18: Dados qualitativos padrões
B19: Característica | C19: 6 | D19: 7 | E19: 8 | F19: 9 | G19: 10 | H19: 11 | I19: 12 | J19: 13 | K19: 14 | L19: 15 | M19: 16 | N19: 17 | O19: 18 | P19: 19 | Q19: TOTAL | R19: %
B20: Mulher | C20: 3 | D20: 0 | E20: 2 | F20: 6 | G20: 3 | H20: 3 | I20: 1 | J20: 6 | K20: 6 | L20: 6 | M20: 0 | N20: 6 | O20: 5 | P20: 1 | Q20: =SUM(C20:P20) -> 48 | R20: =Q20/$Q$15 -> 0.056009335
B21: Crianças e adolescentes | C21: 4 | D21: 3 | E21: 0 | F21: 0 | G21: 0 | H21: 1 | I21: 4 | J21: 6 | K21: 5 | L21: 3 | M21: 3 | N21: 3 | O21: 1 | P21: 0 | Q21: =SUM(C21:P21) -> 33 | R21: =Q21/$Q$15 -> 0.038506418
B22: Capacete | C22: 9 | D22: 4 | E22: 7 | F22: 9 | G22: 8 | H22: 7 | I22: 7 | J22: 5 | K22: 6 | L22: 3 | M22: 8 | N22: 14 | O22: 10 | P22: 15 | Q22: =SUM(C22:P22) -> 112 | R22: =Q22/$Q$15 -> 0.13068845
B23: Carona criança | C23: 1 | D23: 0 | E23: 1 | F23: 1 | G23: 0 | H23: 1 | I23: 0 | J23: 0 | K23: 0 | L23: 1 | M23: 0 | N23: 0 | O23: 0 | P23: 0 | Q23: =SUM(C23:P23) -> 5 | R23: =Q23/$Q$15 -> 0.0058343057
B24: Carona mulher | C24: 1 | D24: 0 | E24: 2 | F24: 0 | G24: 1 | H24: 0 | I24: 0 | J24: 0 | K24: 0 | L24: 0 | M24: 1 | N24: 0 | O24: 0 | P24: 0 | Q24: =SUM(C24:P24) -> 5 | R24: =Q24/$Q$15 -> 0.0058343057
B25: Carona homem | C25: 0 | D25: 0 | E25: 1 | F25: 0 | G25: 0 | H25: 0 | I25: 0 | J25: 1 | K25: 0 | L25: 0 | M25: 0 | N25: 0 | O25: 1 | P25: 0 | Q25: =SUM(C25:P25) -> 3 | R25: =Q25/$Q$15 -> 0.0035005834
B26: Cargueira | C26: 2 | D26: 3 | E26: 7 | F26: 6 | G26: 5 | H26: 14 | I26: 13 | J26: 3 | K26: 8 | L26: 12 | M26: 12 | N26: 6 | O26: 5 | P26: 2 | Q26: =SUM(C26:P26) -> 98 | R26: =Q26/$Q$15 -> 0.11435239
B27: Adaptada a carga | C27: 3 | D27: 1 | E27: 4 | F27: 5 | G27: 2 | H27: 4 | I27: 0 | J27: 0 | K27: 1 | L27: 0 | M27: 0 | N27: 9 | O27: 2 | P27: 1
B28: Serviço | C28: 0 | D28: 2 | E28: 7 | F28: 5 | G28: 8 | H28: 19 | I28: 12 | J28: 3 | K28: 10 | L28: 10 | M28: 11 | N28: 6 | O28: 3 | P28: 1 | Q28: =SUM(C28:P28) -> 97 | R28: =Q28/$Q$15 -> 0.11318553
B29: Contramao | C29: 2 | D29: 6 | E29: 12 | F29: 8 | G29: 15 | H29: 13 | I29: 10 | J29: 5 | K29: 10 | L29: 4 | M29: 11 | N29: 14 | O29: 10 | P29: 4 | Q29: =SUM(C29:P29) -> 124 | R29: =Q29/$Q$15 -> 0.14469078
B30: Contramão para conversão | C30: 0 | D30: 0 | E30: 0 | F30: 0 | G30: 0 | H30: 0 | I30: 0 | J30: 0 | K30: 0 | L30: 0 | M30: 0 | N30: 0 | O30: 0 | P30: 0 | Q30: =SUM(C30:P30) -> 0 | R30: =Q30/$Q$15 -> 0
B31: Calçada | C31: 3 | D31: 9 | E31: 7 | F31: 12 | G31: 13 | H31: 12 | I31: 8 | J31: 7 | K31: 14 | L31: 11 | M31: 7 | N31: 7 | O31: 7 | P31: 3 | Q31: =SUM(C31:P31) -> 120 | R31: =Q31/$Q$15 -> 0.14002334
A33: Dados qualitativos das observações
B34: Característica | C34: 6 | D34: 7 | E34: 8 | F34: 9 | G34: 10 | H34: 11 | I34: 12 | J34: 13 | K34: 14 | L34: 15 | M34: 16 | N34: 17 | O34: 18 | P34: 19 | Q34: TOTAL | R34: %
B35: Bike PE | C35: 0 | D35: 0 | E35: 0 | F35: 0 | G35: 0 | H35: 0 | I35: 0 | J35: 0 | K35: 1 | L35: 0 | M35: 2 | N35: 0 | O35: 2 | P35: 1 | Q35: =SUM(C35:P35) -> 6 | R35: =Q35/$Q$15 -> 0.0070011669
B36: Triciclo | C36: 0 | D36: 0 | E36: 0 | F36: 0 | G36: 0 | H36: 0 | I36: 0 | J36: 0 | K36: 0 | L36: 0 | M36: 2 | N36: 1 | O36: 0 | P36: 0 | Q36: =SUM(C36:P36) -> 3 | R36: =Q36/$Q$15 -> 0.0035005834
B37: Eletrica | C37: 0 | D37: 1 | E37: 0 | F37: 0 | G37: 0 | H37: 1 | I37: 0 | J37: 0 | K37: 0 | L37: 0 | M37: 2 | N37: 0 | O37: 0 | P37: 0 | Q37: =SUM(C37:P37) -> 4 | R37: =Q37/$Q$15 -> 0.0046674446
B38: Skate | C38: 0 | D38: 0 | E38: 0 | F38: 0 | G38: 3 | H38: 0 | I38: 0 | J38: 0 | K38: 1 | L38: 0 | M38: 0 | N38: 0 | O38: 0 | P38: 0 | Q38: =SUM(C38:P38) -> 4 | R38: =Q38/$Q$15 -> 0.0046674446
B39: Grupos de pedal | C39: 0 | D39: 0 | E39: 0 | F39: 0 | G39: 0 | H39: 0 | I39: 0 | J39: 0 | K39: 0 | L39: 0 | M39: 0 | N39: 0 | O39: 0 | P39: 0 | Q39: =SUM(C39:P39) -> 0 | R39: =Q39/$Q$15 -> 0
C45: =C34 -> 6 | D45: =D34 -> 7 | E45: =E34 -> 8 | F45: =F34 -> 9 | G45: =G34 -> 10 | H45: =H34 -> 11 | I45: =I34 -> 12 | J45: =J34 -> 13 | ... P45: =P34 -> 19
C46: =C15 -> 49 | D46: =D15 -> 66 | E46: =E15 -> 66 | F46: =F15 -> 53 | G46: =G15 -> 55 | H46: =H15 -> 69 | I46: =I15 -> 56 | J46: =J15 -> 35 | ... P46: =P15 -> 52
K47: =Original!K15 -> 60 | L47: =Original!L15 -> 66 | M47: =Original!M15 -> 96 | N47: =Original!N15 -> 117 | O47: =Original!O15 -> 89

Sheet CONFFLUXO
A1: =Fluxo!A2 -> TOTAL | F1: 2 | G1: {=TRANSPOSE(Dados!2:2)} -> ORIGEM
F2: 3 | G2: DESTINO
A3: =Dados!A3 -> Jaqueira | B3: =Dados!B3 -> Graças | F3: 4 | G3: 6 | Q3: =HLOOKUP($A$1,Dados!$C$2:$R$14,F1,0) -> 15
A4: =Dados!A4 -> Jaqueira | B4: =Dados!B4 -> Aflitos | F4: 5 | G4: 7 | Q4: =HLOOKUP($A$1,Dados!$C$2:$R$14,F2,0) -> 19
A5: =Dados!A5 -> Jaqueira | B5: =Dados!B5 -> Rosarinho | F5: 6 | G5: 8 | Q5: =HLOOKUP($A$1,Dados!$C$2:$R$14,F3,0) -> 5
A6: =Dados!A6 -> Rosarinho | B6: =Dados!B6 -> Jaqueira | F6: 7 | G6: 9 | Q6: =HLOOKUP($A$1,Dados!$C$2:$R$14,F4,0) -> 27
A7: =Dados!A7 -> Rosarinho | B7: =Dados!B7 -> Graças | F7: 8 | G7: 10 | Q7: =HLOOKUP($A$1,Dados!$C$2:$R$14,F5,0) -> 169
A8: =Dados!A8 -> Rosarinho | B8: =Dados!B8 -> Aflitos | F8: 9 | G8: 11 | Q8: =HLOOKUP($A$1,Dados!$C$2:$R$14,F6,0) -> 40
A9: =Dados!A9 -> Graças | B9: =Dados!B9 -> Aflitos | F9: 10 | G9: 12 | Q9: =HLOOKUP($A$1,Dados!$C$2:$R$14,F7,0) -> 46
A10: =Dados!A10 -> Graças | B10: =Dados!B10 -> Rosarinho | F10: 11 | G10: 13 | Q10: =HLOOKUP($A$1,Dados!$C$2:$R$14,F8,0) -> 256
A11: =Dados!A11 -> Graças | B11: =Dados!B11 -> Jaqueira | F11: 12 | G11: 14 | Q11: =HLOOKUP($A$1,Dados!$C$2:$R$14,F9,0) -> 66
A12: =Dados!A12 -> Aflitos | B12: =Dados!B12 -> Rosarinho | F12: 13 | G12: 15 | Q12: =HLOOKUP($A$1,Dados!$C$2:$R$14,F10,0) -> 28
A13: =Dados!A13 -> Aflitos | B13: =Dados!B13 -> Jaqueira | G13: 16 | Q13: =HLOOKUP($A$1,Dados!$C$2:$R$14,F11,0) -> 307
A14: =Dados!A14 -> Aflitos | B14: =Dados!B14 -> Graças | G14: 17 | Q14: =HLOOKUP($A$1,Dados!$C$2:$R$14,F12,0) -> 46
G15: 18
G16: 19
G17: TOTAL
G18: %

Sheet Gráficos
A1: Ciclistas por hora
A2: Horário início | B2: =Dados!C2 -> 6 | C2: =Dados!D2 -> 7 | D2: =Dados!E2 -> 8 | E2: =Dados!F2 -> 9 | F2: =Dados!G2 -> 10 | G2: =Dados!H2 -> 11 | H2: =Dados!I2 -> 12 | I2: =Dados!J2 -> 13 | ... O2: =Dados!P2 -> 19
A3: Homens | B3: =Dados!C15-B4-B5 -> 50 | C3: =Dados!D15-C4-C5 -> 74 | D3: =Dados!E15-D4-D5 -> 77 | E3: =Dados!F15-E4-E5 -> 55 | F3: =Dados!G15-F4-F5 -> 62 | G3: =Dados!H15-G4-G5 -> 77 | H3: =Dados!I15-H4-H5 -> 60 | I3: =Dados!J15-I4-I5 -> 29 | ... O3: =Dados!P15-O4-O5 -> 60
A4: Mulheres | B4: =Dados!C20 -> 4 | C4: =Dados!D20 -> 0 | D4: =Dados!E20 -> 2 | E4: =Dados!F20 -> 7 | F4: =Dados!G20 -> 4 | G4: =Dados!H20 -> 4 | H4: =Dados!I20 -> 1 | I4: =Dados!J20 -> 7 | ... O4: =Dados!P20 -> 1
A5: Crianças e adolescentes | B5: =Dados!C21 -> 5 | C5: =Dados!D21 -> 4 | D5: =Dados!E21 -> 0 | E5: =Dados!F21 -> 0 | F5: =Dados!G21 -> 0 | G5: =Dados!H21 -> 1 | H5: =Dados!I21 -> 5 | I5: =Dados!J21 -> 7 | ... O5: =Dados!P21 -> 0
A7: Ciclistas por hora %
A8: Horário | B8: 6 | C8: 7 | D8: 8 | E8: 9 | F8: 10 | G8: 11 | H8: 12 | I8: 13 | J8: 14 | K8: 15 | L8: 16 | M8: 17 | N8: 18 | O8: 19
A9: Mulheres | B9: =B4/Dados!C$15 -> 0.06779661 | C9: =C4/Dados!D$15 -> 0 | D9: =D4/Dados!E$15 -> 0.025316456 | E9: =E4/Dados!F$15 -> 0.11290323 | F9: =F4/Dados!G$15 -> 0.060606061 | G9: =G4/Dados!H$15 -> 0.048780488 | H9: =H4/Dados!I$15 -> 0.015151515 | I9: =I4/Dados!J$15 -> 0.1627907 | ... O9: =O4/Dados!P$15 -> 0.016393443
A10: Crianças e adolescentes | B10: =B5/Dados!C$15 -> 0.084745763 | C10: =C5/Dados!D$15 -> 0.051282051 | D10: =D5/Dados!E$15 -> 0 | E10: =E5/Dados!F$15 -> 0 | F10: =F5/Dados!G$15 -> 0 | G10: =G5/Dados!H$15 -> 0.012195122 | H10: =H5/Dados!I$15 -> 0.075757576 | I10: =I5/Dados!J$15 -> 0.1627907 | ... O10: =O5/Dados!P$15 -> 0
A12: =Dados!B19 -> Característica | B12: =Dados!R19 -> %
A13: =Dados!B20 -> Mulher | B13: =Dados!R20 -> 0.0625
A14: =Dados!B21 -> Crianças e adolescentes | B14: =Dados!R21 -> 0.022460938
A15: =Dados!B22 -> Capacete | B15: =Dados!R22 -> 0.13769531
A16: Caronas | B16: =SUM(Dados!R23:R25) -> 0.10839844
A17: =Dados!B26 -> Contramão | B17: =Dados!R26 -> 0.11621094
A18: =Dados!B31 -> Carona criança | B18: =Dados!R31 -> 0.088867188
A19: =Dados!B33 -> Carona homem | B19: =Dados!R33 -> 0.0029296875
A20: =Dados!B35 -> Adaptada a carga | B20: =Dados!R35 -> 0.020507812

Sheet Fluxo
A1: HORÁRIO | E1: =UPPER(CONFFLUXO!A3) -> JAQUEIRA
A2: TOTAL | E2: =SUM(E3:G3) -> 39
E3: =CONFFLUXO!Q3 -> 15 | F3: =CONFFLUXO!Q4 -> 19 | G3: =CONFFLUXO!Q5 -> 5
A5: =UPPER(CONFFLUXO!A12) -> AFLITOS | B5: =SUM(C5:C7) -> 381 | C5: =CONFFLUXO!Q14 -> 46 | I5: =CONFFLUXO!Q6 -> 27 | J5: =SUM(I5:I7) -> 236 | K5: =UPPER(CONFFLUXO!A6) -> ROSARINHO
C6: =CONFFLUXO!Q13 -> 307 | F6: =SUM(E3:G3,I5:I7,E9:G9,C5:C7) -> 1024 | I6: =CONFFLUXO!Q7 -> 169
C7: =CONFFLUXO!Q12 -> 28 | I7: =CONFFLUXO!Q8 -> 40
E9: =CONFFLUXO!Q11 -> 66 | F9: =CONFFLUXO!Q10 -> 256 | G9: =CONFFLUXO!Q9 -> 46
E10: =SUM(E9:G9) -> 368
E11: =UPPER(CONFFLUXO!A9) -> GRAÇAS | K11: =MAX(3:3,I:I,9:9,C:C) -> 307
