Workbook

Sheet Resumo
A1: Cruzamento | B1: Av. Gov. Agamenon Magalhães x Praça do Derby - Pista Leste
A2: Data | B2: 45428
A3: Coordenadas Geográficas | B3: -8.05661, -34.89772
A4: Relatório | B4: https://docs.google.com/document/d/1BZJUktFWwg41ilPXeb55opLide8Hn3ww/edit?usp=drive_link&ouid=106119240800332821299&rtpof=true&sd=true
A5: Total | B5: =Dados!R15 -> 2013
A6: Máximo em um hora | B6: =MAX(Dados!D15:Q15) -> 311
A7: Mulher | B7: =Dados!S20 -> 0.077496274
A8: Crianças e adolescentes | B8: =Dados!S21 -> 0.0069547938
A9: Capacete | B9: =Dados!S22 -> 0.094386488
A10: Caronas | B10: =Dados!S23 -> 0.017386985
A11: Cargueiras | B11: =Dados!S24 -> 0.056631893
A12: Serviço | B12: =Dados!S25 -> 0.03030303
A13: Contramão | B13: =Dados!S26 -> 0.055638351
A14: Calçada | B14: =Dados!S27 -> 0.084451068

Sheet Dados
B1: Dados quantitativos e sentido de deslocamento
B2: ORIGEM | C2: DESTINO | D2: 6 | E2: 7 | F2: 8 | G2: 9 | H2: 10 | I2: 11 | J2: 12 | K2: 13 | L2: 14 | M2: 15 | N2: 16 | O2: 17 | P2: 18 | Q2: 19 | R2: TOTAL | S2: %
B3: OLINDA | C3: =B12 -> DERBY | D3: 3 | E3: 3 | F3: 1 | G3: 1 | H3: 1 | I3: 5 | J3: 5 | K3: 1 | L3: 5 | M3: 0 | N3: 4 | O3: 13 | P3: 7 | Q3: 1 | R3: =SUM(D3:Q3) -> 50 | S3: =R3/$R$15 -> 0.024838549
B4: =B3 -> OLINDA | C4: =B9 -> BOA VIAGEM | D4: 4 | E4: 2 | F4: 2 | G4: 2 | H4: 1 | I4: 4 | J4: 1 | K4: 3 | L4: 1 | M4: 0 | N4: 1 | O4: 2 | P4: 0 | Q4: 2 | R4: =SUM(D4:Q4) -> 25 | S4: =R4/$R$15 -> 0.012419275
B5: =B3 -> OLINDA | C5: =B6 -> BOA VISTA | D5: 0 | E5: 0 | F5: 1 | G5: 0 | H5: 0 | I5: 3 | J5: 3 | K5: 0 | L5: 7 | M5: 1 | N5: 5 | O5: 2 | P5: 2 | Q5: 1 | R5: =SUM(D5:Q5) -> 25 | S5: =R5/$R$15 -> 0.012419275
B6: BOA VISTA | C6: =B3 -> OLINDA | D6: 0 | E6: 1 | F6: 1 | G6: 0 | H6: 2 | I6: 3 | J6: 1 | K6: 5 | L6: 3 | M6: 1 | N6: 5 | O6: 2 | P6: 2 | Q6: 0 | R6: =SUM(D6:Q6) -> 26 | S6: =R6/$R$15 -> 0.012916046
B7: =B6 -> BOA VISTA | C7: =B12 -> DERBY | D7: 7 | E7: 9 | F7: 7 | G7: 26 | H7: 4 | I7: 31 | J7: 0 | K7: 30 | L7: 33 | M7: 38 | N7: 74 | O7: 124 | P7: 61 | Q7: 30 | R7: =SUM(D7:Q7) -> 474 | S7: =R7/$R$15 -> 0.23546945
B8: =B6 -> BOA VISTA | C8: =B9 -> BOA VIAGEM | D8: 0 | E8: 1 | F8: 1 | G8: 0 | H8: 1 | I8: 1 | J8: 0 | K8: 1 | L8: 0 | M8: 4 | N8: 4 | O8: 0 | P8: 0 | Q8: 3 | R8: =SUM(D8:Q8) -> 16 | S8: =R8/$R$15 -> 0.0079483358
B9: BOA VIAGEM | C9: =B6 -> BOA VISTA | D9: 1 | E9: 5 | F9: 2 | G9: 3 | H9: 2 | I9: 2 | J9: 1 | K9: 3 | L9: 2 | M9: 2 | N9: 3 | O9: 3 | P9: 5 | Q9: 3 | R9: =SUM(D9:Q9) -> 37 | S9: =R9/$R$15 -> 0.018380527
B10: =B9 -> BOA VIAGEM | C10: =B3 -> OLINDA | D10: 30 | E10: 41 | F10: 21 | G10: 18 | H10: 15 | I10: 13 | J10: 29 | K10: 19 | L10: 19 | M10: 39 | N10: 59 | O10: 90 | P10: 62 | Q10: 28 | R10: =SUM(D10:Q10) -> 483 | S10: =R10/$R$15 -> 0.23994039
B11: =B9 -> BOA VIAGEM | C11: =B12 -> DERBY | D11: 3 | E11: 1 | F11: 2 | G11: 2 | H11: 6 | I11: 6 | J11: 4 | K11: 3 | L11: 1 | M11: 2 | N11: 16 | O11: 10 | P11: 12 | Q11: 6 | R11: =SUM(D11:Q11) -> 74 | S11: =R11/$R$15 -> 0.036761053
B12: DERBY | C12: =B9 -> BOA VIAGEM | D12: 0 | E12: 0 | F12: 1 | G12: 0 | H12: 1 | I12: 0 | J12: 1 | K12: 0 | L12: 0 | M12: 0 | N12: 1 | O12: 0 | P12: 0 | Q12: 2 | R12: =SUM(D12:Q12) -> 6 | S12: =R12/$R$15 -> 0.0029806259
B13: =B12 -> DERBY | C13: =B6 -> BOA VISTA | D13: 59 | E13: 87 | F13: 58 | G13: 42 | H13: 38 | I13: 29 | J13: 40 | K13: 24 | L13: 23 | M13: 42 | N13: 21 | O13: 23 | P13: 31 | Q13: 34 | R13: =SUM(D13:Q13) -> 551 | S13: =R13/$R$15 -> 0.27372081
B14: =B12 -> DERBY | C14: =B3 -> OLINDA | D14: 19 | E14: 24 | F14: 23 | G14: 10 | H14: 14 | I14: 15 | J14: 11 | K14: 18 | L14: 7 | M14: 16 | N14: 16 | O14: 42 | P14: 28 | Q14: 3 | R14: =SUM(D14:Q14) -> 246 | S14: =R14/$R$15 -> 0.12220566
C15: TOTAL | D15: =SUM(D3:D14) -> 126 | E15: =SUM(E3:E14) -> 174 | F15: =SUM(F3:F14) -> 120 | G15: =SUM(G3:G14) -> 104 | H15: =SUM(H3:H14) -> 85 | I15: =SUM(I3:I14) -> 112 | J15: =SUM(J3:J14) -> 96 | K15: =SUM(K3:K14) -> 107 | ... Q15: =SUM(Q3:Q14) -> 113 | R15: =SUM(R$3:R$14) -> 2013
C16: Percentual | D16: =D15/$R$15 -> 0.062593145 | E16: =E15/$R$15 -> 0.086438152 | F16: =F15/$R$15 -> 0.059612519 | G16: =G15/$R$15 -> 0.051664183 | H16: =H15/$R$15 -> 0.042225534 | I16: =I15/$R$15 -> 0.055638351 | J16: =J15/$R$15 -> 0.047690015 | K16: =K15/$R$15 -> 0.053154496 | ... Q16: =Q15/$R$15 -> 0.056135122 | R16: =SUM(D16:Q16) -> 1
C18: Dados qualitativos padrões
C19: Característica | D19: 6 | E19: 7 | F19: 8 | G19: 9 | H19: 10 | I19: 11 | J19: 12 | K19: 13 | L19: 14 | M19: 15 | N19: 16 | O19: 17 | P19: 18 | Q19: 19 | R19: TOTAL | S19: %
C20: Mulher | D20: 5 | E20: 12 | F20: 17 | G20: 3 | H20: 8 | I20: 7 | J20: 12 | K20: 5 | L20: 9 | M20: 10 | N20: 26 | O20: 19 | P20: 12 | Q20: 11 | R20: =SUM(D20:Q20) -> 156 | S20: =R20/$R$15 -> 0.077496274
C21: Crianças e adolescentes | D21: 0 | E21: 0 | F21: 0 | G21: 0 | H21: 0 | I21: 0 | J21: 3 | K21: 2 | L21: 0 | M21: 0 | N21: 2 | O21: 5 | P21: 0 | Q21: 2 | R21: =SUM(D21:Q21) -> 14 | S21: =R21/$R$15 -> 0.0069547938
C22: Capacete | D22: 14 | E22: 27 | F22: 16 | G22: 10 | H22: 9 | I22: 4 | J22: 7 | K22: 5 | L22: 8 | M22: 6 | N22: 21 | O22: 29 | P22: 20 | Q22: 14 | R22: =SUM(D22:Q22) -> 190 | S22: =R22/$R$15 -> 0.094386488
C23: Caronas | D23: 2 | E23: 5 | F23: 1 | G23: 1 | H23: =SUM(H32:H34) -> 0 | I23: 2 | J23: 3 | K23: 3 | L23: =SUM(L32:L34) -> 0 | M23: 2 | N23: 3 | O23: 11 | P23: 1 | Q23: 1 | R23: =SUM(D23:Q23) -> 35 | S23: =R23/$R$15 -> 0.017386985
C24: Cargueiras | D24: 8 | E24: 9 | F24: 10 | G24: 9 | H24: 15 | I24: 10 | J24: 7 | K24: 2 | L24: 10 | M24: 8 | N24: 14 | O24: 3 | P24: 7 | Q24: 2 | R24: =SUM(D24:Q24) -> 114 | S24: =R24/$R$15 -> 0.056631893
C25: Serviço | D25: 1 | E25: 1 | F25: 0 | G25: =SUM(G37:G38) -> 12 | H25: 1 | I25: 2 | J25: 0 | K25: =SUM(K37:K38) -> 26 | L25: 3 | M25: 4 | N25: 8 | O25: 2 | P25: 1 | Q25: 0 | R25: =SUM(D25:Q25) -> 61 | S25: =R25/$R$15 -> 0.03030303
C26: Contramão | D26: 12 | E26: 5 | F26: 4 | G26: 0 | H26: 4 | I26: 4 | J26: 10 | K26: 6 | L26: 1 | M26: 2 | N26: 9 | O26: 38 | P26: 8 | Q26: =SUM(Q39:Q40) -> 9 | R26: =SUM(D26:Q26) -> 112 | S26: =R26/$R$15 -> 0.055638351
C27: Calçada | D27: 20 | E27: 20 | F27: 12 | G27: 4 | H27: 4 | I27: 5 | J27: 5 | K27: 4 | L27: 7 | M27: 15 | N27: 18 | O27: 38 | P27: 12 | Q27: 6 | R27: =SUM(D27:Q27) -> 170 | S27: =R27/$R$15 -> 0.084451068
C30: Dados qualitativos das observações
C31: Característica | D31: 6 | E31: 7 | F31: 8 | G31: 9 | H31: 10 | I31: 11 | J31: 12 | K31: 13 | L31: 14 | M31: 15 | N31: 16 | O31: 17 | P31: 18 | Q31: 19 | R31: TOTAL | S31: %
C32: Carona criança | D32: 1 | E32: 4 | F32: 0 | G32: 1 | H32: 0 | I32: 2 | J32: 2 | K32: 2 | L32: 0 | M32: 1 | N32: 1 | O32: 3 | P32: 0 | Q32: 1 | R32: =SUM(D32:Q32) -> 18 | S32: =R32/$R$15 -> 0.0089418778
C33: Carona mulher | D33: 1 | E33: 1 | F33: 1 | G33: 0 | H33: 0 | I33: 0 | J33: 1 | K33: 1 | L33: 0 | M33: 1 | N33: 2 | O33: 0 | P33: 1 | Q33: 0 | R33: =SUM(D33:Q33) -> 9 | S33: =R33/$R$15 -> 0.0044709389
C34: Carona homem | D34: 0 | E34: 0 | F34: 0 | G34: 0 | H34: 0 | I34: 0 | J34: 0 | K34: 0 | L34: 0 | M34: 0 | N34: 0 | O34: 0 | P34: 0 | Q34: 0 | R34: =SUM(D34:Q34) -> 0 | S34: =R34/$R$15 -> 0
C35: Cargueira tradicional | D35: 8 | E35: 9 | F35: 10 | G35: 9 | H35: 15 | I35: 10 | J35: 7 | K35: 2 | L35: 10 | M35: 8 | N35: 14 | O35: 11 | P35: 7 | Q35: 2 | R35: =SUM(D35:Q35) -> 122 | S35: =R35/$R$15 -> 0.060606061
C36: Adaptada a carga | D36: 8 | E36: 7 | F36: 6 | G36: 8 | H36: 9 | I36: 7 | J36: 4 | K36: 5 | L36: 10 | M36: 6 | N36: 13 | O36: 18 | P36: 5 | Q36: 8 | R36: =SUM(D36:Q36) -> 114 | S36: =R36/$R$15 -> 0.056631893
C37: Serviço | D37: 1 | E37: 1 | F37: 0 | G37: 0 | H37: 1 | I37: 2 | J37: 0 | K37: 0 | L37: 3 | M37: 4 | N37: 8 | O37: 2 | P37: 1 | Q37: 0 | R37: =SUM(D37:Q37) -> 23 | S37: =R37/$R$15 -> 0.011425733
C38: Serviço APP | D38: 0 | E38: 0 | F38: 2 | G38: 12 | H38: 15 | I38: 35 | J38: 45 | K38: 26 | L38: 24 | M38: 26 | N38: 26 | O38: 26 | P38: 17 | Q38: 15 | R38: =SUM(D38:Q38) -> 269 | S38: =R38/$R$15 -> 0.1336314
C39: Contramão | D39: 12 | E39: 5 | F39: 4 | G39: 0 | H39: 4 | I39: 4 | J39: 10 | K39: 6 | L39: 1 | M39: 2 | N39: 9 | O39: 38 | P39: 8 | Q39: 2 | R39: =SUM(D39:Q39) -> 105 | S39: =R39/$R$15 -> 0.052160954
C40: Contramão para conversão | D40: 10 | E40: 5 | F40: 0 | G40: 0 | H40: 0 | I40: 4 | J40: 0 | K40: 0 | L40: 4 | M40: 3 | N40: 22 | O40: 16 | P40: 10 | Q40: 7 | R40: =SUM(D40:Q40) -> 81 | S40: =R40/$R$15 -> 0.04023845
C41: Bike PE | D41: 4 | E41: 9 | F41: 16 | G41: 9 | H41: 5 | I41: 7 | J41: 14 | K41: 7 | L41: 5 | M41: 16 | N41: 27 | O41: 38 | P41: 20 | Q41: 20 | R41: =SUM(D41:Q41) -> 197 | S41: =R41/$R$15 -> 0.097863885
C42: Empurrando | D42: 0 | E42: 0 | F42: 3 | G42: 0 | H42: 0 | I42: 0 | J42: 0 | K42: 0 | L42: 1 | M42: 0 | N42: 0 | O42: 0 | P42: 0 | Q42: 0 | R42: =SUM(D42:Q42) -> 4 | S42: =R42/$R$15 -> 0.001987084
C43: Triciclo | D43: 0 | E43: 0 | F43: 0 | G43: 1 | H43: 0 | I43: 1 | J43: 0 | K43: 0 | L43: 0 | M43: 0 | N43: 0 | O43: 0 | P43: 0 | Q43: 0 | R43: =SUM(D43:Q43) -> 2 | S43: =R43/$R$15 -> 0.00099354198
...

Sheet CONFFLUXO
A1: =Fluxo!A2 -> TOTAL | F1: 2 | G1: {=TRANSPOSE(Dados!2:2)}
F2: 3 | G2: ORIGEM
A3: =Dados!B3 -> OLINDA | B3: =Dados!C3 -> DERBY | F3: 4 | G3: DESTINO | Q3: =HLOOKUP($A$1,Dados!$D$2:$S$14,F1,0) -> 50
A4: =Dados!B4 -> OLINDA | B4: =Dados!C4 -> BOA VIAGEM | F4: 5 | G4: 6 | Q4: =HLOOKUP($A$1,Dados!$D$2:$S$14,F2,0) -> 25
A5: =Dados!B5 -> OLINDA | B5: =Dados!C5 -> BOA VISTA | F5: 6 | G5: 7 | Q5: =HLOOKUP($A$1,Dados!$D$2:$S$14,F3,0) -> 25
A6: =Dados!B6 -> BOA VISTA | B6: =Dados!C6 -> OLINDA | F6: 7 | G6: 8 | Q6: =HLOOKUP($A$1,Dados!$D$2:$S$14,F4,0) -> 26
A7: =Dados!B7 -> BOA VISTA | B7: =Dados!C7 -> DERBY | F7: 8 | G7: 9 | Q7: =HLOOKUP($A$1,Dados!$D$2:$S$14,F5,0) -> 474
A8: =Dados!B8 -> BOA VISTA | B8: =Dados!C8 -> BOA VIAGEM | F8: 9 | G8: 10 | Q8: =HLOOKUP($A$1,Dados!$D$2:$S$14,F6,0) -> 16
A9: =Dados!B9 -> BOA VIAGEM | B9: =Dados!C9 -> BOA VISTA | F9: 10 | G9: 11 | Q9: =HLOOKUP($A$1,Dados!$D$2:$S$14,F7,0) -> 37
A10: =Dados!B10 -> BOA VIAGEM | B10: =Dados!C10 -> OLINDA | F10: 11 | G10: 12 | Q10: =HLOOKUP($A$1,Dados!$D$2:$S$14,F8,0) -> 483
A11: =Dados!B11 -> BOA VIAGEM | B11: =Dados!C11 -> DERBY | F11: 12 | G11: 13 | Q11: =HLOOKUP($A$1,Dados!$D$2:$S$14,F9,0) -> 74
A12: =Dados!B12 -> DERBY | B12: =Dados!C12 -> BOA VIAGEM | F12: 13 | G12: 14 | Q12: =HLOOKUP($A$1,Dados!$D$2:$S$14,F10,0) -> 6
A13: =Dados!B13 -> DERBY | B13: =Dados!C13 -> BOA VISTA | G13: 15 | Q13: =HLOOKUP($A$1,Dados!$D$2:$S$14,F11,0) -> 551
A14: =Dados!B14 -> DERBY | B14: =Dados!C14 -> OLINDA | G14: 16 | Q14: =HLOOKUP($A$1,Dados!$D$2:$S$14,F12,0) -> 246
G15: 17
G16: 18
G17: 19
G18: TOTAL
G19: %

Sheet Gráficos
A1: Ciclistas por hora
A2: Horário início | B2: =Dados!D2 -> 6 | C2: =Dados!E2 -> 7 | D2: =Dados!F2 -> 8 | E2: =Dados!G2 -> 9 | F2: =Dados!H2 -> 10 | G2: =Dados!I2 -> 11 | H2: =Dados!J2 -> 12 | I2: =Dados!K2 -> 13 | ... O2: =Dados!Q2 -> 19
A3: Homens | B3: =Dados!D15-B4-B5 -> 121 | C3: =Dados!E15-C4-C5 -> 162 | D3: =Dados!F15-D4-D5 -> 103 | E3: =Dados!G15-E4-E5 -> 101 | F3: =Dados!H15-F4-F5 -> 77 | G3: =Dados!I15-G4-G5 -> 105 | H3: =Dados!J15-H4-H5 -> 81 | I3: =Dados!K15-I4-I5 -> 100 | ... O3: =Dados!Q15-O4-O5 -> 100
A4: Mulheres | B4: =Dados!D20 -> 5 | C4: =Dados!E20 -> 12 | D4: =Dados!F20 -> 17 | E4: =Dados!G20 -> 3 | F4: =Dados!H20 -> 8 | G4: =Dados!I20 -> 7 | H4: =Dados!J20 -> 12 | I4: =Dados!K20 -> 5 | ... O4: =Dados!Q20 -> 11
A5: Crianças e adolescentes | B5: =Dados!D21 -> 0 | C5: =Dados!E21 -> 0 | D5: =Dados!F21 -> 0 | E5: =Dados!G21 -> 0 | F5: =Dados!H21 -> 0 | G5: =Dados!I21 -> 0 | H5: =Dados!J21 -> 3 | I5: =Dados!K21 -> 2 | ... O5: =Dados!Q21 -> 2
A7: Ciclistas por hora %
A8: Horário | B8: 6 | C8: 7 | D8: 8 | E8: 9 | F8: 10 | G8: 11 | H8: 12 | I8: 13 | J8: 14 | K8: 15 | L8: 16 | M8: 17 | N8: 18 | O8: 19
A9: Mulheres | B9: =B4/Dados!D$15 -> 0.03968254 | C9: =C4/Dados!E$15 -> 0.068965517 | D9: =D4/Dados!F$15 -> 0.14166667 | E9: =E4/Dados!G$15 -> 0.028846154 | F9: =F4/Dados!H$15 -> 0.094117647 | G9: =G4/Dados!I$15 -> 0.0625 | H9: =H4/Dados!J$15 -> 0.125 | I9: =I4/Dados!K$15 -> 0.046728972 | ... O9: =O4/Dados!Q$15 -> 0.097345133
A10: Crianças e adolescentes | B10: =B5/Dados!D$15 -> 0 | C10: =C5/Dados!E$15 -> 0 | D10: =D5/Dados!F$15 -> 0 | E10: =E5/Dados!G$15 -> 0 | F10: =F5/Dados!H$15 -> 0 | G10: =G5/Dados!I$15 -> 0 | H10: =H5/Dados!J$15 -> 0.03125 | I10: =I5/Dados!K$15 -> 0.018691589 | ... O10: =O5/Dados!Q$15 -> 0.017699115
A12: =Dados!C19 -> Característica | B12: =Dados!S19 -> %
A13: =Dados!C20 -> Mulher | B13: =Dados!S20 -> 0.077496274
A14: =Dados!C21 -> Crianças e adolescentes | B14: =Dados!S21 -> 0.0069547938
A15: =Dados!C22 -> Capacete | B15: =Dados!S22 -> 0.094386488
A16: Caronas | B16: =SUM(Dados!S32:S34) -> 0.013412817
A17: =Dados!C35 -> Cargueira tradicional | B17: =Dados!S35 -> 0.060606061
A18: =Dados!C37 -> Serviço | B18: =Dados!S37 -> 0.011425733
A19: =Dados!C39 -> Contramão | B19: =Dados!S39 -> 0.052160954
A20: =Dados!C27 -> Calçada | B20: =Dados!S27 -> 0.084451068

Sheet Fluxo
A1: HORÁRIO | E1: OLINDA
A2: TOTAL | E2: =SUM(E3:G3) -> 100
E3: =CONFFLUXO!Q3 -> 50 | F3: =CONFFLUXO!Q4 -> 25 | G3: =CONFFLUXO!Q5 -> 25
A5: DERBY | B5: =SUM(C5:C7) -> 803 | C5: =CONFFLUXO!Q14 -> 246 | I5: =CONFFLUXO!Q6 -> 26 | J5: =SUM(I5:I7) -> 516 | K5: BOA VISTA
C6: =CONFFLUXO!Q13 -> 551 | F6: =SUM(E3:G3,I5:I7,E9:G9,C5:C7) -> 2013 | I6: =CONFFLUXO!Q7 -> 474
C7: =CONFFLUXO!Q12 -> 6 | I7: =CONFFLUXO!Q8 -> 16
E9: =CONFFLUXO!Q11 -> 74 | F9: =CONFFLUXO!Q10 -> 483 | G9: =CONFFLUXO!Q9 -> 37
E10: =SUM(E9:G9) -> 594
E11: BOA VIAGEM | K11: =MAX(3:3,I:I,9:9,C:C) -> 551

Sheet Coordenadas
A1: Norte
A2: Leste
A3: Sul
A4: Oeste
