Workbook

Sheet Resumo
A1: Cruzamento | B1: Av. Mascarenhas de Moraes x R. Eng. Alves de Souza
A2: Data | B2: 43551
A3: Coordenadas Geográficas | B3: -8.09845, -34.91019
A4: Relatório | B4: https://docs.google.com/document/d/1kVjca7Uq0T7XsLlxHwFs7NEuvXSyxKsg/edit
A5: Total | B5: =Dados!Q15 -> 1403
A6: Máximo em um hora | B6: =MAX(Dados!C15:P15) -> 180
A7: Mulher | B7: =Dados!R20 -> 0.081254455
A8: Crianças e adolescentes | B8: =Dados!R21 -> 0.024946543
A9: Capacete | B9: =Dados!R22 -> 0.047042053
A10: Caronas | B10: =Dados!R23 -> 0.060584462
A11: Cargueiras | B11: =Dados!R24 -> 0.17533856
A12: Serviço | B12: =Dados!R25 -> 0.035637919
A13: Contramão | B13: =Dados!R26 -> 0.14112616
A14: Calçada | B14: =Dados!R27 -> 0.17605132

Sheet Dados
A1: Dados quantitativos e sentido de deslocamento
A2: ORIGEM | B2: DESTINO | C2: 6 | D2: 7 | E2: 8 | F2: 9 | G2: 10 | H2: 11 | I2: 12 | J2: 13 | K2: 14 | L2: 15 | M2: 16 | N2: 17 | O2: 18 | P2: 19 | Q2: TOTAL | R2: %
A3: Lagoa do Araçá | B3: Jaboatão | C3: 9 | D3: 16 | E3: 7 | F3: 9 | G3: 1 | H3: 5 | I3: 11 | J3: 11 | K3: 7 | L3: 7 | M3: 6 | N3: 18 | O3: 8 | P3: 5 | Q3: =SUM(C3:P3) -> 120 | R3: =Q3/$Q$15 -> 0.085531005
A4: Lagoa do Araçá | B4: Boa Viagem | C4: 1 | D4: 15 | E4: 7 | F4: 6 | G4: 11 | H4: 14 | I4: 13 | J4: 18 | K4: 10 | L4: 3 | M4: 13 | N4: 13 | O4: 11 | P4: 11 | Q4: =SUM(C4:P4) -> 146 | R4: =Q4/$Q$15 -> 0.10406272
A5: Lagoa do Araçá | B5: Centro | C5: 2 | D5: 4 | E5: 6 | F5: 2 | G5: 1 | H5: 6 | I5: 8 | J5: 9 | K5: 1 | L5: 1 | M5: 2 | N5: 8 | O5: 1 | P5: 1 | Q5: =SUM(C5:P5) -> 52 | R5: =Q5/$Q$15 -> 0.037063435
A6: Jaboatão | B6: Lagoa do Araçá | C6: 16 | D6: 18 | E6: 9 | F6: 1 | G6: 5 | H6: 7 | I6: 5 | J6: 6 | K6: 4 | L6: 4 | M6: 9 | N6: 11 | O6: 13 | P6: 11 | Q6: =SUM(C6:P6) -> 119 | R6: =Q6/$Q$15 -> 0.084818247
A7: Jaboatão | B7: Centro | C7: 39 | D7: 44 | E7: 28 | F7: 15 | G7: 18 | H7: 22 | I7: 18 | J7: 24 | K7: 24 | L7: 27 | M7: 29 | N7: 63 | O7: 43 | P7: 36 | Q7: =SUM(C7:P7) -> 430 | R7: =Q7/$Q$15 -> 0.3064861
A8: Jaboatão | B8: Boa Viagem | C8: 0 | D8: 1 | E8: 0 | F8: 0 | G8: 1 | H8: 3 | I8: 0 | J8: 1 | K8: 1 | L8: 0 | M8: 4 | N8: 0 | O8: 1 | P8: 0 | Q8: =SUM(C8:P8) -> 12 | R8: =Q8/$Q$15 -> 0.0085531005
A9: Boa Viagem | B9: Jaboatão | C9: 1 | D9: 2 | E9: 0 | F9: 1 | G9: 2 | H9: 3 | I9: 0 | J9: 3 | K9: 4 | L9: 1 | M9: 1 | N9: 1 | O9: 0 | P9: 0 | Q9: =SUM(C9:P9) -> 19 | R9: =Q9/$Q$15 -> 0.013542409
A10: Boa Viagem | B10: Lagoa do Araçá | C10: 6 | D10: 19 | E10: 8 | F10: 5 | G10: 2 | H10: 12 | I10: 8 | J10: 15 | K10: 5 | L10: 5 | M10: 6 | N10: 12 | O10: 10 | P10: 4 | Q10: =SUM(C10:P10) -> 117 | R10: =Q10/$Q$15 -> 0.08339273
A11: Boa Viagem | B11: Centro | C11: 3 | D11: 6 | E11: 3 | F11: 2 | G11: 0 | H11: 3 | I11: 0 | J11: 1 | K11: 6 | L11: 3 | M11: 5 | N11: 0 | O11: 1 | P11: 1 | Q11: =SUM(C11:P11) -> 34 | R11: =Q11/$Q$15 -> 0.024233785
A12: Centro | B12: Lagoa do Araçá | C12: 1 | D12: 1 | E12: 1 | F12: 2 | G12: 1 | H12: 4 | I12: 5 | J12: 1 | K12: 0 | L12: 1 | M12: 5 | N12: 9 | O12: 2 | P12: 1 | Q12: =SUM(C12:P12) -> 34 | R12: =Q12/$Q$15 -> 0.024233785
A13: Centro | B13: Jaboatão | C13: 33 | D13: 52 | E13: 24 | F13: 15 | G13: 14 | H13: 14 | I13: 15 | J13: 10 | K13: 10 | L13: 17 | M13: 26 | N13: 34 | O13: 16 | P13: 11 | Q13: =SUM(C13:P13) -> 291 | R13: =Q13/$Q$15 -> 0.20741269
A14: Centro | B14: Boa Viagem | C14: 4 | D14: 2 | E14: 3 | F14: 6 | G14: 0 | H14: 1 | I14: 1 | J14: 0 | K14: 0 | L14: 1 | M14: 4 | N14: 6 | O14: 0 | P14: 1 | Q14: =SUM(C14:P14) -> 29 | R14: =Q14/$Q$15 -> 0.020669993
B15: TOTAL | C15: =SUM(C$3:C$14) -> 115 | D15: =SUM(D$3:D$14) -> 180 | E15: =SUM(E$3:E$14) -> 96 | F15: =SUM(F$3:F$14) -> 64 | G15: =SUM(G$3:G$14) -> 56 | H15: =SUM(H$3:H$14) -> 94 | I15: =SUM(I$3:I$14) -> 84 | J15: =SUM(J$3:J$14) -> 99 | ... Q15: =SUM(Q$3:Q$14) -> 1403
B16: Percentual | C16: =C15/$Q$15 -> 0.081967213 | D16: =D15/$Q$15 -> 0.12829651 | E16: =E15/$Q$15 -> 0.068424804 | F16: =F15/$Q$15 -> 0.045616536 | G16: =G15/$Q$15 -> 0.039914469 | H16: =H15/$Q$15 -> 0.066999287 | I16: =I15/$Q$15 -> 0.059871703 | J16: =J15/$Q$15 -> 0.070563079 | ... P16: =P15/$Q$15 -> 0.058446187 | Q16: =SUM(C16:P16) -> 1
A18: Dados qualitativos padrões
B19: Característica | C19: 6 | D19: 7 | E19: 8 | F19: 9 | G19: 10 | H19: 11 | I19: 12 | J19: 13 | K19: 14 | L19: 15 | M19: 16 | N19: 17 | O19: 18 | P19: 19 | Q19: TOTAL | R19: %
B20: Mulher | C20: 4 | D20: 19 | E20: 5 | F20: 4 | G20: 6 | H20: 8 | I20: 8 | J20: 17 | K20: 9 | L20: 4 | M20: 11 | N20: 14 | O20: 3 | P20: 2 | Q20: =SUM(C20:P20) -> 114 | R20: =Q20/$Q$15 -> 0.081254455
B21: Crianças e adolescentes | C21: 0 | D21: 6 | E21: 0 | F21: 0 | G21: 3 | H21: 5 | I21: 4 | J21: 2 | K21: 4 | L21: 2 | M21: 6 | N21: 1 | O21: 1 | P21: 1 | Q21: =SUM(C21:P21) -> 35 | R21: =Q21/$Q$15 -> 0.024946543
B22: Capacete | C22: 9 | D22: 15 | E22: 4 | F22: 2 | G22: 1 | H22: 0 | I22: 5 | J22: 1 | K22: 8 | L22: 5 | M22: 1 | N22: 5 | O22: 9 | P22: 1 | Q22: =SUM(C22:P22) -> 66 | R22: =Q22/$Q$15 -> 0.047042053
B23: Caronas | C23: =SUM(C31:C33) -> 4 | D23: =SUM(D31:D33) -> 15 | E23: =SUM(E31:E33) -> 1 | F23: =SUM(F31:F33) -> 2 | G23: =SUM(G31:G33) -> 3 | H23: =SUM(H31:H33) -> 7 | I23: =SUM(I31:I33) -> 6 | J23: =SUM(J31:J33) -> 11 | ... P23: =SUM(P31:P33) -> 4 | Q23: =SUM(C23:P23) -> 85 | R23: =Q23/$Q$15 -> 0.060584462
B24: Cargueiras | C24: =SUM(C34:C35) -> 19 | D24: =SUM(D34:D35) -> 30 | E24: =SUM(E34:E35) -> 16 | F24: =SUM(F34:F35) -> 18 | G24: =SUM(G34:G35) -> 11 | H24: =SUM(H34:H35) -> 11 | I24: =SUM(I34:I35) -> 15 | J24: =SUM(J34:J35) -> 17 | ... P24: =SUM(P34:P35) -> 8 | Q24: =SUM(C24:P24) -> 246 | R24: =Q24/$Q$15 -> 0.17533856
B25: Serviço | C25: =SUM(C36:C37) -> 0 | D25: =SUM(D36:D37) -> 7 | E25: =SUM(E36:E37) -> 3 | F25: =SUM(F36:F37) -> 11 | G25: =SUM(G36:G37) -> 5 | H25: =SUM(H36:H37) -> 3 | I25: =SUM(I36:I37) -> 6 | J25: =SUM(J36:J37) -> 3 | ... P25: =SUM(P36:P37) -> 1 | Q25: =SUM(C25:P25) -> 50 | R25: =Q25/$Q$15 -> 0.035637919
B26: Contramão | C26: =SUM(C38:C39) -> 26 | D26: =SUM(D38:D39) -> 27 | E26: =SUM(E38:E39) -> 11 | F26: =SUM(F38:F39) -> 6 | G26: =SUM(G38:G39) -> 9 | H26: =SUM(H38:H39) -> 16 | I26: =SUM(I38:I39) -> 15 | J26: =SUM(J38:J39) -> 6 | ... P26: =SUM(P38:P39) -> 8 | Q26: =SUM(C26:P26) -> 198 | R26: =Q26/$Q$15 -> 0.14112616
B27: Calçada | C27: 15 | D27: 30 | E27: 16 | F27: 11 | G27: 11 | H27: 15 | I27: 15 | J27: 22 | K27: 9 | L27: 15 | M27: 31 | N27: 25 | O27: 22 | P27: 10 | Q27: =SUM(C27:P27) -> 247 | R27: =Q27/$Q$15 -> 0.17605132
A29: Dados qualitativos das observações
B30: Característica | C30: 6 | D30: 7 | E30: 8 | F30: 9 | G30: 10 | H30: 11 | I30: 12 | J30: 13 | K30: 14 | L30: 15 | M30: 16 | N30: 17 | O30: 18 | P30: 19 | Q30: TOTAL | R30: %
B31: Carona criança | C31: 2 | D31: 13 | E31: 0 | F31: 1 | G31: 1 | H31: 5 | I31: 6 | J31: 8 | K31: 2 | L31: 5 | M31: 6 | N31: 6 | O31: 0 | P31: 2 | Q31: =SUM(C31:P31) -> 57 | R31: =Q31/$Q$15 -> 0.040627227
B32: Carona mulher | C32: 2 | D32: 2 | E32: 1 | F32: 1 | G32: 1 | H32: 2 | I32: 0 | J32: 3 | K32: 1 | L32: 0 | M32: 2 | N32: 1 | O32: 5 | P32: 1 | Q32: =SUM(C32:P32) -> 22 | R32: =Q32/$Q$15 -> 0.015680684
B33: Carona homem | C33: 0 | D33: 0 | E33: 0 | F33: 0 | G33: 1 | H33: 0 | I33: 0 | J33: 0 | K33: 0 | L33: 0 | M33: 0 | N33: 1 | O33: 3 | P33: 1 | Q33: =SUM(C33:P33) -> 6 | R33: =Q33/$Q$15 -> 0.0042765502
B34: Cargueira | C34: 7 | D34: 19 | E34: 10 | F34: 10 | G34: 10 | H34: 9 | I34: 15 | J34: 14 | K34: 11 | L34: 13 | M34: 16 | N34: 15 | O34: 7 | P34: 5 | Q34: =SUM(C34:P34) -> 161 | R34: =Q34/$Q$15 -> 0.1147541
B35: Adaptada a carga | C35: 12 | D35: 11 | E35: 6 | F35: 8 | G35: 1 | H35: 2 | I35: 0 | J35: 3 | K35: 7 | L35: 5 | M35: 15 | N35: 10 | O35: 2 | P35: 3
B36: Serviço | C36: 0 | D36: 7 | E36: 3 | F36: 11 | G36: 5 | H36: 3 | I36: 6 | J36: 2 | K36: 4 | L36: 2 | M36: 0 | N36: 2 | O36: 1 | Q36: =SUM(C36:P36) -> 46 | R36: =Q36/$Q$15 -> 0.032786885
B37: Serviço App | C37: 0 | D37: 0 | E37: 0 | F37: 0 | J37: 1 | K37: 0 | L37: 0 | M37: 0 | N37: 1 | O37: 1 | P37: 1
B38: Contramao | C38: 23 | D38: 27 | E38: 11 | F38: 6 | G38: 9 | H38: 16 | I38: 15 | J38: 5 | K38: 4 | L38: 11 | M38: 22 | N38: 22 | O38: 14 | P38: 5 | Q38: =SUM(C38:P38) -> 190 | R38: =Q38/$Q$15 -> 0.13542409
B39: Contramão para conversão | C39: 3 | E39: 0 | F39: 0 | G39: 0 | H39: 0 | I39: 0 | J39: 1 | K39: 0 | L39: 0 | M39: 1 | N39: 0 | O39: 0 | P39: 3 | Q39: =SUM(C39:P39) -> 8 | R39: =Q39/$Q$15 -> 0.005702067
B40: Bike PE | D40: 1 | Q40: =SUM(C40:P40) -> 1 | R40: =Q40/$Q$15 -> 0.00071275837
B41: Triciclo e carroça | Q41: =SUM(C41:P41) -> 0 | R41: =Q41/$Q$15 -> 0
B42: Motorizada ou elétrica | K42: 1 | L42: 1 | Q42: =SUM(C42:P42) -> 2 | R42: =Q42/$Q$15 -> 0.0014255167
...

Sheet CONFFLUXO
A1: =Fluxo!A2 -> TOTAL | F1: 2 | G1: {=TRANSPOSE(Dados!2:2)} -> ORIGEM
F2: 3 | G2: DESTINO
A3: =Dados!A3 -> Lagoa do Araçá | B3: =Dados!B3 -> Jaboatão | F3: 4 | G3: 6 | Q3: =HLOOKUP($A$1,Dados!$C$2:$R$14,F1,0) -> 120
A4: =Dados!A4 -> Lagoa do Araçá | B4: =Dados!B4 -> Boa Viagem | F4: 5 | G4: 7 | Q4: =HLOOKUP($A$1,Dados!$C$2:$R$14,F2,0) -> 146
A5: =Dados!A5 -> Lagoa do Araçá | B5: =Dados!B5 -> Centro | F5: 6 | G5: 8 | Q5: =HLOOKUP($A$1,Dados!$C$2:$R$14,F3,0) -> 52
A6: =Dados!A6 -> Jaboatão | B6: =Dados!B6 -> Lagoa do Araçá | F6: 7 | G6: 9 | Q6: =HLOOKUP($A$1,Dados!$C$2:$R$14,F4,0) -> 119
A7: =Dados!A7 -> Jaboatão | B7: =Dados!B7 -> Centro | F7: 8 | G7: 10 | Q7: =HLOOKUP($A$1,Dados!$C$2:$R$14,F5,0) -> 430
A8: =Dados!A8 -> Jaboatão | B8: =Dados!B8 -> Boa Viagem | F8: 9 | G8: 11 | Q8: =HLOOKUP($A$1,Dados!$C$2:$R$14,F6,0) -> 12
A9: =Dados!A9 -> Boa Viagem | B9: =Dados!B9 -> Jaboatão | F9: 10 | G9: 12 | Q9: =HLOOKUP($A$1,Dados!$C$2:$R$14,F7,0) -> 19
A10: =Dados!A10 -> Boa Viagem | B10: =Dados!B10 -> Lagoa do Araçá | F10: 11 | G10: 13 | Q10: =HLOOKUP($A$1,Dados!$C$2:$R$14,F8,0) -> 117
A11: =Dados!A11 -> Boa Viagem | B11: =Dados!B11 -> Centro | F11: 12 | G11: 14 | Q11: =HLOOKUP($A$1,Dados!$C$2:$R$14,F9,0) -> 34
A12: =Dados!A12 -> Centro | B12: =Dados!B12 -> Lagoa do Araçá | F12: 13 | G12: 15 | Q12: =HLOOKUP($A$1,Dados!$C$2:$R$14,F10,0) -> 34
A13: =Dados!A13 -> Centro | B13: =Dados!B13 -> Jaboatão | G13: 16 | Q13: =HLOOKUP($A$1,Dados!$C$2:$R$14,F11,0) -> 291
A14: =Dados!A14 -> Centro | B14: =Dados!B14 -> Boa Viagem | G14: 17 | Q14: =HLOOKUP($A$1,Dados!$C$2:$R$14,F12,0) -> 29
G15: 18
G16: 19
G17: TOTAL
G18: %

Sheet Gráficos
A1: Ciclistas por hora
A2: Horário início | B2: =Dados!C2 -> 6 | C2: =Dados!D2 -> 7 | D2: =Dados!E2 -> 8 | E2: =Dados!F2 -> 9 | F2: =Dados!G2 -> 10 | G2: =Dados!H2 -> 11 | H2: =Dados!I2 -> 12 | I2: =Dados!J2 -> 13 | ... O2: =Dados!P2 -> 19
A3: Homens | B3: =Dados!C15-B4-B5 -> 111 | C3: =Dados!D15-C4-C5 -> 155 | D3: =Dados!E15-D4-D5 -> 91 | E3: =Dados!F15-E4-E5 -> 60 | F3: =Dados!G15-F4-F5 -> 47 | G3: =Dados!H15-G4-G5 -> 81 | H3: =Dados!I15-H4-H5 -> 72 | I3: =Dados!J15-I4-I5 -> 80 | ... O3: =Dados!P15-O4-O5 -> 79
A4: Mulheres | B4: =Dados!C20 -> 4 | C4: =Dados!D20 -> 19 | D4: =Dados!E20 -> 5 | E4: =Dados!F20 -> 4 | F4: =Dados!G20 -> 6 | G4: =Dados!H20 -> 8 | H4: =Dados!I20 -> 8 | I4: =Dados!J20 -> 17 | ... O4: =Dados!P20 -> 2
A5: Crianças e adolescentes | B5: =Dados!C21 -> 0 | C5: =Dados!D21 -> 6 | D5: =Dados!E21 -> 0 | E5: =Dados!F21 -> 0 | F5: =Dados!G21 -> 3 | G5: =Dados!H21 -> 5 | H5: =Dados!I21 -> 4 | I5: =Dados!J21 -> 2 | ... O5: =Dados!P21 -> 1
A7: Ciclistas por hora %
A8: Horário | B8: 6 | C8: 7 | D8: 8 | E8: 9 | F8: 10 | G8: 11 | H8: 12 | I8: 13 | J8: 14 | K8: 15 | L8: 16 | M8: 17 | N8: 18 | O8: 19
A9: Mulheres | B9: =B4/Dados!C$15 -> 0.034782609 | C9: =C4/Dados!D$15 -> 0.10555556 | D9: =D4/Dados!E$15 -> 0.052083333 | E9: =E4/Dados!F$15 -> 0.0625 | F9: =F4/Dados!G$15 -> 0.10714286 | G9: =G4/Dados!H$15 -> 0.085106383 | H9: =H4/Dados!I$15 -> 0.095238095 | I9: =I4/Dados!J$15 -> 0.17171717 | ... O9: =O4/Dados!P$15 -> 0.024390244
A10: Crianças e adolescentes | B10: =B5/Dados!C$15 -> 0 | C10: =C5/Dados!D$15 -> 0.033333333 | D10: =D5/Dados!E$15 -> 0 | E10: =E5/Dados!F$15 -> 0 | F10: =F5/Dados!G$15 -> 0.053571429 | G10: =G5/Dados!H$15 -> 0.053191489 | H10: =H5/Dados!I$15 -> 0.047619048 | I10: =I5/Dados!J$15 -> 0.02020202 | ... O10: =O5/Dados!P$15 -> 0.012195122
A12: =Dados!B19 -> Característica | B12: =Dados!R19 -> %
A13: =Dados!B20 -> Mulher | B13: =Dados!R20 -> 0.081254455
A14: =Dados!B21 -> Crianças e adolescentes | B14: =Dados!R21 -> 0.024946543
A15: =Dados!B22 -> Capacete | B15: =Dados!R22 -> 0.047042053
A16: Caronas | B16: =SUM(Dados!R31:R33) -> 0.060584462
A17: =Dados!B34 -> Cargueira | B17: =Dados!R34 -> 0.1147541
A18: =Dados!B36 -> Serviço | B18: =Dados!R36 -> 0.032786885
A19: =Dados!B38 -> Contramao | B19: =Dados!R38 -> 0.13542409
A20: =Dados!B27 -> Calçada | B20: =Dados!R27 -> 0.17605132

Sheet Fluxo
A1: HORÁRIO | E1: =UPPER(CONFFLUXO!A3) -> LAGOA DO ARAÇÁ
A2: TOTAL | E2: =SUM(E3:G3) -> 318
E3: =CONFFLUXO!Q3 -> 120 | F3: =CONFFLUXO!Q4 -> 146 | G3: =CONFFLUXO!Q5 -> 52
A5: =UPPER(CONFFLUXO!A12) -> CENTRO | B5: =SUM(C5:C7) -> 354 | C5: =CONFFLUXO!Q14 -> 29 | I5: =CONFFLUXO!Q6 -> 119 | J5: =SUM(I5:I7) -> 561 | K5: =UPPER(CONFFLUXO!A6) -> JABOATÃO
C6: =CONFFLUXO!Q13 -> 291 | F6: =SUM(E3:G3,I5:I7,E9:G9,C5:C7) -> 1403 | I6: =CONFFLUXO!Q7 -> 430
C7: =CONFFLUXO!Q12 -> 34 | I7: =CONFFLUXO!Q8 -> 12
E9: =CONFFLUXO!Q11 -> 34 | F9: =CONFFLUXO!Q10 -> 117 | G9: =CONFFLUXO!Q9 -> 19
E10: =SUM(E9:G9) -> 170
E11: =UPPER(CONFFLUXO!A9) -> BOA VIAGEM | K11: =MAX(3:3,I:I,9:9,C:C) -> 430
