Workbook

Sheet Resumo
A1: Cruzamento | B1: Av. Rui Barbosa x Av. Dr. Malaquias
A2: Data | B2: 46092
A3: Coordenadas Geográficas | B3: -8.03989, -34.90401
A4: Relatório | B4: "link"
A5: Total | B5: =Dados!Q15 -> 853
A6: Máximo em um hora | B6: =MAX(Dados!C15:P15) -> 123
A7: Mulher | B7: =Dados!R20 -> 0.087924971
A8: Crianças e adolescentes | B8: =Dados!R21 -> 0.045720985
A9: Capacete | B9: =Dados!R22 -> 0.13130129
A10: Caronas | B10: =Dados!R51 -> 0.015240328
A11: Cargueiras | B11: =Dados!R52 -> 0.031652989
A12: Serviço | B12: =Dados!R53 -> 0.052754982
A13: Contramão | B13: =Dados!R54 -> 0.083235639
A14: Calçada | B14: =Dados!R32 -> 0.2919109

Sheet Dados
A1: Dados quantitativos e sentido de deslocamento
A2: ORIGEM | B2: DESTINO | C2: 6 | D2: 7 | E2: 8 | F2: 9 | G2: 10 | H2: 11 | I2: 12 | J2: 13 | K2: 14 | L2: 15 | M2: 16 | N2: 17 | O2: 18 | P2: 19 | Q2: TOTAL | R2: %
A3: Rosarinho | B3: Jaqueira | C3: =ROUND(IF(ISBLANK(Original!C3),'Base projeção'!C3*'Base projeção'!$A$16,Original!C3),0) -> 1 | D3: =ROUND(IF(ISBLANK(Original!D3),'Base projeção'!D3*'Base projeção'!$A$16,Original!D3),0) -> 1 | E3: =ROUND(IF(ISBLANK(Original!E3),'Base projeção'!E3*'Base projeção'!$A$16,Original!E3),0) -> 1 | F3: =ROUND(IF(ISBLANK(Original!F3),'Base projeção'!F3*'Base projeção'!$A$16,Original!F3),0) -> 4 | G3: =ROUND(IF(ISBLANK(Original!G3),'Base projeção'!G3*'Base projeção'!$A$16,Original!G3),0) -> 5 | H3: =ROUND(IF(ISBLANK(Original!H3),'Base projeção'!H3*'Base projeção'!$A$16,Original!H3),0) -> 0 | I3: =ROUND(IF(ISBLANK(Original!I3),'Base projeção'!I3*'Base projeção'!$A$16,Original!I3),0) -> 2 | J3: =ROUND(IF(ISBLANK(Original!J3),'Base projeção'!J3*'Base projeção'!$A$16,Original!J3),0) -> 1 | ... P3: =ROUND(IF(ISBLANK(Original!P3),'Base projeção'!P3*'Base projeção'!$A$16,Original!P3),0) -> 3 | Q3: =SUM(C3:P3) -> 30 | R3: =Q3/$Q$15 -> 0.035169988
A4: Rosarinho | B4: Torre | Q4: =SUM(C4:P4) -> 0 | R4: =Q4/$Q$15 -> 0
A5: Rosarinho | B5: Graças | C5: =ROUND(IF(ISBLANK(Original!C5),'Base projeção'!C5*'Base projeção'!$A$16,Original!C5),0) -> 8 | D5: =ROUND(IF(ISBLANK(Original!D5),'Base projeção'!D5*'Base projeção'!$A$16,Original!D5),0) -> 14 | E5: =ROUND(IF(ISBLANK(Original!E5),'Base projeção'!E5*'Base projeção'!$A$16,Original!E5),0) -> 11 | F5: =ROUND(IF(ISBLANK(Original!F5),'Base projeção'!F5*'Base projeção'!$A$16,Original!F5),0) -> 7 | G5: =ROUND(IF(ISBLANK(Original!G5),'Base projeção'!G5*'Base projeção'!$A$16,Original!G5),0) -> 11 | H5: =ROUND(IF(ISBLANK(Original!H5),'Base projeção'!H5*'Base projeção'!$A$16,Original!H5),0) -> 2 | I5: =ROUND(IF(ISBLANK(Original!I5),'Base projeção'!I5*'Base projeção'!$A$16,Original!I5),0) -> 11 | J5: =ROUND(IF(ISBLANK(Original!J5),'Base projeção'!J5*'Base projeção'!$A$16,Original!J5),0) -> 1 | ... P5: =ROUND(IF(ISBLANK(Original!P5),'Base projeção'!P5*'Base projeção'!$A$16,Original!P5),0) -> 5 | Q5: =SUM(C5:P5) -> 124 | R5: =Q5/$Q$15 -> 0.14536928
A6: Graças | B6: Rosarinho | C6: =ROUND(IF(ISBLANK(Original!C6),'Base projeção'!C6*'Base projeção'!$A$16,Original!C6),0) -> 1 | D6: =ROUND(IF(ISBLANK(Original!D6),'Base projeção'!D6*'Base projeção'!$A$16,Original!D6),0) -> 3 | E6: =ROUND(IF(ISBLANK(Original!E6),'Base projeção'!E6*'Base projeção'!$A$16,Original!E6),0) -> 4 | F6: =ROUND(IF(ISBLANK(Original!F6),'Base projeção'!F6*'Base projeção'!$A$16,Original!F6),0) -> 1 | G6: =ROUND(IF(ISBLANK(Original!G6),'Base projeção'!G6*'Base projeção'!$A$16,Original!G6),0) -> 0 | H6: =ROUND(IF(ISBLANK(Original!H6),'Base projeção'!H6*'Base projeção'!$A$16,Original!H6),0) -> 3 | I6: =ROUND(IF(ISBLANK(Original!I6),'Base projeção'!I6*'Base projeção'!$A$16,Original!I6),0) -> 3 | J6: =ROUND(IF(ISBLANK(Original!J6),'Base projeção'!J6*'Base projeção'!$A$16,Original!J6),0) -> 2 | ... P6: =ROUND(IF(ISBLANK(Original!P6),'Base projeção'!P6*'Base projeção'!$A$16,Original!P6),0) -> 2 | Q6: =SUM(C6:P6) -> 38 | R6: =Q6/$Q$15 -> 0.044548652
A7: Graças | B7: Jaqueira | C7: =ROUND(IF(ISBLANK(Original!C7),'Base projeção'!C7*'Base projeção'!$A$16,Original!C7),0) -> 10 | D7: =ROUND(IF(ISBLANK(Original!D7),'Base projeção'!D7*'Base projeção'!$A$16,Original!D7),0) -> 7 | E7: =ROUND(IF(ISBLANK(Original!E7),'Base projeção'!E7*'Base projeção'!$A$16,Original!E7),0) -> 6 | F7: =ROUND(IF(ISBLANK(Original!F7),'Base projeção'!F7*'Base projeção'!$A$16,Original!F7),0) -> 9 | G7: =ROUND(IF(ISBLANK(Original!G7),'Base projeção'!G7*'Base projeção'!$A$16,Original!G7),0) -> 5 | H7: =ROUND(IF(ISBLANK(Original!H7),'Base projeção'!H7*'Base projeção'!$A$16,Original!H7),0) -> 4 | I7: =ROUND(IF(ISBLANK(Original!I7),'Base projeção'!I7*'Base projeção'!$A$16,Original!I7),0) -> 12 | J7: =ROUND(IF(ISBLANK(Original!J7),'Base projeção'!J7*'Base projeção'!$A$16,Original!J7),0) -> 3 | ... P7: =ROUND(IF(ISBLANK(Original!P7),'Base projeção'!P7*'Base projeção'!$A$16,Original!P7),0) -> 19 | Q7: =SUM(C7:P7) -> 162 | R7: =Q7/$Q$15 -> 0.18991794
A8: Graças | B8: Torre | Q8: =SUM(C8:P8) -> 0 | R8: =Q8/$Q$15 -> 0
A9: Torre | B9: Graças | Q9: =SUM(C9:P9) -> 0 | R9: =Q9/$Q$15 -> 0
A10: Torre | B10: Rosarinho | Q10: =SUM(C10:P10) -> 0 | R10: =Q10/$Q$15 -> 0
A11: Torre | B11: Jaqueira | Q11: =SUM(C11:P11) -> 0 | R11: =Q11/$Q$15 -> 0
A12: Jaqueira | B12: Torre | Q12: =SUM(C12:P12) -> 0 | R12: =Q12/$Q$15 -> 0
A13: Jaqueira | B13: Graças | C13: =ROUND(IF(ISBLANK(Original!C13),'Base projeção'!C13*'Base projeção'!$A$16,Original!C13),0) -> 73 | D13: =ROUND(IF(ISBLANK(Original!D13),'Base projeção'!D13*'Base projeção'!$A$16,Original!D13),0) -> 70 | E13: =ROUND(IF(ISBLANK(Original!E13),'Base projeção'!E13*'Base projeção'!$A$16,Original!E13),0) -> 43 | F13: =ROUND(IF(ISBLANK(Original!F13),'Base projeção'!F13*'Base projeção'!$A$16,Original!F13),0) -> 20 | G13: =ROUND(IF(ISBLANK(Original!G13),'Base projeção'!G13*'Base projeção'!$A$16,Original!G13),0) -> 14 | H13: =ROUND(IF(ISBLANK(Original!H13),'Base projeção'!H13*'Base projeção'!$A$16,Original!H13),0) -> 26 | I13: =ROUND(IF(ISBLANK(Original!I13),'Base projeção'!I13*'Base projeção'!$A$16,Original!I13),0) -> 24 | J13: =ROUND(IF(ISBLANK(Original!J13),'Base projeção'!J13*'Base projeção'!$A$16,Original!J13),0) -> 19 | ... P13: =ROUND(IF(ISBLANK(Original!P13),'Base projeção'!P13*'Base projeção'!$A$16,Original!P13),0) -> 27 | Q13: =SUM(C13:P13) -> 454 | R13: =Q13/$Q$15 -> 0.53223916
A14: Jaqueira | B14: Rosarinho | C14: =ROUND(IF(ISBLANK(Original!C14),'Base projeção'!C14*'Base projeção'!$A$16,Original!C14),0) -> 3 | D14: =ROUND(IF(ISBLANK(Original!D14),'Base projeção'!D14*'Base projeção'!$A$16,Original!D14),0) -> 5 | E14: =ROUND(IF(ISBLANK(Original!E14),'Base projeção'!E14*'Base projeção'!$A$16,Original!E14),0) -> 4 | F14: =ROUND(IF(ISBLANK(Original!F14),'Base projeção'!F14*'Base projeção'!$A$16,Original!F14),0) -> 2 | G14: =ROUND(IF(ISBLANK(Original!G14),'Base projeção'!G14*'Base projeção'!$A$16,Original!G14),0) -> 1 | H14: =ROUND(IF(ISBLANK(Original!H14),'Base projeção'!H14*'Base projeção'!$A$16,Original!H14),0) -> 4 | I14: =ROUND(IF(ISBLANK(Original!I14),'Base projeção'!I14*'Base projeção'!$A$16,Original!I14),0) -> 3 | J14: =ROUND(IF(ISBLANK(Original!J14),'Base projeção'!J14*'Base projeção'!$A$16,Original!J14),0) -> 4 | ... P14: =ROUND(IF(ISBLANK(Original!P14),'Base projeção'!P14*'Base projeção'!$A$16,Original!P14),0) -> 3 | Q14: =SUM(C14:P14) -> 45 | R14: =Q14/$Q$15 -> 0.052754982
B15: TOTAL | C15: =SUM(C3:C14) -> 96 | D15: =SUM(D3:D14) -> 100 | E15: =SUM(E3:E14) -> 69 | F15: =SUM(F3:F14) -> 43 | G15: =SUM(G3:G14) -> 36 | H15: =SUM(H3:H14) -> 39 | I15: =SUM(I3:I14) -> 55 | J15: =SUM(J3:J14) -> 30 | ... P15: =SUM(P3:P14) -> 59 | Q15: =SUM(Q$3:Q$14) -> 853
B16: Percentual | C16: =C15/$Q$15 -> 0.11254396 | D16: =D15/$Q$15 -> 0.11723329 | E16: =E15/$Q$15 -> 0.080890973 | F16: =F15/$Q$15 -> 0.050410317 | G16: =G15/$Q$15 -> 0.042203986 | H16: =H15/$Q$15 -> 0.045720985 | I16: =I15/$Q$15 -> 0.064478312 | J16: =J15/$Q$15 -> 0.035169988 | ... P16: =P15/$Q$15 -> 0.069167644 | Q16: =SUM(C16:P16) -> 1
B18: Dados qualitativos padrões
B19: Característica | C19: 6 | D19: 7 | E19: 8 | F19: 9 | G19: 10 | H19: 11 | I19: 12 | J19: 13 | K19: 14 | L19: 15 | M19: 16 | N19: 17 | O19: 18 | P19: 19 | Q19: TOTAL | R19: %
B20: Mulher | C20: =ROUND(IF(ISBLANK(Original!C20),'Base projeção'!C20*'Base projeção'!$A$16,Original!C20),0) -> 5 | D20: =ROUND(IF(ISBLANK(Original!D20),'Base projeção'!D20*'Base projeção'!$A$16,Original!D20),0) -> 12 | E20: =ROUND(IF(ISBLANK(Original!E20),'Base projeção'!E20*'Base projeção'!$A$16,Original!E20),0) -> 8 | F20: =ROUND(IF(ISBLANK(Original!F20),'Base projeção'!F20*'Base projeção'!$A$16,Original!F20),0) -> 8 | G20: =ROUND(IF(ISBLANK(Original!G20),'Base projeção'!G20*'Base projeção'!$A$16,Original!G20),0) -> 1 | H20: =ROUND(IF(ISBLANK(Original!H20),'Base projeção'!H20*'Base projeção'!$A$16,Original!H20),0) -> 4 | I20: =ROUND(IF(ISBLANK(Original!I20),'Base projeção'!I20*'Base projeção'!$A$16,Original!I20),0) -> 1 | J20: =ROUND(IF(ISBLANK(Original!J20),'Base projeção'!J20*'Base projeção'!$A$16,Original!J20),0) -> 5 | ... P20: =ROUND(IF(ISBLANK(Original!P20),'Base projeção'!P20*'Base projeção'!$A$16,Original!P20),0) -> 5 | Q20: =SUM(C20:P20) -> 75 | R20: =Q20/$Q$15 -> 0.087924971
B21: Crianças e adolescentes | C21: =ROUND(IF(ISBLANK(Original!C21),'Base projeção'!C21*'Base projeção'!$A$16,Original!C21),0) -> 5 | D21: =ROUND(IF(ISBLANK(Original!D21),'Base projeção'!D21*'Base projeção'!$A$16,Original!D21),0) -> 0 | E21: =ROUND(IF(ISBLANK(Original!E21),'Base projeção'!E21*'Base projeção'!$A$16,Original!E21),0) -> 0 | F21: =ROUND(IF(ISBLANK(Original!F21),'Base projeção'!F21*'Base projeção'!$A$16,Original!F21),0) -> 0 | G21: =ROUND(IF(ISBLANK(Original!G21),'Base projeção'!G21*'Base projeção'!$A$16,Original!G21),0) -> 0 | H21: =ROUND(IF(ISBLANK(Original!H21),'Base projeção'!H21*'Base projeção'!$A$16,Original!H21),0) -> 0 | I21: =ROUND(IF(ISBLANK(Original!I21),'Base projeção'!I21*'Base projeção'!$A$16,Original!I21),0) -> 11 | J21: =ROUND(IF(ISBLANK(Original!J21),'Base projeção'!J21*'Base projeção'!$A$16,Original!J21),0) -> 8 | ... P21: =ROUND(IF(ISBLANK(Original!P21),'Base projeção'!P21*'Base projeção'!$A$16,Original!P21),0) -> 4 | Q21: =SUM(C21:P21) -> 39 | R21: =Q21/$Q$15 -> 0.045720985
B22: Capacete | C22: =ROUND(IF(ISBLANK(Original!C22),'Base projeção'!C22*'Base projeção'!$A$16,Original!C22),0) -> 11 | D22: =ROUND(IF(ISBLANK(Original!D22),'Base projeção'!D22*'Base projeção'!$A$16,Original!D22),0) -> 15 | E22: =ROUND(IF(ISBLANK(Original!E22),'Base projeção'!E22*'Base projeção'!$A$16,Original!E22),0) -> 13 | F22: =ROUND(IF(ISBLANK(Original!F22),'Base projeção'!F22*'Base projeção'!$A$16,Original!F22),0) -> 9 | G22: =ROUND(IF(ISBLANK(Original!G22),'Base projeção'!G22*'Base projeção'!$A$16,Original!G22),0) -> 5 | H22: =ROUND(IF(ISBLANK(Original!H22),'Base projeção'!H22*'Base projeção'!$A$16,Original!H22),0) -> 8 | I22: =ROUND(IF(ISBLANK(Original!I22),'Base projeção'!I22*'Base projeção'!$A$16,Original!I22),0) -> 8 | J22: =ROUND(IF(ISBLANK(Original!J22),'Base projeção'!J22*'Base projeção'!$A$16,Original!J22),0) -> 3 | ... P22: =ROUND(IF(ISBLANK(Original!P22),'Base projeção'!P22*'Base projeção'!$A$16,Original!P22),0) -> 19 | Q22: =SUM(C22:P22) -> 112 | R22: =Q22/$Q$15 -> 0.13130129
B23: Carona criança | C23: =ROUND(IF(ISBLANK(Original!C23),'Base projeção'!C23*'Base projeção'!$A$16,Original!C23),0) -> 1 | D23: =ROUND(IF(ISBLANK(Original!D23),'Base projeção'!D23*'Base projeção'!$A$16,Original!D23),0) -> 2 | E23: =ROUND(IF(ISBLANK(Original!E23),'Base projeção'!E23*'Base projeção'!$A$16,Original!E23),0) -> 2 | F23: =ROUND(IF(ISBLANK(Original!F23),'Base projeção'!F23*'Base projeção'!$A$16,Original!F23),0) -> 0 | G23: =ROUND(IF(ISBLANK(Original!G23),'Base projeção'!G23*'Base projeção'!$A$16,Original!G23),0) -> 0 | H23: =ROUND(IF(ISBLANK(Original!H23),'Base projeção'!H23*'Base projeção'!$A$16,Original!H23),0) -> 0 | I23: =ROUND(IF(ISBLANK(Original!I23),'Base projeção'!I23*'Base projeção'!$A$16,Original!I23),0) -> 0 | J23: =ROUND(IF(ISBLANK(Original!J23),'Base projeção'!J23*'Base projeção'!$A$16,Original!J23),0) -> 0 | ... P23: =ROUND(IF(ISBLANK(Original!P23),'Base projeção'!P23*'Base projeção'!$A$16,Original!P23),0) -> 0 | Q23: =SUM(C23:P23) -> 9 | R23: =Q23/$Q$15 -> 0.010550996
B24: Carona mulher | C24: =ROUND(IF(ISBLANK(Original!C24),'Base projeção'!C24*'Base projeção'!$A$16,Original!C24),0) -> 1 | D24: =ROUND(IF(ISBLANK(Original!D24),'Base projeção'!D24*'Base projeção'!$A$16,Original!D24),0) -> 1 | E24: =ROUND(IF(ISBLANK(Original!E24),'Base projeção'!E24*'Base projeção'!$A$16,Original!E24),0) -> 1 | F24: =ROUND(IF(ISBLANK(Original!F24),'Base projeção'!F24*'Base projeção'!$A$16,Original!F24),0) -> 0 | G24: =ROUND(IF(ISBLANK(Original!G24),'Base projeção'!G24*'Base projeção'!$A$16,Original!G24),0) -> 0 | H24: =ROUND(IF(ISBLANK(Original!H24),'Base projeção'!H24*'Base projeção'!$A$16,Original!H24),0) -> 0 | I24: =ROUND(IF(ISBLANK(Original!I24),'Base projeção'!I24*'Base projeção'!$A$16,Original!I24),0) -> 0 | J24: =ROUND(IF(ISBLANK(Original!J24),'Base projeção'!J24*'Base projeção'!$A$16,Original!J24),0) -> 0 | ... P24: =ROUND(IF(ISBLANK(Original!P24),'Base projeção'!P24*'Base projeção'!$A$16,Original!P24),0) -> 0 | Q24: =SUM(C24:P24) -> 4 | R24: =Q24/$Q$15 -> 0.0046893318
B25: Carona homem | C25: =ROUND(IF(ISBLANK(Original!C25),'Base projeção'!C25*'Base projeção'!$A$16,Original!C25),0) -> 0 | D25: =ROUND(IF(ISBLANK(Original!D25),'Base projeção'!D25*'Base projeção'!$A$16,Original!D25),0) -> 0 | E25: =ROUND(IF(ISBLANK(Original!E25),'Base projeção'!E25*'Base projeção'!$A$16,Original!E25),0) -> 0 | F25: =ROUND(IF(ISBLANK(Original!F25),'Base projeção'!F25*'Base projeção'!$A$16,Original!F25),0) -> 0 | G25: =ROUND(IF(ISBLANK(Original!G25),'Base projeção'!G25*'Base projeção'!$A$16,Original!G25),0) -> 0 | H25: =ROUND(IF(ISBLANK(Original!H25),'Base projeção'!H25*'Base projeção'!$A$16,Original!H25),0) -> 0 | I25: =ROUND(IF(ISBLANK(Original!I25),'Base projeção'!I25*'Base projeção'!$A$16,Original!I25),0) -> 0 | J25: =ROUND(IF(ISBLANK(Original!J25),'Base projeção'!J25*'Base projeção'!$A$16,Original!J25),0) -> 0 | ... P25: =ROUND(IF(ISBLANK(Original!P25),'Base projeção'!P25*'Base projeção'!$A$16,Original!P25),0) -> 0 | Q25: =SUM(C25:P25) -> 0 | R25: =Q25/$Q$15 -> 0
B26: Cargueira tradicional | C26: =ROUND(IF(ISBLANK(Original!C26),'Base projeção'!C26*'Base projeção'!$A$16,Original!C26),0) -> 3 | D26: =ROUND(IF(ISBLANK(Original!D26),'Base projeção'!D26*'Base projeção'!$A$16,Original!D26),0) -> 1 | E26: =ROUND(IF(ISBLANK(Original!E26),'Base projeção'!E26*'Base projeção'!$A$16,Original!E26),0) -> 3 | F26: =ROUND(IF(ISBLANK(Original!F26),'Base projeção'!F26*'Base projeção'!$A$16,Original!F26),0) -> 4 | G26: =ROUND(IF(ISBLANK(Original!G26),'Base projeção'!G26*'Base projeção'!$A$16,Original!G26),0) -> 0 | H26: =ROUND(IF(ISBLANK(Original!H26),'Base projeção'!H26*'Base projeção'!$A$16,Original!H26),0) -> 0 | I26: =ROUND(IF(ISBLANK(Original!I26),'Base projeção'!I26*'Base projeção'!$A$16,Original!I26),0) -> 0 | J26: =ROUND(IF(ISBLANK(Original!J26),'Base projeção'!J26*'Base projeção'!$A$16,Original!J26),0) -> 0 | ... P26: =ROUND(IF(ISBLANK(Original!P26),'Base projeção'!P26*'Base projeção'!$A$16,Original!P26),0) -> 0 | Q26: =SUM(C26:P26) -> 12 | R26: =Q26/$Q$15 -> 0.014067995
B27: Adaptada a carga | C27: =ROUND(IF(ISBLANK(Original!C27),'Base projeção'!C27*'Base projeção'!$A$16,Original!C27),0) -> 4 | D27: =ROUND(IF(ISBLANK(Original!D27),'Base projeção'!D27*'Base projeção'!$A$16,Original!D27),0) -> 2 | E27: =ROUND(IF(ISBLANK(Original!E27),'Base projeção'!E27*'Base projeção'!$A$16,Original!E27),0) -> 6 | F27: =ROUND(IF(ISBLANK(Original!F27),'Base projeção'!F27*'Base projeção'!$A$16,Original!F27),0) -> 2 | G27: =ROUND(IF(ISBLANK(Original!G27),'Base projeção'!G27*'Base projeção'!$A$16,Original!G27),0) -> 0 | H27: =ROUND(IF(ISBLANK(Original!H27),'Base projeção'!H27*'Base projeção'!$A$16,Original!H27),0) -> 0 | I27: =ROUND(IF(ISBLANK(Original!I27),'Base projeção'!I27*'Base projeção'!$A$16,Original!I27),0) -> 0 | J27: =ROUND(IF(ISBLANK(Original!J27),'Base projeção'!J27*'Base projeção'!$A$16,Original!J27),0) -> 0 | ... P27: =ROUND(IF(ISBLANK(Original!P27),'Base projeção'!P27*'Base projeção'!$A$16,Original!P27),0) -> 0 | Q27: =SUM(C27:P27) -> 15 | R27: =Q27/$Q$15 -> 0.017584994
B28: Serviço | C28: =ROUND(IF(ISBLANK(Original!C28),'Base projeção'!C28*'Base projeção'!$A$16,Original!C28),0) -> 0 | D28: =ROUND(IF(ISBLANK(Original!D28),'Base projeção'!D28*'Base projeção'!$A$16,Original!D28),0) -> 0 | E28: =ROUND(IF(ISBLANK(Original!E28),'Base projeção'!E28*'Base projeção'!$A$16,Original!E28),0) -> 0 | F28: =ROUND(IF(ISBLANK(Original!F28),'Base projeção'!F28*'Base projeção'!$A$16,Original!F28),0) -> 0 | G28: =ROUND(IF(ISBLANK(Original!G28),'Base projeção'!G28*'Base projeção'!$A$16,Original!G28),0) -> 0 | H28: =ROUND(IF(ISBLANK(Original!H28),'Base projeção'!H28*'Base projeção'!$A$16,Original!H28),0) -> 0 | I28: =ROUND(IF(ISBLANK(Original!I28),'Base projeção'!I28*'Base projeção'!$A$16,Original!I28),0) -> 0 | J28: =ROUND(IF(ISBLANK(Original!J28),'Base projeção'!J28*'Base projeção'!$A$16,Original!J28),0) -> 0 | ... P28: =ROUND(IF(ISBLANK(Original!P28),'Base projeção'!P28*'Base projeção'!$A$16,Original!P28),0) -> 0 | Q28: =SUM(C28:P28) -> 12 | R28: =Q28/$Q$15 -> 0.014067995
B29: Serviço APP | C29: =ROUND(IF(ISBLANK(Original!C29),'Base projeção'!C29*'Base projeção'!$A$16,Original!C29),0) -> 0 | D29: =ROUND(IF(ISBLANK(Original!D29),'Base projeção'!D29*'Base projeção'!$A$16,Original!D29),0) -> 0 | E29: =ROUND(IF(ISBLANK(Original!E29),'Base projeção'!E29*'Base projeção'!$A$16,Original!E29),0) -> 4 | F29: =ROUND(IF(ISBLANK(Original!F29),'Base projeção'!F29*'Base projeção'!$A$16,Original!F29),0) -> 0 | G29: =ROUND(IF(ISBLANK(Original!G29),'Base projeção'!G29*'Base projeção'!$A$16,Original!G29),0) -> 0 | H29: =ROUND(IF(ISBLANK(Original!H29),'Base projeção'!H29*'Base projeção'!$A$16,Original!H29),0) -> 0 | I29: =ROUND(IF(ISBLANK(Original!I29),'Base projeção'!I29*'Base projeção'!$A$16,Original!I29),0) -> 0 | J29: =ROUND(IF(ISBLANK(Original!J29),'Base projeção'!J29*'Base projeção'!$A$16,Original!J29),0) -> 0 | ... P29: =ROUND(IF(ISBLANK(Original!P29),'Base projeção'!P29*'Base projeção'!$A$16,Original!P29),0) -> 0 | Q29: =SUM(C29:P29) -> 33 | R29: =Q29/$Q$15 -> 0.038686987
B30: Contramão | C30: =ROUND(IF(ISBLANK(Original!C30),'Base projeção'!C30*'Base projeção'!$A$16,Original!C30),0) -> 10 | D30: =ROUND(IF(ISBLANK(Original!D30),'Base projeção'!D30*'Base projeção'!$A$16,Original!D30),0) -> 9 | E30: =ROUND(IF(ISBLANK(Original!E30),'Base projeção'!E30*'Base projeção'!$A$16,Original!E30),0) -> 7 | F30: =ROUND(IF(ISBLANK(Original!F30),'Base projeção'!F30*'Base projeção'!$A$16,Original!F30),0) -> 13 | G30: =ROUND(IF(ISBLANK(Original!G30),'Base projeção'!G30*'Base projeção'!$A$16,Original!G30),0) -> 0 | H30: =ROUND(IF(ISBLANK(Original!H30),'Base projeção'!H30*'Base projeção'!$A$16,Original!H30),0) -> 0 | I30: =ROUND(IF(ISBLANK(Original!I30),'Base projeção'!I30*'Base projeção'!$A$16,Original!I30),0) -> 0 | J30: =ROUND(IF(ISBLANK(Original!J30),'Base projeção'!J30*'Base projeção'!$A$16,Original!J30),0) -> 0 | ... P30: =ROUND(IF(ISBLANK(Original!P30),'Base projeção'!P30*'Base projeção'!$A$16,Original!P30),0) -> 0 | Q30: =SUM(C30:P30) -> 71 | R30: =Q30/$Q$15 -> 0.083235639
B31: Contramão para conversão | C31: =ROUND(IF(ISBLANK(Original!C31),'Base projeção'!C31*'Base projeção'!$A$16,Original!C31),0) -> 0 | D31: =ROUND(IF(ISBLANK(Original!D31),'Base projeção'!D31*'Base projeção'!$A$16,Original!D31),0) -> 0 | E31: =ROUND(IF(ISBLANK(Original!E31),'Base projeção'!E31*'Base projeção'!$A$16,Original!E31),0) -> 0 | F31: =ROUND(IF(ISBLANK(Original!F31),'Base projeção'!F31*'Base projeção'!$A$16,Original!F31),0) -> 0 | G31: =ROUND(IF(ISBLANK(Original!G31),'Base projeção'!G31*'Base projeção'!$A$16,Original!G31),0) -> 0 | H31: =ROUND(IF(ISBLANK(Original!H31),'Base projeção'!H31*'Base projeção'!$A$16,Original!H31),0) -> 0 | I31: =ROUND(IF(ISBLANK(Original!I31),'Base projeção'!I31*'Base projeção'!$A$16,Original!I31),0) -> 0 | J31: =ROUND(IF(ISBLANK(Original!J31),'Base projeção'!J31*'Base projeção'!$A$16,Original!J31),0) -> 0 | ... P31: =ROUND(IF(ISBLANK(Original!P31),'Base projeção'!P31*'Base projeção'!$A$16,Original!P31),0) -> 0 | Q31: =SUM(C31:P31) -> 0 | R31: =Q31/$Q$15 -> 0
B32: Calçada | C32: =ROUND(IF(ISBLANK(Original!C32),'Base projeção'!C32*'Base projeção'!$A$16,Original!C32),0) -> 43 | D32: =ROUND(IF(ISBLANK(Original!D32),'Base projeção'!D32*'Base projeção'!$A$16,Original!D32),0) -> 60 | E32: =ROUND(IF(ISBLANK(Original!E32),'Base projeção'!E32*'Base projeção'!$A$16,Original!E32),0) -> 44 | F32: =ROUND(IF(ISBLANK(Original!F32),'Base projeção'!F32*'Base projeção'!$A$16,Original!F32),0) -> 18 | G32: =ROUND(IF(ISBLANK(Original!G32),'Base projeção'!G32*'Base projeção'!$A$16,Original!G32),0) -> 0 | H32: =ROUND(IF(ISBLANK(Original!H32),'Base projeção'!H32*'Base projeção'!$A$16,Original!H32),0) -> 0 | I32: =ROUND(IF(ISBLANK(Original!I32),'Base projeção'!I32*'Base projeção'!$A$16,Original!I32),0) -> 0 | J32: =ROUND(IF(ISBLANK(Original!J32),'Base projeção'!J32*'Base projeção'!$A$16,Original!J32),0) -> 0 | ... P32: =ROUND(IF(ISBLANK(Original!P32),'Base projeção'!P32*'Base projeção'!$A$16,Original!P32),0) -> 0 | Q32: =SUM(C32:P32) -> 249 | R32: =Q32/$Q$15 -> 0.2919109
B35: Dados qualitativos das observações
B36: Característica | C36: 6 | D36: 7 | E36: 8 | F36: 9 | G36: 10 | H36: 11 | I36: 12 | J36: 13 | K36: 14 | L36: 15 | M36: 16 | N36: 17 | O36: 18 | P36: 19 | Q36: TOTAL | R36: %
B37: Bike PE | Q37: =SUM(C37:P37) -> 0 | R37: =Q37/$Q$15 -> 0
B38: Empurrando | Q38: =SUM(C38:P38) -> 0 | R38: =Q38/$Q$15 -> 0
B39: Triciclo | Q39: =SUM(C39:P39) -> 0 | R39: =Q39/$Q$15 -> 0
B40: Carroça | Q40: =SUM(C40:P40) -> 0 | R40: =Q40/$Q$15 -> 0
B41: Elétrica | Q41: =SUM(C41:P41) -> 0 | R41: =Q41/$Q$15 -> 0
B42: Motorizada | Q42: =SUM(C42:P42) -> 0 | R42: =Q42/$Q$15 -> 0
B43: Skate e outros patináveis | Q43: =SUM(C43:P43) -> 0 | R43: =Q43/$Q$15 -> 0
...

Sheet Original
A1: Dados quantitativos e sentido de deslocamento
A2: ORIGEM | B2: DESTINO | C2: 6 | D2: 7 | E2: 8 | F2: 9 | G2: 10 | H2: 11 | I2: 12 | J2: 13 | K2: 14 | L2: 15 | M2: 16 | N2: 17 | O2: 18 | P2: 19 | Q2: TOTAL | R2: %
A3: Rosarinho | B3: Jaqueira | C3: 1 | D3: 1 | E3: 1 | F3: 4 | N3: 7 | O3: 4 | Q3: =SUM(C3:P3) -> 18 | R3: =Q3/$Q$15 -> 0.035019455
A4: Rosarinho | B4: Torre | Q4: =SUM(C4:P4) -> 0 | R4: =Q4/$Q$15 -> 0
A5: Rosarinho | B5: Graças | C5: 8 | D5: 14 | E5: 11 | F5: 7 | N5: 19 | O5: 10 | Q5: =SUM(C5:P5) -> 69 | R5: =Q5/$Q$15 -> 0.13424125
A6: Graças | B6: Rosarinho | C6: 1 | D6: 3 | E6: 4 | F6: 1 | N6: 8 | O6: 7 | Q6: =SUM(C6:P6) -> 24 | R6: =Q6/$Q$15 -> 0.046692607
A7: Graças | B7: Jaqueira | C7: 10 | D7: 7 | E7: 6 | F7: 9 | N7: 34 | O7: 27 | Q7: =SUM(C7:P7) -> 93 | R7: =Q7/$Q$15 -> 0.18093385
A8: Graças | B8: Torre | Q8: =SUM(C8:P8) -> 0 | R8: =Q8/$Q$15 -> 0
A9: Torre | B9: Graças | Q9: =SUM(C9:P9) -> 0 | R9: =Q9/$Q$15 -> 0
A10: Torre | B10: Rosarinho | Q10: =SUM(C10:P10) -> 0 | R10: =Q10/$Q$15 -> 0
A11: Torre | B11: Jaqueira | Q11: =SUM(C11:P11) -> 0 | R11: =Q11/$Q$15 -> 0
A12: Jaqueira | B12: Torre | Q12: =SUM(C12:P12) -> 0 | R12: =Q12/$Q$15 -> 0
A13: Jaqueira | B13: Graças | C13: 73 | D13: 70 | E13: 43 | F13: 20 | N13: 44 | O13: 34 | Q13: =SUM(C13:P13) -> 284 | R13: =Q13/$Q$15 -> 0.55252918
A14: Jaqueira | B14: Rosarinho | C14: 3 | D14: 5 | E14: 4 | F14: 2 | N14: 11 | O14: 1 | Q14: =SUM(C14:P14) -> 26 | R14: =Q14/$Q$15 -> 0.050583658
B15: TOTAL | C15: =SUM(C3:C14) -> 96 | D15: =SUM(D3:D14) -> 100 | E15: =SUM(E3:E14) -> 69 | F15: =SUM(F3:F14) -> 43 | G15: =SUM(G3:G14) -> 0 | H15: =SUM(H3:H14) -> 0 | I15: =SUM(I3:I14) -> 0 | J15: =SUM(J3:J14) -> 0 | ... P15: =SUM(P3:P14) -> 0 | Q15: =SUM(Q$3:Q$14) -> 514
B16: Percentual | C16: =C15/$Q$15 -> 0.18677043 | D16: =D15/$Q$15 -> 0.19455253 | E16: =E15/$Q$15 -> 0.13424125 | F16: =F15/$Q$15 -> 0.083657588 | G16: =G15/$Q$15 -> 0 | H16: =H15/$Q$15 -> 0 | I16: =I15/$Q$15 -> 0 | J16: =J15/$Q$15 -> 0 | ... P16: =P15/$Q$15 -> 0 | Q16: =SUM(C16:P16) -> 1
B18: Dados qualitativos padrões
B19: Característica | C19: 6 | D19: 7 | E19: 8 | F19: 9 | G19: 10 | H19: 11 | I19: 12 | J19: 13 | K19: 14 | L19: 15 | M19: 16 | N19: 17 | O19: 18 | P19: 19 | Q19: TOTAL | R19: %
B20: Mulher | C20: 5 | D20: 12 | E20: 8 | F20: 8 | N20: 5 | O20: 10 | Q20: =SUM(C20:P20) -> 48 | R20: =Q20/$Q$15 -> 0.093385214
B21: Crianças e adolescentes | C21: 5 | D21: 0 | E21: 0 | F21: 0 | N21: 0 | O21: 0 | Q21: =SUM(C21:P21) -> 5 | R21: =Q21/$Q$15 -> 0.0097276265
B22: Capacete | C22: 11 | D22: 15 | E22: 13 | F22: 9 | N22: 4 | O22: 3 | Q22: =SUM(C22:P22) -> 55 | R22: =Q22/$Q$15 -> 0.10700389
B23: Carona criança | C23: 1 | D23: 2 | E23: 2 | F23: 0 | N23: 0 | O23: 4 | Q23: =SUM(C23:P23) -> 9 | R23: =Q23/$Q$15 -> 0.017509728
B24: Carona mulher | C24: 1 | D24: 1 | E24: 1 | F24: 0 | N24: 1 | O24: 0 | Q24: =SUM(C24:P24) -> 4 | R24: =Q24/$Q$15 -> 0.0077821012
B25: Carona homem | C25: 0 | D25: 0 | E25: 0 | F25: 0 | N25: 0 | O25: 0 | Q25: =SUM(C25:P25) -> 0 | R25: =Q25/$Q$15 -> 0
B26: Cargueira tradicional | C26: 3 | D26: 1 | E26: 3 | F26: 4 | N26: 0 | O26: 1 | Q26: =SUM(C26:P26) -> 12 | R26: =Q26/$Q$15 -> 0.023346303
B27: Adaptada a carga | C27: 4 | D27: 2 | E27: 6 | F27: 2 | N27: 0 | O27: 1 | Q27: =SUM(C27:P27) -> 15 | R27: =Q27/$Q$15 -> 0.029182879
B28: Serviço | C28: 0 | D28: 0 | E28: 0 | F28: 0 | N28: 12 | O28: 0 | Q28: =SUM(C28:P28) -> 12 | R28: =Q28/$Q$15 -> 0.023346303
B29: Serviço APP | C29: 0 | D29: 0 | E29: 4 | F29: 0 | N29: 19 | O29: 10 | Q29: =SUM(C29:P29) -> 33 | R29: =Q29/$Q$15 -> 0.064202335
B30: Contramão | C30: 10 | D30: 9 | E30: 7 | F30: 13 | N30: 10 | O30: 22 | Q30: =SUM(C30:P30) -> 71 | R30: =Q30/$Q$15 -> 0.1381323
B31: Contramão para conversão | C31: 0 | D31: 0 | E31: 0 | F31: 0 | N31: 0 | O31: 0 | Q31: =SUM(C31:P31) -> 0 | R31: =Q31/$Q$15 -> 0
B32: Calçada | C32: 43 | D32: 60 | E32: 44 | F32: 18 | N32: 51 | O32: 33 | Q32: =SUM(C32:P32) -> 249 | R32: =Q32/$Q$15 -> 0.4844358
B35: Dados qualitativos das observações
B36: Característica | C36: 6 | D36: 7 | E36: 8 | F36: 9 | G36: 10 | H36: 11 | I36: 12 | J36: 13 | K36: 14 | L36: 15 | M36: 16 | N36: 17 | O36: 18 | P36: 19 | Q36: TOTAL | R36: %
B37: Bike PE | Q37: =SUM(C37:P37) -> 0 | R37: =Q37/$Q$15 -> 0
B38: Empurrando | C38: 1 | Q38: =SUM(C38:P38) -> 1 | R38: =Q38/$Q$15 -> 0.0019455253
B39: Triciclo | C39: 1 | Q39: =SUM(C39:P39) -> 1 | R39: =Q39/$Q$15 -> 0.0019455253
B40: Carroça | Q40: =SUM(C40:P40) -> 0 | R40: =Q40/$Q$15 -> 0
B41: Elétrica | C41: 3 | F41: 2 | Q41: =SUM(C41:P41) -> 5 | R41: =Q41/$Q$15 -> 0.0097276265
B42: Motorizada | Q42: =SUM(C42:P42) -> 0 | R42: =Q42/$Q$15 -> 0
B43: Skate e outros patináveis | Q43: =SUM(C43:P43) -> 0 | R43: =Q43/$Q$15 -> 0
...

Sheet Base projeção
A1: Dados quantitativos e sentido de deslocamento
A2: ORIGEM | B2: DESTINO | C2: 6 | D2: 7 | E2: 8 | F2: 9 | G2: 10 | H2: 11 | I2: 12 | J2: 13 | K2: 14 | L2: 15 | M2: 16 | N2: 17 | O2: 18 | P2: 19 | Q2: TOTAL | R2: %
A3: Rosarinho | B3: Jaqueira | C3: 2 | D3: 2 | E3: 2 | F3: 2 | G3: 5 | H3: 0 | I3: 2 | J3: 1 | K3: 1 | L3: 0 | M3: 0 | N3: 5 | O3: 3 | P3: 3 | Q3: =SUM(C3:P3) -> 28 | R3: =Q3/$Q$15 -> 0.035175879
A4: Rosarinho | Q4: =SUM(C4:P4) -> 0 | R4: =Q4/$Q$15 -> 0
A5: Rosarinho | B5: Graças | C5: 11 | D5: 10 | E5: 14 | F5: 6 | G5: 10 | H5: 2 | I5: 10 | J5: 1 | K5: 11 | L5: 2 | M5: 10 | N5: 15 | O5: 11 | P5: 5 | Q5: =SUM(C5:P5) -> 118 | R5: =Q5/$Q$15 -> 0.14824121
A6: Graças | B6: Rosarinho | C6: 4 | D6: 2 | E6: 9 | F6: 4 | G6: 0 | H6: 3 | I6: 3 | J6: 2 | K6: 1 | L6: 1 | M6: 2 | N6: 3 | O6: 3 | P6: 2 | Q6: =SUM(C6:P6) -> 39 | R6: =Q6/$Q$15 -> 0.048994975
A7: Graças | B7: Jaqueira | C7: 12 | D7: 2 | E7: 3 | F7: 1 | G7: 5 | H7: 4 | I7: 11 | J7: 3 | K7: 9 | L7: 4 | M7: 11 | N7: 18 | O7: 12 | P7: 18 | Q7: =SUM(C7:P7) -> 113 | R7: =Q7/$Q$15 -> 0.1419598
A8: Graças | Q8: =SUM(C8:P8) -> 0 | R8: =Q8/$Q$15 -> 0
A9: Torre | Q9: =SUM(C9:P9) -> 0 | R9: =Q9/$Q$15 -> 0
A10: Torre | Q10: =SUM(C10:P10) -> 0 | R10: =Q10/$Q$15 -> 0
A11: Torre | Q11: =SUM(C11:P11) -> 0 | R11: =Q11/$Q$15 -> 0
A12: Jaqueira | Q12: =SUM(C12:P12) -> 0 | R12: =Q12/$Q$15 -> 0
A13: Jaqueira | B13: Graças | C13: 69 | D13: 51 | E13: 59 | F13: 49 | G13: 13 | H13: 24 | I13: 22 | J13: 18 | K13: 25 | L13: 19 | M13: 12 | N13: 40 | O13: 40 | P13: 25 | Q13: =SUM(C13:P13) -> 466 | R13: =Q13/$Q$15 -> 0.58542714
A14: Jaqueira | B14: Rosarinho | C14: 4 | D14: 2 | E14: 4 | F14: 1 | G14: 1 | H14: 4 | I14: 3 | J14: 4 | K14: 1 | L14: 2 | M14: 1 | N14: 2 | O14: 0 | P14: 3 | Q14: =SUM(C14:P14) -> 32 | R14: =Q14/$Q$15 -> 0.040201005
A15: AUMENTO | B15: TOTAL | C15: =SUM(C3:C14) -> 102 | D15: =SUM(D3:D14) -> 69 | E15: =SUM(E3:E14) -> 91 | F15: =SUM(F3:F14) -> 63 | G15: =SUM(G3:G14) -> 34 | H15: =SUM(H3:H14) -> 37 | I15: =SUM(I3:I14) -> 51 | J15: =SUM(J3:J14) -> 29 | ... Q15: =SUM(Q3:Q14) -> 796
A16: =Original!$Q$15/SUM(C15:F15,N15:O15) -> 1.0775681 | B16: Percentual | C16: =C15/$Q$15 -> 0.1281407 | D16: =D15/$Q$15 -> 0.086683417 | E16: =E15/$Q$15 -> 0.11432161 | F16: =F15/$Q$15 -> 0.079145729 | G16: =G15/$Q$15 -> 0.042713568 | H16: =H15/$Q$15 -> 0.046482412 | I16: =I15/$Q$15 -> 0.064070352 | J16: =J15/$Q$15 -> 0.036432161 | ... P16: =P15/$Q$15 -> 0.070351759 | Q16: =SUM(C16:P16) -> 1
B18: Dados qualitativos padrões
B19: Característica | C19: 6 | D19: 7 | E19: 8 | F19: 9 | G19: 10 | H19: 11 | I19: 12 | J19: 13 | K19: 14 | L19: 15 | M19: 16 | N19: 17 | O19: 18 | P19: 19 | Q19: TOTAL | R19: %
B20: Mulher | C20: 5 | D20: 3 | E20: 8 | F20: 4 | G20: 1 | H20: 4 | I20: 1 | J20: 5 | K20: 7 | L20: 1 | M20: 2 | N20: 10 | O20: 2 | P20: 5 | Q20: =SUM(C20:P20) -> 58 | R20: =Q20/$Q$15 -> 0.072864322
B21: Crianças e adolescentes | C21: 4 | D21: 1 | E21: 0 | F21: 0 | G21: 0 | H21: 0 | I21: 10 | J21: 7 | K21: 4 | L21: 6 | M21: 1 | N21: 4 | O21: 2 | P21: 4 | Q21: =SUM(C21:P21) -> 43 | R21: =Q21/$Q$15 -> 0.054020101
B22: Capacete | C22: 5 | D22: 10 | E22: 7 | F22: 8 | G22: 5 | H22: 7 | I22: 7 | J22: 3 | K22: 5 | L22: 4 | M22: 5 | N22: 18 | O22: 10 | P22: 18 | Q22: =SUM(C22:P22) -> 112 | R22: =Q22/$Q$15 -> 0.14070352
B23: Carona criança | Q23: =SUM(C23:P23) -> 0 | R23: =Q23/$Q$15 -> 0
B24: Carona mulher | Q24: =SUM(C24:P24) -> 0 | R24: =Q24/$Q$15 -> 0
B25: Carona homem | Q25: =SUM(C25:P25) -> 0 | R25: =Q25/$Q$15 -> 0
B26: Cargueira tradicional | Q26: =SUM(C26:P26) -> 0 | R26: =Q26/$Q$15 -> 0
B27: Adaptada a carga | Q27: =SUM(C27:P27) -> 0 | R27: =Q27/$Q$15 -> 0
B28: Serviço | Q28: =SUM(C28:P28) -> 0 | R28: =Q28/$Q$15 -> 0
B29: Serviço APP | Q29: =SUM(C29:P29) -> 0 | R29: =Q29/$Q$15 -> 0
B30: Contramão | Q30: =SUM(C30:P30) -> 0 | R30: =Q30/$Q$15 -> 0
B31: Contramão para conversão | Q31: =SUM(C31:P31) -> 0 | R31: =Q31/$Q$15 -> 0
B32: Calçada | Q32: =SUM(C32:P32) -> 0 | R32: =Q32/$Q$15 -> 0
B35: Dados qualitativos das observações
B36: Característica | C36: 6 | D36: 7 | E36: 8 | F36: 9 | G36: 10 | H36: 11 | I36: 12 | J36: 13 | K36: 14 | L36: 15 | M36: 16 | N36: 17 | O36: 18 | P36: 19 | Q36: TOTAL | R36: %
B37: Bike PE | Q37: =SUM(C37:P37) -> 0 | R37: =Q37/$Q$15 -> 0
B38: Empurrando | C38: 1 | Q38: =SUM(C38:P38) -> 1 | R38: =Q38/$Q$15 -> 0.0012562814
B39: Triciclo | C39: 1 | Q39: =SUM(C39:P39) -> 1 | R39: =Q39/$Q$15 -> 0.0012562814
B40: Carroça | Q40: =SUM(C40:P40) -> 0 | R40: =Q40/$Q$15 -> 0
B41: Elétrica | C41: 3 | F41: 2 | Q41: =SUM(C41:P41) -> 5 | R41: =Q41/$Q$15 -> 0.006281407
B42: Motorizada | Q42: =SUM(C42:P42) -> 0 | R42: =Q42/$Q$15 -> 0
B43: Skate e outros patináveis | Q43: =SUM(C43:P43) -> 0 | R43: =Q43/$Q$15 -> 0
...

Sheet CONFFLUXO
A1: =Fluxo!A2 -> TOTAL | F1: 2 | G1: {=TRANSPOSE(Dados!2:2)} -> ORIGEM
F2: 3 | G2: DESTINO
A3: =Dados!A3 -> Rosarinho | B3: =Dados!B3 -> Jaqueira | F3: 4 | G3: 6 | Q3: =HLOOKUP($A$1,Dados!$C$2:$R$14,F1,0) -> 30
A4: =Dados!A4 -> Rosarinho | B4: =Dados!B4 -> Torre | F4: 5 | G4: 7 | Q4: =HLOOKUP($A$1,Dados!$C$2:$R$14,F2,0) -> 0
A5: =Dados!A5 -> Rosarinho | B5: =Dados!B5 -> Graças | F5: 6 | G5: 8 | Q5: =HLOOKUP($A$1,Dados!$C$2:$R$14,F3,0) -> 124
A6: =Dados!A6 -> Graças | B6: =Dados!B6 -> Rosarinho | F6: 7 | G6: 9 | Q6: =HLOOKUP($A$1,Dados!$C$2:$R$14,F4,0) -> 38
A7: =Dados!A7 -> Graças | B7: =Dados!B7 -> Jaqueira | F7: 8 | G7: 10 | Q7: =HLOOKUP($A$1,Dados!$C$2:$R$14,F5,0) -> 162
A8: =Dados!A8 -> Graças | B8: =Dados!B8 -> Torre | F8: 9 | G8: 11 | Q8: =HLOOKUP($A$1,Dados!$C$2:$R$14,F6,0) -> 0
A9: =Dados!A9 -> Torre | B9: =Dados!B9 -> Graças | F9: 10 | G9: 12 | Q9: =HLOOKUP($A$1,Dados!$C$2:$R$14,F7,0) -> 0
A10: =Dados!A10 -> Torre | B10: =Dados!B10 -> Rosarinho | F10: 11 | G10: 13 | Q10: =HLOOKUP($A$1,Dados!$C$2:$R$14,F8,0) -> 0
A11: =Dados!A11 -> Torre | B11: =Dados!B11 -> Jaqueira | F11: 12 | G11: 14 | Q11: =HLOOKUP($A$1,Dados!$C$2:$R$14,F9,0) -> 0
A12: =Dados!A12 -> Jaqueira | B12: =Dados!B12 -> Torre | F12: 13 | G12: 15 | Q12: =HLOOKUP($A$1,Dados!$C$2:$R$14,F10,0) -> 0
A13: =Dados!A13 -> Jaqueira | B13: =Dados!B13 -> Graças | G13: 16 | Q13: =HLOOKUP($A$1,Dados!$C$2:$R$14,F11,0) -> 454
A14: =Dados!A14 -> Jaqueira | B14: =Dados!B14 -> Rosarinho | G14: 17 | Q14: =HLOOKUP($A$1,Dados!$C$2:$R$14,F12,0) -> 45
G15: 18
G16: 19
G17: TOTAL
G18: %

Sheet Gráficos
A1: Ciclistas por hora
A2: Horário início | B2: =Dados!C2 -> 6 | C2: =Dados!D2 -> 7 | D2: =Dados!E2 -> 8 | E2: =Dados!F2 -> 9 | F2: =Dados!G2 -> 10 | G2: =Dados!H2 -> 11 | H2: =Dados!I2 -> 12 | I2: =Dados!J2 -> 13 | ... O2: =Dados!P2 -> 19
A3: Homens | B3: =Dados!C15-B4-B5 -> 86 | C3: =Dados!D15-C4-C5 -> 88 | D3: =Dados!E15-D4-D5 -> 61 | E3: =Dados!F15-E4-E5 -> 35 | F3: =Dados!G15-F4-F5 -> 35 | G3: =Dados!H15-G4-G5 -> 35 | H3: =Dados!I15-H4-H5 -> 43 | I3: =Dados!J15-I4-I5 -> 17 | ... O3: =Dados!P15-O4-O5 -> 50
A4: Mulheres | B4: =Dados!C20 -> 5 | C4: =Dados!D20 -> 12 | D4: =Dados!E20 -> 8 | E4: =Dados!F20 -> 8 | F4: =Dados!G20 -> 1 | G4: =Dados!H20 -> 4 | H4: =Dados!I20 -> 1 | I4: =Dados!J20 -> 5 | ... O4: =Dados!P20 -> 5
A5: Crianças e adolescentes | B5: =Dados!C21 -> 5 | C5: =Dados!D21 -> 0 | D5: =Dados!E21 -> 0 | E5: =Dados!F21 -> 0 | F5: =Dados!G21 -> 0 | G5: =Dados!H21 -> 0 | H5: =Dados!I21 -> 11 | I5: =Dados!J21 -> 8 | ... O5: =Dados!P21 -> 4
A7: Ciclistas por hora %
A8: Horário | B8: 6 | C8: 7 | D8: 8 | E8: 9 | F8: 10 | G8: 11 | H8: 12 | I8: 13 | J8: 14 | K8: 15 | L8: 16 | M8: 17 | N8: 18 | O8: 19
A9: Mulheres | B9: =B4/Dados!C$15 -> 0.052083333 | C9: =C4/Dados!D$15 -> 0.12 | D9: =D4/Dados!E$15 -> 0.11594203 | E9: =E4/Dados!F$15 -> 0.18604651 | F9: =F4/Dados!G$15 -> 0.027777778 | G9: =G4/Dados!H$15 -> 0.1025641 | H9: =H4/Dados!I$15 -> 0.018181818 | I9: =I4/Dados!J$15 -> 0.16666667 | ... O9: =O4/Dados!P$15 -> 0.084745763
A10: Crianças e adolescentes | B10: =B5/Dados!C$15 -> 0.052083333 | C10: =C5/Dados!D$15 -> 0 | D10: =D5/Dados!E$15 -> 0 | E10: =E5/Dados!F$15 -> 0 | F10: =F5/Dados!G$15 -> 0 | G10: =G5/Dados!H$15 -> 0 | H10: =H5/Dados!I$15 -> 0.2 | I10: =I5/Dados!J$15 -> 0.26666667 | ... O10: =O5/Dados!P$15 -> 0.06779661
A12: =Dados!B19 -> Característica | B12: =Dados!R19 -> %
A13: =Dados!B20 -> Mulher | B13: =Dados!R20 -> 0.087924971
A14: =Dados!B21 -> Crianças e adolescentes | B14: =Dados!R21 -> 0.045720985
A15: =Dados!B22 -> Capacete | B15: =Dados!R22 -> 0.13130129
A16: Caronas | B16: =SUM(Dados!R23:R25) -> 0.015240328
A17: =Dados!B35 -> Dados qualitativos das observações | B17: =Dados!R35
A18: =Dados!B37 -> Bike PE | B18: =Dados!R37 -> 0
A19: =Dados!B39 -> Triciclo | B19: =Dados!R39 -> 0
A20: =Dados!B27 -> Adaptada a carga | B20: =Dados!R27 -> 0.017584994

Sheet Fluxo
A1: HORÁRIO | E1: =UPPER(CONFFLUXO!A3) -> ROSARINHO
A2: TOTAL | E2: =SUM(E3:G3) -> 154
E3: =CONFFLUXO!Q3 -> 30 | F3: =CONFFLUXO!Q4 -> 0 | G3: =CONFFLUXO!Q5 -> 124
A5: =UPPER(CONFFLUXO!A12) -> JAQUEIRA | B5: =SUM(C5:C7) -> 499 | C5: =CONFFLUXO!Q14 -> 45 | I5: =CONFFLUXO!Q6 -> 38 | J5: =SUM(I5:I7) -> 200 | K5: =UPPER(CONFFLUXO!A6) -> GRAÇAS
C6: =CONFFLUXO!Q13 -> 454 | F6: =SUM(E3:G3,I5:I7,E9:G9,C5:C7) -> 853 | I6: =CONFFLUXO!Q7 -> 162
C7: =CONFFLUXO!Q12 -> 0 | I7: =CONFFLUXO!Q8 -> 0
E9: =CONFFLUXO!Q11 -> 0 | F9: =CONFFLUXO!Q10 -> 0 | G9: =CONFFLUXO!Q9 -> 0
E10: =SUM(E9:G9) -> 0
E11: =UPPER(CONFFLUXO!A9) -> TORRE | K11: =MAX(3:3,I:I,9:9,C:C) -> 454

Sheet Coordenadas
A1: Norte
A2: Leste
A3: Sul
A4: Oeste
