Workbook

Sheet Resumo
A1: Cruzamento | B1: Av. Rui Barbosa x Av. Dr. Malaquias
A2: Data | B2: 43593
A3: Coordenadas Geográficas | B3: -8.03989, -34.90401
A4: Relatório
A5: Total | B5: =Dados!Q15 -> 796
A6: Máximo em um hora | B6: =MAX(Dados!C15:P15) -> 102
A7: Mulher | B7: =Dados!R20 -> 0.072864322
A8: Crianças e adolescentes | B8: =Dados!R21 -> 0.054020101
A9: Capacete | B9: =Dados!R22 -> 0.14070352
A10: Caronas | B10: =Dados!R23 -> 0.022613065
A11: Cargueiras | B11: =Dados!R24 -> 0.031407035
A12: Serviço | B12: =Dados!R25 -> 0.016331658
A13: Contramão | B13: =Dados!R26 -> 0.050251256
A14: Calçada | B14: =Dados!R27 -> 0.15703518

Sheet Dados
A1: Dados quantitativos e sentido de deslocamento
A2: ORIGEM | B2: DESTINO | C2: 6 | D2: 7 | E2: 8 | F2: 9 | G2: 10 | H2: 11 | I2: 12 | J2: 13 | K2: 14 | L2: 15 | M2: 16 | N2: 17 | O2: 18 | P2: 19 | Q2: TOTAL | R2: %
A3: Jaqueira | Q3: =SUM(C3:P3) -> 0 | R3: =Q3/$Q$15 -> 0
A4: Jaqueira | B4: Graças | C4: =ROUND(IF(ISBLANK(Original!D4),'Base projeção'!C4*'Base projeção'!$A$16,Original!D4),0) -> 69 | D4: =ROUND(IF(ISBLANK(Original!E4),'Base projeção'!D4*'Base projeção'!$A$16,Original!E4),0) -> 51 | E4: =ROUND(IF(ISBLANK(Original!F4),'Base projeção'!E4*'Base projeção'!$A$16,Original!F4),0) -> 59 | F4: =ROUND(IF(ISBLANK(Original!G4),'Base projeção'!F4*'Base projeção'!$A$16,Original!G4),0) -> 49 | G4: =ROUND(IF(ISBLANK(Original!H4),'Base projeção'!G4*'Base projeção'!$A$16,Original!H4),0) -> 13 | H4: =ROUND(IF(ISBLANK(Original!I4),'Base projeção'!H4*'Base projeção'!$A$16,Original!I4),0) -> 24 | I4: =ROUND(IF(ISBLANK(Original!J4),'Base projeção'!I4*'Base projeção'!$A$16,Original!J4),0) -> 22 | J4: =ROUND(IF(ISBLANK(Original!K4),'Base projeção'!J4*'Base projeção'!$A$16,Original!K4),0) -> 18 | ... P4: =ROUND(IF(ISBLANK(Original!Q4),'Base projeção'!P4*'Base projeção'!$A$16,Original!Q4),0) -> 25 | Q4: =SUM(C4:P4) -> 466 | R4: =Q4/$Q$15 -> 0.58542714
A5: Jaqueira | B5: Rosarinho | C5: =ROUND(IF(ISBLANK(Original!D5),'Base projeção'!C5*'Base projeção'!$A$16,Original!D5),0) -> 4 | D5: =ROUND(IF(ISBLANK(Original!E5),'Base projeção'!D5*'Base projeção'!$A$16,Original!E5),0) -> 2 | E5: =ROUND(IF(ISBLANK(Original!F5),'Base projeção'!E5*'Base projeção'!$A$16,Original!F5),0) -> 4 | F5: =ROUND(IF(ISBLANK(Original!G5),'Base projeção'!F5*'Base projeção'!$A$16,Original!G5),0) -> 1 | G5: =ROUND(IF(ISBLANK(Original!H5),'Base projeção'!G5*'Base projeção'!$A$16,Original!H5),0) -> 1 | H5: =ROUND(IF(ISBLANK(Original!I5),'Base projeção'!H5*'Base projeção'!$A$16,Original!I5),0) -> 4 | I5: =ROUND(IF(ISBLANK(Original!J5),'Base projeção'!I5*'Base projeção'!$A$16,Original!J5),0) -> 3 | J5: =ROUND(IF(ISBLANK(Original!K5),'Base projeção'!J5*'Base projeção'!$A$16,Original!K5),0) -> 4 | ... P5: =ROUND(IF(ISBLANK(Original!Q5),'Base projeção'!P5*'Base projeção'!$A$16,Original!Q5),0) -> 3 | Q5: =SUM(C5:P5) -> 32 | R5: =Q5/$Q$15 -> 0.040201005
A6: Rosarinho | B6: Jaqueira | C6: =ROUND(IF(ISBLANK(Original!D6),'Base projeção'!C6*'Base projeção'!$A$16,Original!D6),0) -> 2 | D6: =ROUND(IF(ISBLANK(Original!E6),'Base projeção'!D6*'Base projeção'!$A$16,Original!E6),0) -> 2 | E6: =ROUND(IF(ISBLANK(Original!F6),'Base projeção'!E6*'Base projeção'!$A$16,Original!F6),0) -> 2 | F6: =ROUND(IF(ISBLANK(Original!G6),'Base projeção'!F6*'Base projeção'!$A$16,Original!G6),0) -> 2 | G6: =ROUND(IF(ISBLANK(Original!H6),'Base projeção'!G6*'Base projeção'!$A$16,Original!H6),0) -> 5 | H6: =ROUND(IF(ISBLANK(Original!I6),'Base projeção'!H6*'Base projeção'!$A$16,Original!I6),0) -> 0 | I6: =ROUND(IF(ISBLANK(Original!J6),'Base projeção'!I6*'Base projeção'!$A$16,Original!J6),0) -> 2 | J6: =ROUND(IF(ISBLANK(Original!K6),'Base projeção'!J6*'Base projeção'!$A$16,Original!K6),0) -> 1 | ... P6: =ROUND(IF(ISBLANK(Original!Q6),'Base projeção'!P6*'Base projeção'!$A$16,Original!Q6),0) -> 3 | Q6: =SUM(C6:P6) -> 28 | R6: =Q6/$Q$15 -> 0.035175879
A7: Rosarinho | Q7: =SUM(C7:P7) -> 0 | R7: =Q7/$Q$15 -> 0
A8: Rosarinho | B8: Graças | C8: =ROUND(IF(ISBLANK(Original!D8),'Base projeção'!C8*'Base projeção'!$A$16,Original!D8),0) -> 11 | D8: =ROUND(IF(ISBLANK(Original!E8),'Base projeção'!D8*'Base projeção'!$A$16,Original!E8),0) -> 10 | E8: =ROUND(IF(ISBLANK(Original!F8),'Base projeção'!E8*'Base projeção'!$A$16,Original!F8),0) -> 14 | F8: =ROUND(IF(ISBLANK(Original!G8),'Base projeção'!F8*'Base projeção'!$A$16,Original!G8),0) -> 6 | G8: =ROUND(IF(ISBLANK(Original!H8),'Base projeção'!G8*'Base projeção'!$A$16,Original!H8),0) -> 10 | H8: =ROUND(IF(ISBLANK(Original!I8),'Base projeção'!H8*'Base projeção'!$A$16,Original!I8),0) -> 2 | I8: =ROUND(IF(ISBLANK(Original!J8),'Base projeção'!I8*'Base projeção'!$A$16,Original!J8),0) -> 10 | J8: =ROUND(IF(ISBLANK(Original!K8),'Base projeção'!J8*'Base projeção'!$A$16,Original!K8),0) -> 1 | ... P8: =ROUND(IF(ISBLANK(Original!Q8),'Base projeção'!P8*'Base projeção'!$A$16,Original!Q8),0) -> 5 | Q8: =SUM(C8:P8) -> 118 | R8: =Q8/$Q$15 -> 0.14824121
A9: Graças | B9: Rosarinho | C9: =ROUND(IF(ISBLANK(Original!D9),'Base projeção'!C9*'Base projeção'!$A$16,Original!D9),0) -> 4 | D9: =ROUND(IF(ISBLANK(Original!E9),'Base projeção'!D9*'Base projeção'!$A$16,Original!E9),0) -> 2 | E9: =ROUND(IF(ISBLANK(Original!F9),'Base projeção'!E9*'Base projeção'!$A$16,Original!F9),0) -> 9 | F9: =ROUND(IF(ISBLANK(Original!G9),'Base projeção'!F9*'Base projeção'!$A$16,Original!G9),0) -> 4 | G9: =ROUND(IF(ISBLANK(Original!H9),'Base projeção'!G9*'Base projeção'!$A$16,Original!H9),0) -> 0 | H9: =ROUND(IF(ISBLANK(Original!I9),'Base projeção'!H9*'Base projeção'!$A$16,Original!I9),0) -> 3 | I9: =ROUND(IF(ISBLANK(Original!J9),'Base projeção'!I9*'Base projeção'!$A$16,Original!J9),0) -> 3 | J9: =ROUND(IF(ISBLANK(Original!K9),'Base projeção'!J9*'Base projeção'!$A$16,Original!K9),0) -> 2 | ... P9: =ROUND(IF(ISBLANK(Original!Q9),'Base projeção'!P9*'Base projeção'!$A$16,Original!Q9),0) -> 2 | Q9: =SUM(C9:P9) -> 39 | R9: =Q9/$Q$15 -> 0.048994975
A10: Graças | B10: Jaqueira | C10: =ROUND(IF(ISBLANK(Original!D10),'Base projeção'!C10*'Base projeção'!$A$16,Original!D10),0) -> 12 | D10: =ROUND(IF(ISBLANK(Original!E10),'Base projeção'!D10*'Base projeção'!$A$16,Original!E10),0) -> 2 | E10: =ROUND(IF(ISBLANK(Original!F10),'Base projeção'!E10*'Base projeção'!$A$16,Original!F10),0) -> 3 | F10: =ROUND(IF(ISBLANK(Original!G10),'Base projeção'!F10*'Base projeção'!$A$16,Original!G10),0) -> 1 | G10: =ROUND(IF(ISBLANK(Original!H10),'Base projeção'!G10*'Base projeção'!$A$16,Original!H10),0) -> 5 | H10: =ROUND(IF(ISBLANK(Original!I10),'Base projeção'!H10*'Base projeção'!$A$16,Original!I10),0) -> 4 | I10: =ROUND(IF(ISBLANK(Original!J10),'Base projeção'!I10*'Base projeção'!$A$16,Original!J10),0) -> 11 | J10: =ROUND(IF(ISBLANK(Original!K10),'Base projeção'!J10*'Base projeção'!$A$16,Original!K10),0) -> 3 | ... P10: =ROUND(IF(ISBLANK(Original!Q10),'Base projeção'!P10*'Base projeção'!$A$16,Original!Q10),0) -> 18 | Q10: =SUM(C10:P10) -> 113 | R10: =Q10/$Q$15 -> 0.1419598
A11: Graças | Q11: =SUM(C11:P11) -> 0 | R11: =Q11/$Q$15 -> 0
A12: Torre | Q12: =SUM(C12:P12) -> 0 | R12: =Q12/$Q$15 -> 0
A13: Torre | Q13: =SUM(C13:P13) -> 0 | R13: =Q13/$Q$15 -> 0
A14: Torre | Q14: =SUM(C14:P14) -> 0 | R14: =Q14/$Q$15 -> 0
B15: TOTAL | C15: =SUM(C$3:C$14) -> 102 | D15: =SUM(D$3:D$14) -> 69 | E15: =SUM(E$3:E$14) -> 91 | F15: =SUM(F$3:F$14) -> 63 | G15: =SUM(G$3:G$14) -> 34 | H15: =SUM(H$3:H$14) -> 37 | I15: =SUM(I$3:I$14) -> 51 | J15: =SUM(J$3:J$14) -> 29 | ... Q15: =SUM(Q$3:Q$14) -> 796
B16: Percentual | C16: =C15/$Q$15 -> 0.1281407 | D16: =D15/$Q$15 -> 0.086683417 | E16: =E15/$Q$15 -> 0.11432161 | F16: =F15/$Q$15 -> 0.079145729 | G16: =G15/$Q$15 -> 0.042713568 | H16: =H15/$Q$15 -> 0.046482412 | I16: =I15/$Q$15 -> 0.064070352 | J16: =J15/$Q$15 -> 0.036432161 | ... P16: =P15/$Q$15 -> 0.070351759 | Q16: =SUM(C16:P16) -> 1
A18: Dados qualitativos padrões
B19: Característica | C19: 6 | D19: 7 | E19: 8 | F19: 9 | G19: 10 | H19: 11 | I19: 12 | J19: 13 | K19: 14 | L19: 15 | M19: 16 | N19: 17 | O19: 18 | P19: 19 | Q19: TOTAL | R19: %
B20: Mulher | C20: =ROUND(IF(ISBLANK(Original!D20),'Base projeção'!C20*'Base projeção'!$A$16,Original!D20),0) -> 5 | D20: =ROUND(IF(ISBLANK(Original!E20),'Base projeção'!D20*'Base projeção'!$A$16,Original!E20),0) -> 3 | E20: =ROUND(IF(ISBLANK(Original!F20),'Base projeção'!E20*'Base projeção'!$A$16,Original!F20),0) -> 8 | F20: =ROUND(IF(ISBLANK(Original!G20),'Base projeção'!F20*'Base projeção'!$A$16,Original!G20),0) -> 4 | G20: =ROUND(IF(ISBLANK(Original!H20),'Base projeção'!G20*'Base projeção'!$A$16,Original!H20),0) -> 1 | H20: =ROUND(IF(ISBLANK(Original!I20),'Base projeção'!H20*'Base projeção'!$A$16,Original!I20),0) -> 4 | I20: =ROUND(IF(ISBLANK(Original!J20),'Base projeção'!I20*'Base projeção'!$A$16,Original!J20),0) -> 1 | J20: =ROUND(IF(ISBLANK(Original!K20),'Base projeção'!J20*'Base projeção'!$A$16,Original!K20),0) -> 5 | ... P20: =ROUND(IF(ISBLANK(Original!Q20),'Base projeção'!P20*'Base projeção'!$A$16,Original!Q20),0) -> 5 | Q20: =SUM(C20:P20) -> 58 | R20: =Q20/$Q$15 -> 0.072864322
B21: Capacete | C21: =ROUND(IF(ISBLANK(Original!D21),'Base projeção'!C21*'Base projeção'!$A$16,Original!D21),0) -> 4 | D21: =ROUND(IF(ISBLANK(Original!E21),'Base projeção'!D21*'Base projeção'!$A$16,Original!E21),0) -> 1 | E21: =ROUND(IF(ISBLANK(Original!F21),'Base projeção'!E21*'Base projeção'!$A$16,Original!F21),0) -> 0 | F21: =ROUND(IF(ISBLANK(Original!G21),'Base projeção'!F21*'Base projeção'!$A$16,Original!G21),0) -> 0 | G21: =ROUND(IF(ISBLANK(Original!H21),'Base projeção'!G21*'Base projeção'!$A$16,Original!H21),0) -> 0 | H21: =ROUND(IF(ISBLANK(Original!I21),'Base projeção'!H21*'Base projeção'!$A$16,Original!I21),0) -> 0 | I21: =ROUND(IF(ISBLANK(Original!J21),'Base projeção'!I21*'Base projeção'!$A$16,Original!J21),0) -> 10 | J21: =ROUND(IF(ISBLANK(Original!K21),'Base projeção'!J21*'Base projeção'!$A$16,Original!K21),0) -> 7 | ... P21: =ROUND(IF(ISBLANK(Original!Q21),'Base projeção'!P21*'Base projeção'!$A$16,Original!Q21),0) -> 4 | Q21: =SUM(C21:P21) -> 43 | R21: =Q21/$Q$15 -> 0.054020101
B22: Crianças e adolescentes | C22: =ROUND(IF(ISBLANK(Original!D22),'Base projeção'!C22*'Base projeção'!$A$16,Original!D22),0) -> 5 | D22: =ROUND(IF(ISBLANK(Original!E22),'Base projeção'!D22*'Base projeção'!$A$16,Original!E22),0) -> 10 | E22: =ROUND(IF(ISBLANK(Original!F22),'Base projeção'!E22*'Base projeção'!$A$16,Original!F22),0) -> 7 | F22: =ROUND(IF(ISBLANK(Original!G22),'Base projeção'!F22*'Base projeção'!$A$16,Original!G22),0) -> 8 | G22: =ROUND(IF(ISBLANK(Original!H22),'Base projeção'!G22*'Base projeção'!$A$16,Original!H22),0) -> 5 | H22: =ROUND(IF(ISBLANK(Original!I22),'Base projeção'!H22*'Base projeção'!$A$16,Original!I22),0) -> 7 | I22: =ROUND(IF(ISBLANK(Original!J22),'Base projeção'!I22*'Base projeção'!$A$16,Original!J22),0) -> 7 | J22: =ROUND(IF(ISBLANK(Original!K22),'Base projeção'!J22*'Base projeção'!$A$16,Original!K22),0) -> 3 | ... P22: =ROUND(IF(ISBLANK(Original!Q22),'Base projeção'!P22*'Base projeção'!$A$16,Original!Q22),0) -> 18 | Q22: =SUM(C22:P22) -> 112 | R22: =Q22/$Q$15 -> 0.14070352
B23: Caronas | C23: =ROUND(IF(ISBLANK(Original!D23),'Base projeção'!C23*'Base projeção'!$A$16,Original!D23),0) -> 0 | D23: =ROUND(IF(ISBLANK(Original!E23),'Base projeção'!D23*'Base projeção'!$A$16,Original!E23),0) -> 3 | E23: =ROUND(IF(ISBLANK(Original!F23),'Base projeção'!E23*'Base projeção'!$A$16,Original!F23),0) -> 0 | F23: =ROUND(IF(ISBLANK(Original!G23),'Base projeção'!F23*'Base projeção'!$A$16,Original!G23),0) -> 0 | G23: =ROUND(IF(ISBLANK(Original!H23),'Base projeção'!G23*'Base projeção'!$A$16,Original!H23),0) -> 1 | H23: =ROUND(IF(ISBLANK(Original!I23),'Base projeção'!H23*'Base projeção'!$A$16,Original!I23),0) -> 2 | I23: =ROUND(IF(ISBLANK(Original!J23),'Base projeção'!I23*'Base projeção'!$A$16,Original!J23),0) -> 2 | J23: =ROUND(IF(ISBLANK(Original!K23),'Base projeção'!J23*'Base projeção'!$A$16,Original!K23),0) -> 2 | ... P23: =ROUND(IF(ISBLANK(Original!Q23),'Base projeção'!P23*'Base projeção'!$A$16,Original!Q23),0) -> 2 | Q23: =SUM(C23:P23) -> 18 | R23: =Q23/$Q$15 -> 0.022613065
B24: Cargueiras | C24: =ROUND(IF(ISBLANK(Original!D24),'Base projeção'!C24*'Base projeção'!$A$16,Original!D24),0) -> 7 | D24: =ROUND(IF(ISBLANK(Original!E24),'Base projeção'!D24*'Base projeção'!$A$16,Original!E24),0) -> 7 | E24: =ROUND(IF(ISBLANK(Original!F24),'Base projeção'!E24*'Base projeção'!$A$16,Original!F24),0) -> 3 | F24: =ROUND(IF(ISBLANK(Original!G24),'Base projeção'!F24*'Base projeção'!$A$16,Original!G24),0) -> 7 | G24: =ROUND(IF(ISBLANK(Original!H24),'Base projeção'!G24*'Base projeção'!$A$16,Original!H24),0) -> 0 | H24: =ROUND(IF(ISBLANK(Original!I24),'Base projeção'!H24*'Base projeção'!$A$16,Original!I24),0) -> 0 | I24: =ROUND(IF(ISBLANK(Original!J24),'Base projeção'!I24*'Base projeção'!$A$16,Original!J24),0) -> 0 | J24: =ROUND(IF(ISBLANK(Original!K24),'Base projeção'!J24*'Base projeção'!$A$16,Original!K24),0) -> 0 | ... P24: =ROUND(IF(ISBLANK(Original!Q24),'Base projeção'!P24*'Base projeção'!$A$16,Original!Q24),0) -> 0 | Q24: =SUM(C24:P24) -> 25 | R24: =Q24/$Q$15 -> 0.031407035
B25: Serviço | C25: =ROUND(IF(ISBLANK(Original!D25),'Base projeção'!C25*'Base projeção'!$A$16,Original!D25),0) -> 1 | D25: =ROUND(IF(ISBLANK(Original!E25),'Base projeção'!D25*'Base projeção'!$A$16,Original!E25),0) -> 2 | E25: =ROUND(IF(ISBLANK(Original!F25),'Base projeção'!E25*'Base projeção'!$A$16,Original!F25),0) -> 4 | F25: =ROUND(IF(ISBLANK(Original!G25),'Base projeção'!F25*'Base projeção'!$A$16,Original!G25),0) -> 4 | G25: =ROUND(IF(ISBLANK(Original!H25),'Base projeção'!G25*'Base projeção'!$A$16,Original!H25),0) -> 0 | H25: =ROUND(IF(ISBLANK(Original!I25),'Base projeção'!H25*'Base projeção'!$A$16,Original!I25),0) -> 0 | I25: =ROUND(IF(ISBLANK(Original!J25),'Base projeção'!I25*'Base projeção'!$A$16,Original!J25),0) -> 0 | J25: =ROUND(IF(ISBLANK(Original!K25),'Base projeção'!J25*'Base projeção'!$A$16,Original!K25),0) -> 1 | ... P25: =ROUND(IF(ISBLANK(Original!Q25),'Base projeção'!P25*'Base projeção'!$A$16,Original!Q25),0) -> 0 | Q25: =SUM(C25:P25) -> 13 | R25: =Q25/$Q$15 -> 0.016331658
B26: Contramão | C26: =ROUND(IF(ISBLANK(Original!D26),'Base projeção'!C26*'Base projeção'!$A$16,Original!D26),0) -> 7 | D26: =ROUND(IF(ISBLANK(Original!E26),'Base projeção'!D26*'Base projeção'!$A$16,Original!E26),0) -> 1 | E26: =ROUND(IF(ISBLANK(Original!F26),'Base projeção'!E26*'Base projeção'!$A$16,Original!F26),0) -> 6 | F26: =ROUND(IF(ISBLANK(Original!G26),'Base projeção'!F26*'Base projeção'!$A$16,Original!G26),0) -> 3 | G26: =ROUND(IF(ISBLANK(Original!H26),'Base projeção'!G26*'Base projeção'!$A$16,Original!H26),0) -> 4 | H26: =ROUND(IF(ISBLANK(Original!I26),'Base projeção'!H26*'Base projeção'!$A$16,Original!I26),0) -> 3 | I26: =ROUND(IF(ISBLANK(Original!J26),'Base projeção'!I26*'Base projeção'!$A$16,Original!J26),0) -> 2 | J26: =ROUND(IF(ISBLANK(Original!K26),'Base projeção'!J26*'Base projeção'!$A$16,Original!K26),0) -> 1 | ... P26: =ROUND(IF(ISBLANK(Original!Q26),'Base projeção'!P26*'Base projeção'!$A$16,Original!Q26),0) -> 1 | Q26: =SUM(C26:P26) -> 40 | R26: =Q26/$Q$15 -> 0.050251256
B27: Calçada | C27: =ROUND(IF(ISBLANK(Original!D27),'Base projeção'!C27*'Base projeção'!$A$16,Original!D27),0) -> 20 | D27: =ROUND(IF(ISBLANK(Original!E27),'Base projeção'!D27*'Base projeção'!$A$16,Original!E27),0) -> 37 | E27: =ROUND(IF(ISBLANK(Original!F27),'Base projeção'!E27*'Base projeção'!$A$16,Original!F27),0) -> 30 | F27: =ROUND(IF(ISBLANK(Original!G27),'Base projeção'!F27*'Base projeção'!$A$16,Original!G27),0) -> 15 | G27: =ROUND(IF(ISBLANK(Original!H27),'Base projeção'!G27*'Base projeção'!$A$16,Original!H27),0) -> 4 | H27: =ROUND(IF(ISBLANK(Original!I27),'Base projeção'!H27*'Base projeção'!$A$16,Original!I27),0) -> 4 | I27: =ROUND(IF(ISBLANK(Original!J27),'Base projeção'!I27*'Base projeção'!$A$16,Original!J27),0) -> 3 | J27: =ROUND(IF(ISBLANK(Original!K27),'Base projeção'!J27*'Base projeção'!$A$16,Original!K27),0) -> 1 | ... P27: =ROUND(IF(ISBLANK(Original!Q27),'Base projeção'!P27*'Base projeção'!$A$16,Original!Q27),0) -> 2 | Q27: =SUM(C27:P27) -> 125 | R27: =Q27/$Q$15 -> 0.15703518
A29: Dados qualitativos das observações
B30: Característica | C30: 6 | D30: 7 | E30: 8 | F30: 9 | G30: 10 | H30: 11 | I30: 12 | J30: 13 | K30: 14 | L30: 15 | M30: 16 | N30: 17 | O30: 18 | P30: 19 | Q30: TOTAL | R30: %
B31: Carona criança | C31: =ROUND(IF(ISBLANK(Original!D31),'Base projeção'!C23*'Base projeção'!$A$16,Original!D31),0) -> 0 | D31: =ROUND(IF(ISBLANK(Original!E31),'Base projeção'!D23*'Base projeção'!$A$16,Original!E31),0) -> 2 | E31: =ROUND(IF(ISBLANK(Original!F31),'Base projeção'!E23*'Base projeção'!$A$16,Original!F31),0) -> 0 | F31: =ROUND(IF(ISBLANK(Original!G31),'Base projeção'!F23*'Base projeção'!$A$16,Original!G31),0) -> 0 | G31: =ROUND(IF(ISBLANK(Original!H31),'Base projeção'!G23*'Base projeção'!$A$16,Original!H31),0) -> 1 | H31: =ROUND(IF(ISBLANK(Original!I31),'Base projeção'!H23*'Base projeção'!$A$16,Original!I31),0) -> 2 | I31: =ROUND(IF(ISBLANK(Original!J31),'Base projeção'!I23*'Base projeção'!$A$16,Original!J31),0) -> 2 | J31: =ROUND(IF(ISBLANK(Original!K31),'Base projeção'!J23*'Base projeção'!$A$16,Original!K31),0) -> 2 | ... P31: =ROUND(IF(ISBLANK(Original!Q31),'Base projeção'!P23*'Base projeção'!$A$16,Original!Q31),0) -> 2 | Q31: =SUM(C31:P31) -> 17 | R31: =Q31/$Q$15 -> 0.021356784
B32: Carona mulher | C32: =ROUND(IF(ISBLANK(Original!D32),'Base projeção'!C24*'Base projeção'!$A$16,Original!D32),0) -> 0 | D32: =ROUND(IF(ISBLANK(Original!E32),'Base projeção'!D24*'Base projeção'!$A$16,Original!E32),0) -> 1 | E32: =ROUND(IF(ISBLANK(Original!F32),'Base projeção'!E24*'Base projeção'!$A$16,Original!F32),0) -> 0 | F32: =ROUND(IF(ISBLANK(Original!G32),'Base projeção'!F24*'Base projeção'!$A$16,Original!G32),0) -> 0 | G32: =ROUND(IF(ISBLANK(Original!H32),'Base projeção'!G24*'Base projeção'!$A$16,Original!H32),0) -> 0 | H32: =ROUND(IF(ISBLANK(Original!I32),'Base projeção'!H24*'Base projeção'!$A$16,Original!I32),0) -> 0 | I32: =ROUND(IF(ISBLANK(Original!J32),'Base projeção'!I24*'Base projeção'!$A$16,Original!J32),0) -> 0 | J32: =ROUND(IF(ISBLANK(Original!K32),'Base projeção'!J24*'Base projeção'!$A$16,Original!K32),0) -> 0 | ... P32: =ROUND(IF(ISBLANK(Original!Q32),'Base projeção'!P24*'Base projeção'!$A$16,Original!Q32),0) -> 0 | Q32: =SUM(C32:P32) -> 2 | R32: =Q32/$Q$15 -> 0.0025125628
B33: Carona homem | C33: =ROUND(IF(ISBLANK(Original!D33),'Base projeção'!C25*'Base projeção'!$A$16,Original!D33),0) -> 0 | D33: =ROUND(IF(ISBLANK(Original!E33),'Base projeção'!D25*'Base projeção'!$A$16,Original!E33),0) -> 0 | E33: =ROUND(IF(ISBLANK(Original!F33),'Base projeção'!E25*'Base projeção'!$A$16,Original!F33),0) -> 0 | F33: =ROUND(IF(ISBLANK(Original!G33),'Base projeção'!F25*'Base projeção'!$A$16,Original!G33),0) -> 0 | G33: =ROUND(IF(ISBLANK(Original!H33),'Base projeção'!G25*'Base projeção'!$A$16,Original!H33),0) -> 0 | H33: =ROUND(IF(ISBLANK(Original!I33),'Base projeção'!H25*'Base projeção'!$A$16,Original!I33),0) -> 0 | I33: =ROUND(IF(ISBLANK(Original!J33),'Base projeção'!I25*'Base projeção'!$A$16,Original!J33),0) -> 0 | J33: =ROUND(IF(ISBLANK(Original!K33),'Base projeção'!J25*'Base projeção'!$A$16,Original!K33),0) -> 1 | ... P33: =ROUND(IF(ISBLANK(Original!Q33),'Base projeção'!P25*'Base projeção'!$A$16,Original!Q33),0) -> 0 | Q33: =SUM(C33:P33) -> 2 | R33: =Q33/$Q$15 -> 0.0025125628
B34: Cargueira | C34: 1 | D34: 3 | E34: 2 | F34: 5 | Q34: =SUM(C34:P34) -> 11 | R34: =Q34/$Q$15 -> 0.013819095
B35: Adaptada a carga | C35: 6 | D35: 4 | E35: 1 | F35: 2
B36: Serviço | C36: 1 | D36: 2 | E36: 4 | F36: 3 | Q36: =SUM(C36:P36) -> 10 | R36: =Q36/$Q$15 -> 0.012562814
B37: Serviço App | C37: 0 | D37: 0 | E37: 0 | F37: 1
B38: Contramao | C38: 7 | D38: 1 | E38: 6 | F38: 3 | Q38: =SUM(C38:P38) -> 17 | R38: =Q38/$Q$15 -> 0.021356784
B39: Contramão para conversão | C39: 0 | D39: 0 | E39: 0 | F39: 0 | Q39: =SUM(C39:P39) -> 0 | R39: =Q39/$Q$15 -> 0
B40: Bike PE | C40: 2 | D40: 4 | E40: 10 | F40: 2 | Q40: =SUM(C40:P40) -> 18 | R40: =Q40/$Q$15 -> 0.022613065
B41: Triciclo | Q41: =SUM(C41:P41) -> 0 | R41: =Q41/$Q$15 -> 0
B42: Eletrica | Q42: =SUM(C42:P42) -> 0 | R42: =Q42/$Q$15 -> 0
...

Sheet Original
A1: Dados quantitativos e sentido de deslocamento
A2: ORIGEM | B2: DESTINO | C2: 5 | D2: 6 | E2: 7 | F2: 8 | G2: 9 | H2: 10 | I2: 11 | J2: 12 | K2: 13 | L2: 14 | M2: 15 | N2: 16 | O2: 17 | P2: 18 | Q2: 19 | R2: TOTAL | S2: %
A3: Jaqueira | R3: =SUM(C3:Q3) -> 0 | S3: =R3/$R$15 -> 0
A4: Jaqueira | B4: Graças | C4: 42 | D4: 69 | E4: 51 | F4: 59 | G4: 49 | R4: =SUM(C4:Q4) -> 270 | S4: =R4/$R$15 -> 0.71428571
A5: Jaqueira | B5: Rosarinho | C5: 0 | D5: 4 | E5: 2 | F5: 4 | G5: 1 | R5: =SUM(C5:Q5) -> 11 | S5: =R5/$R$15 -> 0.029100529
A6: Rosarinho | B6: Jaqueira | C6: 1 | D6: 2 | E6: 2 | F6: 2 | G6: 2 | R6: =SUM(C6:Q6) -> 9 | S6: =R6/$R$15 -> 0.023809524
R7: =SUM(C7:Q7) -> 0 | S7: =R7/$R$15 -> 0
A8: Rosarinho | B8: Graças | C8: 5 | D8: 11 | E8: 10 | F8: 14 | G8: 6 | R8: =SUM(C8:Q8) -> 46 | S8: =R8/$R$15 -> 0.12169312
A9: Graças | B9: Rosarinho | C9: 2 | D9: 4 | E9: 2 | F9: 9 | G9: 4 | R9: =SUM(C9:Q9) -> 21 | S9: =R9/$R$15 -> 0.055555556
A10: Graças | B10: Jaqueira | C10: 3 | D10: 12 | E10: 2 | F10: 3 | G10: 1 | R10: =SUM(C10:Q10) -> 21 | S10: =R10/$R$15 -> 0.055555556
R11: =SUM(C11:Q11) -> 0 | S11: =R11/$R$15 -> 0
R12: =SUM(C12:Q12) -> 0 | S12: =R12/$R$15 -> 0
R13: =SUM(C13:Q13) -> 0 | S13: =R13/$R$15 -> 0
R14: =SUM(C14:Q14) -> 0 | S14: =R14/$R$15 -> 0
B15: TOTAL | C15: =SUM(C$3:C$14) -> 53 | D15: =SUM(D$3:D$14) -> 102 | E15: =SUM(E$3:E$14) -> 69 | F15: =SUM(F$3:F$14) -> 91 | G15: =SUM(G$3:G$14) -> 63 | H15: =SUM(H$3:H$14) -> 0 | I15: =SUM(I$3:I$14) -> 0 | J15: =SUM(J$3:J$14) -> 0 | ... R15: =SUM(R$3:R$14) -> 378
B16: Percentual | C16: =C15/$R$15 -> 0.14021164 | D16: =D15/$R$15 -> 0.26984127 | E16: =E15/$R$15 -> 0.18253968 | F16: =F15/$R$15 -> 0.24074074 | G16: =G15/$R$15 -> 0.16666667 | H16: =H15/$R$15 -> 0 | I16: =I15/$R$15 -> 0 | J16: =J15/$R$15 -> 0 | ... Q16: =Q15/$R$15 -> 0 | R16: =SUM(C16:Q16) -> 1
A18: Dados qualitativos padrões
B19: Característica | C19: 5 | D19: 6 | E19: 7 | F19: 8 | G19: 9 | H19: 10 | I19: 11 | J19: 12 | K19: 13 | L19: 14 | M19: 15 | N19: 16 | O19: 17 | P19: 18 | Q19: 19 | R19: TOTAL | S19: %
B20: Mulher | C20: 3 | D20: 5 | E20: 3 | F20: 8 | G20: 4 | R20: =SUM(C20:Q20) -> 23 | S20: =R20/$R$15 -> 0.060846561
B21: Crianças e adolescentes | C21: 0 | D21: 4 | E21: 1 | F21: 0 | G21: 0 | R21: =SUM(C21:Q21) -> 5 | S21: =R21/$R$15 -> 0.013227513
B22: Capacete | C22: 9 | D22: 5 | E22: 10 | F22: 7 | G22: 8 | R22: =SUM(C22:Q22) -> 39 | S22: =R22/$R$15 -> 0.1031746
B23: Caronas | C23: =SUM(C31:C33) -> 2 | D23: =SUM(D31:D33) -> 0 | E23: =SUM(E31:E33) -> 3 | F23: =SUM(F31:F33) -> 0 | G23: =SUM(G31:G33) -> 0
B24: Cargueiras | C24: =SUM(C34:C35) -> 4 | D24: =SUM(D34:D35) -> 7 | E24: =SUM(E34:E35) -> 7 | F24: =SUM(F34:F35) -> 3 | G24: =SUM(G34:G35) -> 7
B25: Serviço | C25: =SUM(C36:C37) -> 0 | D25: =SUM(D36:D37) -> 1 | E25: =SUM(E36:E37) -> 2 | F25: =SUM(F36:F37) -> 4 | G25: =SUM(G36:G37) -> 4
B26: Contramão | C26: =SUM(C38:C39) -> 4 | D26: =SUM(D38:D39) -> 7 | E26: =SUM(E38:E39) -> 1 | F26: =SUM(F38:F39) -> 6 | G26: =SUM(G38:G39) -> 3
B27: Calçada | C27: 3 | D27: 20 | E27: 37 | F27: 30 | G27: 15 | R27: =SUM(C27:Q27) -> 105 | S27: =R27/$R$15 -> 0.27777778
A29: Dados qualitativos das observações
B30: Característica | C30: 5 | D30: 6 | E30: 7 | F30: 8 | G30: 9 | H30: 10 | I30: 11 | J30: 12 | K30: 13 | L30: 14 | M30: 15 | N30: 16 | O30: 17 | P30: 18 | Q30: 19 | R30: TOTAL | S30: %
B31: Carona criança | C31: 0 | D31: 0 | E31: 2 | F31: 0 | G31: 0 | R31: =SUM(C31:Q31) -> 2 | S31: =R31/$R$15 -> 0.0052910053
B32: Carona mulher | C32: 2 | D32: 0 | E32: 1 | F32: 0 | G32: 0 | R32: =SUM(C32:Q32) -> 3 | S32: =R32/$R$15 -> 0.0079365079
B33: Carona homem | C33: 0 | D33: 0 | E33: 0 | F33: 0 | G33: 0 | R33: =SUM(C33:Q33) -> 0 | S33: =R33/$R$15 -> 0
B34: Cargueira | C34: 2 | D34: 1 | E34: 3 | F34: 2 | G34: 5 | R34: =SUM(C34:Q34) -> 13 | S34: =R34/$R$15 -> 0.034391534
B35: Adaptada a carga | C35: 2 | D35: 6 | E35: 4 | F35: 1 | G35: 2
B36: Serviço | C36: 0 | D36: 1 | E36: 2 | F36: 4 | G36: 3 | R36: =SUM(C36:Q36) -> 10 | S36: =R36/$R$15 -> 0.026455026
B37: Serviço App | C37: 0 | D37: 0 | E37: 0 | F37: 0 | G37: 1
B38: Contramao | C38: 4 | D38: 7 | E38: 1 | F38: 6 | G38: 3 | R38: =SUM(C38:Q38) -> 21 | S38: =R38/$R$15 -> 0.055555556
B39: Contramão para conversão | C39: 0 | D39: 0 | E39: 0 | F39: 0 | G39: 0 | R39: =SUM(C39:Q39) -> 0 | S39: =R39/$R$15 -> 0
B40: Bike PE | C40: 0 | D40: 2 | E40: 4 | F40: 10 | G40: 2 | R40: =SUM(C40:Q40) -> 18 | S40: =R40/$R$15 -> 0.047619048
B41: Triciclo | R41: =SUM(C41:Q41) -> 0 | S41: =R41/$R$15 -> 0
B42: Eletrica | C42: 1 | R42: =SUM(C42:Q42) -> 1 | S42: =R42/$R$15 -> 0.0026455026
...

Sheet Base projeção
A1: Dados quantitativos e sentido de deslocamento
A2: ORIGEM | B2: DESTINO | C2: 6 | D2: 7 | E2: 8 | F2: 9 | G2: 10 | H2: 11 | I2: 12 | J2: 13 | K2: 14 | L2: 15 | M2: 16 | N2: 17 | O2: 18 | P2: 19 | Q2: TOTAL | R2: %
A3: Jaqueira | Q3: =SUM(C3:P3) -> 0 | R3: =Q3/$Q$15 -> 0
A4: Jaqueira | B4: Graças | C4: 86 | D4: 77 | E4: 100 | F4: 21 | G4: 12 | H4: 22 | I4: 21 | J4: 17 | K4: 23 | L4: 18 | M4: 11 | N4: 37 | O4: 37 | P4: 23 | Q4: =SUM(C4:P4) -> 505 | R4: =Q4/$Q$15 -> 0.63522013
A5: Jaqueira | B5: Rosarinho | C5: 1 | D5: 5 | E5: 3 | F5: 6 | G5: 1 | H5: 4 | I5: 3 | J5: 4 | K5: 1 | L5: 2 | M5: 1 | N5: 2 | O5: 0 | P5: 3 | Q5: =SUM(C5:P5) -> 36 | R5: =Q5/$Q$15 -> 0.045283019
A6: Rosarinho | B6: Jaqueira | C6: 2 | D6: 0 | E6: 1 | F6: 2 | G6: 5 | H6: 0 | I6: 2 | J6: 1 | K6: 1 | L6: 0 | M6: 0 | N6: 5 | O6: 3 | P6: 3 | Q6: =SUM(C6:P6) -> 25 | R6: =Q6/$Q$15 -> 0.031446541
Q7: =SUM(C7:P7) -> 0 | R7: =Q7/$Q$15 -> 0
A8: Rosarinho | B8: Graças | C8: 6 | D8: 9 | E8: 3 | F8: 2 | G8: 9 | H8: 2 | I8: 9 | J8: 1 | K8: 10 | L8: 2 | M8: 9 | N8: 14 | O8: 10 | P8: 5 | Q8: =SUM(C8:P8) -> 91 | R8: =Q8/$Q$15 -> 0.11446541
A9: Graças | B9: Rosarinho | C9: 5 | D9: 0 | E9: 2 | F9: 3 | G9: 0 | H9: 3 | I9: 3 | J9: 2 | K9: 1 | L9: 1 | M9: 2 | N9: 3 | O9: 3 | P9: 2 | Q9: =SUM(C9:P9) -> 30 | R9: =Q9/$Q$15 -> 0.037735849
A10: Graças | B10: Jaqueira | C10: 6 | D10: 5 | E10: 6 | F10: 2 | G10: 5 | H10: 4 | I10: 10 | J10: 3 | K10: 8 | L10: 4 | M10: 10 | N10: 17 | O10: 11 | P10: 17 | Q10: =SUM(C10:P10) -> 108 | R10: =Q10/$Q$15 -> 0.13584906
Q11: =SUM(C11:P11) -> 0 | R11: =Q11/$Q$15 -> 0
Q12: =SUM(C12:P12) -> 0 | R12: =Q12/$Q$15 -> 0
Q13: =SUM(C13:P13) -> 0 | R13: =Q13/$Q$15 -> 0
Q14: =SUM(C14:P14) -> 0 | R14: =Q14/$Q$15 -> 0
A15: AUMENTO | B15: TOTAL | C15: =SUM(C$3:C$14) -> 106 | D15: =SUM(D$3:D$14) -> 96 | E15: =SUM(E$3:E$14) -> 115 | F15: =SUM(F$3:F$14) -> 36 | G15: =SUM(G$3:G$14) -> 32 | H15: =SUM(H$3:H$14) -> 35 | I15: =SUM(I$3:I$14) -> 48 | J15: =SUM(J$3:J$14) -> 28 | ... Q15: =SUM(Q$3:Q$14) -> 795
A16: =Original!R15/SUM(C15:F15) -> 1.0708215 | B16: Percentual | C16: =C15/$Q$15 -> 0.13333333 | D16: =D15/$Q$15 -> 0.12075472 | E16: =E15/$Q$15 -> 0.14465409 | F16: =F15/$Q$15 -> 0.045283019 | G16: =G15/$Q$15 -> 0.040251572 | H16: =H15/$Q$15 -> 0.044025157 | I16: =I15/$Q$15 -> 0.060377358 | J16: =J15/$Q$15 -> 0.035220126 | ... P16: =P15/$Q$15 -> 0.066666667 | Q16: =SUM(C16:P16) -> 1
A18: Dados qualitativos padrões
B19: Característica | C19: 6 | D19: 7 | E19: 8 | F19: 9 | G19: 10 | H19: 11 | I19: 12 | J19: 13 | K19: 14 | L19: 15 | M19: 16 | N19: 17 | O19: 18 | P19: 19 | Q19: TOTAL | R19: %
B20: Mulher | C20: 5 | D20: 7 | E20: 4 | F20: 0 | G20: 1 | H20: 4 | I20: 1 | J20: 5 | K20: 7 | L20: 1 | M20: 2 | N20: 9 | O20: 2 | P20: 5 | Q20: =SUM(C20:P20) -> 53 | R20: =Q20/$Q$15 -> 0.066666667
B21: Crianças e adolescentes | C21: 4 | D21: 10 | E21: 0 | F21: 0 | G21: 0 | H21: 0 | I21: 9 | J21: 7 | K21: 4 | L21: 6 | M21: 1 | N21: 4 | O21: 2 | P21: 4 | Q21: =SUM(C21:P21) -> 51 | R21: =Q21/$Q$15 -> 0.064150943
B22: Capacete | C22: 14 | D22: 20 | E22: 14 | F22: 6 | G22: 5 | H22: 7 | I22: 7 | J22: 3 | K22: 5 | L22: 4 | M22: 5 | N22: 17 | O22: 9 | P22: 17 | Q22: =SUM(C22:P22) -> 133 | R22: =Q22/$Q$15 -> 0.1672956
B23: Carona criança | C23: 0 | D23: 2 | E23: 1 | F23: 0 | G23: 1 | H23: 2 | I23: 2 | J23: 2 | K23: 1 | L23: 0 | M23: 0 | N23: 5 | O23: 0 | P23: 2 | Q23: =SUM(C23:P23) -> 18 | R23: =Q23/$Q$15 -> 0.022641509
B24: Carona mulher | C24: 0 | D24: 3 | E24: 2 | F24: 1 | G24: 0 | H24: 0 | I24: 0 | J24: 0 | K24: 0 | L24: 1 | M24: 0 | N24: 0 | O24: 0 | P24: 0 | Q24: =SUM(C24:P24) -> 7 | R24: =Q24/$Q$15 -> 0.0088050314
B25: Carona homem | C25: 0 | D25: 2 | E25: 0 | F25: 0 | G25: 0 | H25: 0 | I25: 0 | J25: 1 | K25: 0 | L25: 0 | M25: 1 | N25: 0 | O25: 0 | P25: 0 | Q25: =SUM(C25:P25) -> 4 | R25: =Q25/$Q$15 -> 0.0050314465
B26: Cargueira | C26: 3 | D26: 2 | E26: 4 | F26: 5 | G26: 4 | H26: 3 | I26: 2 | J26: 1 | K26: 2 | L26: 6 | M26: 2 | N26: 2 | O26: 0 | P26: 1 | Q26: =SUM(C26:P26) -> 37 | R26: =Q26/$Q$15 -> 0.04654088
B27: Adaptada a carga | C27: 5 | D27: 2 | E27: 1 | F27: 2 | G27: 4 | H27: 4 | I27: 3 | J27: 1 | K27: 2 | L27: 0 | M27: 2 | N27: 4 | O27: 1 | P27: 2
B28: Serviço | C28: 3 | D28: 7 | E28: 1 | F28: 1 | G28: 4 | H28: 0 | I28: 2 | J28: 3 | K28: 3 | L28: 6 | M28: 4 | N28: 2 | O28: 0 | P28: 1 | Q28: =SUM(C28:P28) -> 37 | R28: =Q28/$Q$15 -> 0.04654088
B29: Serviço App
B30: Contramao | C30: 17 | D30: 7 | E30: 8 | F30: 14 | G30: 10 | H30: 7 | I30: 9 | J30: 7 | K30: 9 | L30: 5 | M30: 6 | N30: 20 | O30: 18 | P30: 22 | Q30: =SUM(C30:P30) -> 159 | R30: =Q30/$Q$15 -> 0.2
B31: Contramão para conversão | C31: 0 | D31: 7 | E31: 0 | F31: 0 | G31: 0 | H31: 0 | I31: 0 | J31: 0 | K31: 0 | L31: 0 | M31: 0 | N31: 0 | O31: 0 | P31: 0 | Q31: =SUM(C31:P31) -> 7 | R31: =Q31/$Q$15 -> 0.0088050314
B32: Calçada | C32: 14 | D32: 18 | E32: 14 | F32: 7 | G32: 1 | H32: 4 | I32: 4 | J32: 8 | K32: 3 | L32: 3 | M32: 4 | N32: 9 | O32: 13 | P32: 17 | Q32: =SUM(C32:P32) -> 119 | R32: =Q32/$Q$15 -> 0.14968553
A34: Dados qualitativos das observações
B35: Característica | C35: 6 | D35: 7 | E35: 8 | F35: 9 | G35: 10 | H35: 11 | I35: 12 | J35: 13 | K35: 14 | L35: 15 | M35: 16 | N35: 17 | O35: 18 | P35: 19 | Q35: TOTAL | R35: %
B36: Bike PE | C36: 0 | D36: 0 | E36: 1 | F36: 0 | G36: 0 | H36: 0 | I36: 1 | J36: 0 | K36: 0 | L36: 0 | M36: 0 | N36: 1 | O36: 1 | P36: 1 | Q36: =SUM(C36:P36) -> 5 | R36: =Q36/$Q$15 -> 0.0062893082
B37: Triciclo | C37: 0 | D37: 0 | E37: 0 | F37: 0 | G37: 0 | H37: 0 | I37: 0 | J37: 0 | K37: 0 | L37: 0 | M37: 0 | N37: 0 | O37: 0 | P37: 1 | Q37: =SUM(C37:P37) -> 1 | R37: =Q37/$Q$15 -> 0.0012578616
B38: Eletrica | C38: 1 | D38: 0 | E38: 0 | F38: 1 | G38: 0 | H38: 1 | I38: 0 | J38: 0 | K38: 0 | L38: 0 | M38: 0 | N38: 0 | O38: 0 | P38: 0 | Q38: =SUM(C38:P38) -> 3 | R38: =Q38/$Q$15 -> 0.0037735849
B39: Skate | C39: 0 | D39: 0 | E39: 0 | F39: 0 | G39: 0 | H39: 0 | I39: 0 | J39: 0 | K39: 0 | L39: 0 | M39: 0 | N39: 0 | O39: 0 | P39: 0 | Q39: =SUM(C39:P39) -> 0 | R39: =Q39/$Q$15 -> 0
B40: Grupos de pedal | C40: 0 | D40: 0 | E40: 0 | F40: 0 | G40: 0 | H40: 0 | I40: 0 | J40: 0 | K40: 0 | L40: 0 | M40: 0 | N40: 0 | O40: 0 | P40: 0 | Q40: =SUM(C40:P40) -> 0 | R40: =Q40/$Q$15 -> 0
B41: Faixa Azul | Q41: =SUM(C41:P41) -> 0 | R41: =Q41/$Q$15 -> 0
B42: Empurrando | Q42: =SUM(C42:P42) -> 0 | R42: =Q42/$Q$15 -> 0

Sheet Gráficos
A1: Ciclistas por hora
A2: Horário início | B2: =#REF! -> #REF! | C2: =Dados!C2 -> 6 | D2: =Dados!D2 -> 7 | E2: =Dados!E2 -> 8 | F2: =Dados!F2 -> 9 | G2: =Dados!G2 -> 10 | H2: =Dados!H2 -> 11 | I2: =Dados!I2 -> 12 | J2: =Dados!J2 -> 13 | ... N2: =Dados!N2 -> 17 | O2: =Dados!P2 -> 19
A3: Homens | B3: =#REF!-B4-B5 -> #REF! | C3: =Dados!C15-C4-C5 -> 92 | D3: =Dados!D15-D4-D5 -> 56 | E3: =Dados!E15-E4-E5 -> 76 | F3: =Dados!F15-F4-F5 -> 51 | G3: =Dados!G15-G4-G5 -> 28 | H3: =Dados!H15-H4-H5 -> 26 | I3: =Dados!I15-I4-I5 -> 43 | J3: =Dados!J15-J4-J5 -> 21 | ... N3: =Dados!N15-N4-N5 -> 55 | O3: =Dados!P15-O4-O5 -> 33
A4: Mulheres | B4: =#REF! -> #REF! | C4: =Dados!C20 -> 5 | D4: =Dados!D20 -> 3 | E4: =Dados!E20 -> 8 | F4: =Dados!F20 -> 4 | G4: =Dados!G20 -> 1 | H4: =Dados!H20 -> 4 | I4: =Dados!I20 -> 1 | J4: =Dados!J20 -> 5 | ... N4: =Dados!N20 -> 10 | O4: =Dados!P20 -> 5
A5: Crianças e adolescentes | B5: =#REF! -> #REF! | C5: =Dados!C22 -> 5 | D5: =Dados!D22 -> 10 | E5: =Dados!E22 -> 7 | F5: =Dados!F22 -> 8 | G5: =Dados!G22 -> 5 | H5: =Dados!H22 -> 7 | I5: =Dados!I22 -> 7 | J5: =Dados!J22 -> 3 | ... N5: =Dados!N22 -> 18 | O5: =Dados!P22 -> 18
A7: Ciclistas por hora %
A8: Horário | B8: 6 | C8: 7 | D8: 8 | E8: 9 | F8: 10 | G8: 11 | H8: 12 | I8: 13 | J8: 14 | K8: 15 | L8: 16 | M8: 17 | N8: 18 | O8: 19
A9: Mulheres | B9: =B4/#REF! -> #REF! | C9: =C4/Dados!C$15 -> 0.049019608 | D9: =D4/Dados!D$15 -> 0.043478261 | E9: =E4/Dados!E$15 -> 0.087912088 | F9: =F4/Dados!F$15 -> 0.063492063 | G9: =G4/Dados!G$15 -> 0.029411765 | H9: =H4/Dados!H$15 -> 0.10810811 | I9: =I4/Dados!I$15 -> 0.019607843 | J9: =J4/Dados!J$15 -> 0.17241379 | ... N9: =N4/Dados!N$15 -> 0.12048193 | O9: =O4/Dados!P$15 -> 0.089285714
A10: Crianças e adolescentes | B10: =B5/#REF! -> #REF! | C10: =C5/Dados!C$15 -> 0.049019608 | D10: =D5/Dados!D$15 -> 0.14492754 | E10: =E5/Dados!E$15 -> 0.076923077 | F10: =F5/Dados!F$15 -> 0.12698413 | G10: =G5/Dados!G$15 -> 0.14705882 | H10: =H5/Dados!H$15 -> 0.18918919 | I10: =I5/Dados!I$15 -> 0.1372549 | J10: =J5/Dados!J$15 -> 0.10344828 | ... N10: =N5/Dados!N$15 -> 0.21686747 | O10: =O5/Dados!P$15 -> 0.32142857
A12: =Dados!B19 -> Característica | B12: =Dados!R19 -> %
A13: =Dados!B20 -> Mulher | B13: =Dados!R20 -> 0.072864322
A14: =Dados!B22 -> Crianças e adolescentes | B14: =Dados!R22 -> 0.14070352
A15: =Dados!B21 -> Capacete | B15: =Dados!R21 -> 0.054020101
A16: Caronas | B16: =SUM(Dados!R31:R33) -> 0.02638191
A17: =Dados!B34 -> Cargueira | B17: =Dados!R34 -> 0.013819095
A18: =Dados!B36 -> Serviço | B18: =Dados!R36 -> 0.012562814
A19: =Dados!B38 -> Contramao | B19: =Dados!R38 -> 0.021356784
A20: =Dados!B27 -> Calçada | B20: =Dados!R27 -> 0.15703518

Sheet CONFFLUXO
A1: =Fluxo!A2 -> TOTAL | F1: 2 | G1: {=TRANSPOSE(Dados!2:2)} -> ORIGEM
F2: 3 | G2: DESTINO
A3: =Dados!A3 -> Jaqueira | B3: =Dados!B3 | F3: 4 | G3: 6 | Q3: =HLOOKUP($A$1,Dados!$C$2:$R$14,F1,0) -> 0
A4: =Dados!A4 -> Jaqueira | B4: =Dados!B4 -> Graças | F4: 5 | G4: 7 | Q4: =HLOOKUP($A$1,Dados!$C$2:$R$14,F2,0) -> 466
A5: =Dados!A5 -> Jaqueira | B5: =Dados!B5 -> Rosarinho | F5: 6 | G5: 8 | Q5: =HLOOKUP($A$1,Dados!$C$2:$R$14,F3,0) -> 32
A6: =Dados!A6 -> Rosarinho | B6: =Dados!B6 -> Jaqueira | F6: 7 | G6: 9 | Q6: =HLOOKUP($A$1,Dados!$C$2:$R$14,F4,0) -> 28
A7: =Dados!A7 -> Rosarinho | B7: =Dados!B7 | F7: 8 | G7: 10 | Q7: =HLOOKUP($A$1,Dados!$C$2:$R$14,F5,0) -> 0
A8: =Dados!A8 -> Rosarinho | B8: =Dados!B8 -> Graças | F8: 9 | G8: 11 | Q8: =HLOOKUP($A$1,Dados!$C$2:$R$14,F6,0) -> 118
A9: =Dados!A9 -> Graças | B9: =Dados!B9 -> Rosarinho | F9: 10 | G9: 12 | Q9: =HLOOKUP($A$1,Dados!$C$2:$R$14,F7,0) -> 39
A10: =Dados!A10 -> Graças | B10: =Dados!B10 -> Jaqueira | F10: 11 | G10: 13 | Q10: =HLOOKUP($A$1,Dados!$C$2:$R$14,F8,0) -> 113
A11: =Dados!A11 -> Graças | B11: =Dados!B11 | F11: 12 | G11: 14 | Q11: =HLOOKUP($A$1,Dados!$C$2:$R$14,F9,0) -> 0
A12: =Dados!A12 -> Torre | B12: =Dados!B12 | F12: 13 | G12: 15 | Q12: =HLOOKUP($A$1,Dados!$C$2:$R$14,F10,0) -> 0
A13: =Dados!A13 -> Torre | B13: =Dados!B13 | G13: 16 | Q13: =HLOOKUP($A$1,Dados!$C$2:$R$14,F11,0) -> 0
A14: =Dados!A14 -> Torre | B14: =Dados!B14 | G14: 17 | Q14: =HLOOKUP($A$1,Dados!$C$2:$R$14,F12,0) -> 0
G15: 18
G16: 19
G17: TOTAL
G18: %

Sheet Fluxo
A1: HORÁRIO | E1: =UPPER(CONFFLUXO!A3) -> JAQUEIRA
A2: TOTAL | E2: =SUM(E3:G3) -> 498
E3: =CONFFLUXO!Q3 -> 0 | F3: =CONFFLUXO!Q4 -> 466 | G3: =CONFFLUXO!Q5 -> 32
A5: =UPPER(CONFFLUXO!A12) -> TORRE | B5: =SUM(C5:C7) -> 0 | C5: =CONFFLUXO!Q14 -> 0 | I5: =CONFFLUXO!Q6 -> 28 | J5: =SUM(I5:I7) -> 146 | K5: =UPPER(CONFFLUXO!A6) -> ROSARINHO
C6: =CONFFLUXO!Q13 -> 0 | F6: =SUM(E3:G3,I5:I7,E9:G9,C5:C7) -> 796 | I6: =CONFFLUXO!Q7 -> 0
C7: =CONFFLUXO!Q12 -> 0 | I7: =CONFFLUXO!Q8 -> 118
E9: =CONFFLUXO!Q11 -> 0 | F9: =CONFFLUXO!Q10 -> 113 | G9: =CONFFLUXO!Q9 -> 39
E10: =SUM(E9:G9) -> 152
E11: =UPPER(CONFFLUXO!A9) -> GRAÇAS | K11: =MAX(3:3,I:I,9:9,C:C) -> 466
