Workbook

Sheet Resumo
A1: Cruzamento | B1: R. Padre Roma x R. Sebastião Malta Arcoverde
A2: Data | B2: 44433
A3: Coordenadas Geográficas | B3: -8.03309, -34.90729
A4: Relatório | B4: https://drive.google.com/file/d/1cL4GE-D72Nz4_kHIn6Zz6IgBqQeZnYgj/view?usp=sharing
A5: Total | B5: =Dados!S15 -> 2257
A6: Máximo em um hora | B6: =MAX(Dados!E15:R15) -> 293
A7: Mulher | B7: =Dados!T20 -> 0.10766504
A8: Crianças e adolescentes | B8: =Dados!T21 -> 0.019494905
A9: Capacete | B9: =Dados!T22 -> 0.10722198
A10: Caronas | B10: =Dados!T23 -> 0.019494905
A11: Cargueiras | B11: =Dados!T24 -> 0.10013292
A12: Serviço | B12: =Dados!T25 -> 0.11785556
A13: Contramão | B13: =Dados!T26 -> 0.036331413
A14: Calçada | B14: =Dados!T27 -> 0.022596367

Sheet Dados
C1: Dados quantitativos e sentido de deslocamento
C2: ORIGEM | D2: DESTINO | E2: 6 | F2: 7 | G2: 8 | H2: 9 | I2: 10 | J2: 11 | K2: 12 | L2: 13 | M2: 14 | N2: 15 | O2: 16 | P2: 17 | Q2: 18 | R2: 19 | S2: TOTAL | T2: %
C3: Rui Barbosa | D3: =C12 -> Jaqueira | E3: 1 | F3: 0 | G3: 2 | H3: 1 | I3: 0 | J3: 0 | K3: 1 | L3: 0 | M3: 0 | N3: 2 | O3: 1 | P3: 1 | Q3: 1 | R3: 0 | S3: =SUM(E3:R3) -> 10 | T3: =S3/$S$15 -> 0.0044306602
C4: =C3 -> Rui Barbosa | D4: =C9 -> Padre Roma | E4: 0 | F4: 0 | G4: 0 | H4: 0 | I4: 0 | J4: 0 | K4: 0 | L4: 0 | M4: 1 | N4: 0 | O4: 0 | P4: 0 | Q4: 0 | R4: 0 | S4: =SUM(E4:R4) -> 1 | T4: =S4/$S$15 -> 0.00044306602
C5: =C3 -> Rui Barbosa | D5: Tamarineira | E5: 1 | F5: 0 | G5: 1 | H5: 0 | I5: 0 | J5: 1 | K5: 0 | L5: 0 | M5: 2 | N5: 2 | O5: 1 | P5: 1 | Q5: 2 | R5: 0 | S5: =SUM(E5:R5) -> 11 | T5: =S5/$S$15 -> 0.0048737262
C6: Parnamirim | D6: =C3 -> Rui Barbosa | E6: 17 | F6: 14 | G6: 12 | H6: 3 | I6: 3 | J6: 10 | K6: 5 | L6: 7 | M6: 13 | N6: 9 | O6: 10 | P6: 12 | Q6: 8 | R6: 5 | S6: =SUM(E6:R6) -> 128 | T6: =S6/$S$15 -> 0.05671245
C7: =C6 -> Parnamirim | D7: =C12 -> Jaqueira | E7: 51 | F7: 82 | G7: 44 | H7: 29 | I7: 16 | J7: 36 | K7: 36 | L7: 22 | M7: 34 | N7: 41 | O7: 48 | P7: 43 | Q7: 60 | R7: 30 | S7: =SUM(E7:R7) -> 572 | T7: =S7/$S$15 -> 0.25343376
C8: =C6 -> Parnamirim | D8: =C9 -> Padre Roma | E8: 2 | F8: 5 | G8: 6 | H8: 2 | I8: 3 | J8: 3 | K8: 0 | L8: 2 | M8: 4 | N8: 2 | O8: 0 | P8: 0 | Q8: 0 | R8: 0 | S8: =SUM(E8:R8) -> 29 | T8: =S8/$S$15 -> 0.012848914
C9: Padre Roma | D9: =C6 -> Parnamirim | E9: 41 | F9: 43 | G9: 29 | H9: 28 | I9: 27 | J9: 27 | K9: 37 | L9: 24 | M9: 34 | N9: 44 | O9: 59 | P9: 82 | Q9: 69 | R9: 49 | S9: =SUM(E9:R9) -> 593 | T9: =S9/$S$15 -> 0.26273815
C10: =C9 -> Padre Roma | D10: =C3 -> Rui Barbosa | E10: 115 | F10: 141 | G10: 65 | H10: 43 | I10: 32 | J10: 20 | K10: 30 | L10: 44 | M10: 33 | N10: 40 | O10: 66 | P10: 45 | Q10: 45 | R10: 30 | S10: =SUM(E10:R10) -> 749 | T10: =S10/$S$15 -> 0.33185645
C11: =C9 -> Padre Roma | D11: =C12 -> Jaqueira | E11: 0 | F11: 0 | G11: 0 | H11: 1 | I11: 1 | J11: 0 | K11: 2 | L11: 0 | M11: 0 | N11: 0 | O11: 0 | P11: 0 | Q11: 0 | R11: 2 | S11: =SUM(E11:R11) -> 6 | T11: =S11/$S$15 -> 0.0026583961
C12: Jaqueira | D12: =C9 -> Padre Roma | E12: 0 | F12: 0 | G12: 6 | H12: 1 | I12: 0 | J12: 0 | K12: 0 | L12: 0 | M12: 0 | N12: 0 | O12: 1 | P12: 0 | Q12: 0 | R12: 0 | S12: =SUM(E12:R12) -> 8 | T12: =S12/$S$15 -> 0.0035445281
C13: =C12 -> Jaqueira | D13: =C6 -> Parnamirim | E13: 3 | F13: 8 | G13: 2 | H13: 5 | I13: 7 | J13: 7 | K13: 14 | L13: 8 | M13: 13 | N13: 10 | O13: 13 | P13: 22 | Q13: 21 | R13: 15 | S13: =SUM(E13:R13) -> 148 | T13: =S13/$S$15 -> 0.06557377
C14: =C12 -> Jaqueira | D14: =C3 -> Rui Barbosa | E14: 0 | F14: 0 | G14: 0 | H14: 0 | I14: 0 | J14: 0 | K14: 0 | L14: 0 | M14: 0 | N14: 1 | O14: 0 | P14: 1 | Q14: 0 | R14: 0 | S14: =SUM(E14:R14) -> 2 | T14: =S14/$S$15 -> 0.00088613203
D15: TOTAL | E15: =SUM(E3:E14) -> 231 | F15: =SUM(F3:F14) -> 293 | G15: =SUM(G3:G14) -> 167 | H15: =SUM(H3:H14) -> 113 | I15: =SUM(I3:I14) -> 89 | J15: =SUM(J3:J14) -> 104 | K15: =SUM(K3:K14) -> 125 | L15: =SUM(L3:L14) -> 107 | ... R15: =SUM(R3:R14) -> 131 | S15: =SUM(S$3:S$14) -> 2257
D16: Percentual | E16: =E15/$S$15 -> 0.10234825 | F16: =F15/$S$15 -> 0.12981834 | G16: =G15/$S$15 -> 0.073992025 | H16: =H15/$S$15 -> 0.05006646 | I16: =I15/$S$15 -> 0.039432875 | J16: =J15/$S$15 -> 0.046078866 | K16: =K15/$S$15 -> 0.055383252 | L16: =L15/$S$15 -> 0.047408064 | ... R16: =R15/$S$15 -> 0.058041648 | S16: =SUM(E16:R16) -> 1
D18: Dados qualitativos padrões
D19: Característica | E19: 6 | F19: 7 | G19: 8 | H19: 9 | I19: 10 | J19: 11 | K19: 12 | L19: 13 | M19: 14 | N19: 15 | O19: 16 | P19: 17 | Q19: 18 | R19: 19 | S19: TOTAL | T19: %
D20: Mulher | E20: 24 | F20: 17 | G20: 31 | H20: 14 | I20: 11 | J20: 10 | K20: 15 | L20: 7 | M20: 12 | N20: 12 | O20: 26 | P20: 20 | Q20: 27 | R20: 17 | S20: =SUM(E20:R20) -> 243 | T20: =S20/$S$15 -> 0.10766504
D21: Crianças e adolescentes | E21: 3 | F21: 3 | G21: 1 | H21: 0 | I21: 4 | J21: 1 | K21: 5 | L21: 5 | M21: 7 | N21: 3 | O21: 1 | P21: 2 | Q21: 8 | R21: 1 | S21: =SUM(E21:R21) -> 44 | T21: =S21/$S$15 -> 0.019494905
D22: Capacete | E22: 19 | F22: 38 | G22: 24 | H22: 13 | I22: 5 | J22: 6 | K22: 14 | L22: 7 | M22: 6 | N22: 6 | O22: 20 | P22: 21 | Q22: 31 | R22: 32 | S22: =SUM(E22:R22) -> 242 | T22: =S22/$S$15 -> 0.10722198
D23: Caronas | E23: =SUM(E32:E34) -> 4 | F23: =SUM(F32:F34) -> 5 | G23: =SUM(G32:G34) -> 3 | H23: =SUM(H32:H34) -> 3 | I23: =SUM(I32:I34) -> 1 | J23: =SUM(J32:J34) -> 1 | K23: =SUM(K32:K34) -> 3 | L23: =SUM(L32:L34) -> 0 | ... R23: =SUM(R32:R34) -> 1 | S23: =SUM(E23:R23) -> 44 | T23: =S23/$S$15 -> 0.019494905
D24: Cargueiras | E24: =SUM(E35:E36) -> 33 | F24: =SUM(F35:F36) -> 25 | G24: =SUM(G35:G36) -> 16 | H24: =SUM(H35:H36) -> 13 | I24: =SUM(I35:I36) -> 12 | J24: =SUM(J35:J36) -> 12 | K24: =SUM(K35:K36) -> 14 | L24: =SUM(L35:L36) -> 10 | ... R24: =SUM(R35:R36) -> 6 | S24: =SUM(E24:R24) -> 226 | T24: =S24/$S$15 -> 0.10013292
D25: Serviço | E25: =SUM(E37:E38) -> 0 | F25: =SUM(F37:F38) -> 5 | G25: =SUM(G37:G38) -> 6 | H25: =SUM(H37:H38) -> 11 | I25: =SUM(I37:I38) -> 16 | J25: =SUM(J37:J38) -> 28 | K25: =SUM(K37:K38) -> 27 | L25: =SUM(L37:L38) -> 28 | ... R25: =SUM(R37:R38) -> 27 | S25: =SUM(E25:R25) -> 266 | T25: =S25/$S$15 -> 0.11785556
D26: Contramão | E26: =SUM(E39:E40) -> 4 | F26: =SUM(F39:F40) -> 5 | G26: =SUM(G39:G40) -> 8 | H26: =SUM(H39:H40) -> 4 | I26: =SUM(I39:I40) -> 1 | J26: =SUM(J39:J40) -> 6 | K26: =SUM(K39:K40) -> 5 | L26: =SUM(L39:L40) -> 7 | ... R26: =SUM(R39:R40) -> 1 | S26: =SUM(E26:R26) -> 82 | T26: =S26/$S$15 -> 0.036331413
D27: Calçada | E27: 3 | F27: 14 | G27: 7 | H27: 2 | I27: 1 | J27: 4 | K27: 3 | L27: 2 | M27: 5 | N27: 0 | O27: 3 | P27: 3 | Q27: 3 | R27: 1 | S27: =SUM(E27:R27) -> 51 | T27: =S27/$S$15 -> 0.022596367
D30: Dados qualitativos das observações
D31: Característica | E31: 6 | F31: 7 | G31: 8 | H31: 9 | I31: 10 | J31: 11 | K31: 12 | L31: 13 | M31: 14 | N31: 15 | O31: 16 | P31: 17 | Q31: 18 | R31: 19 | S31: TOTAL | T31: %
D32: Carona criança | E32: 2 | F32: 1 | G32: 1 | H32: 1 | I32: 1 | J32: 1 | K32: 3 | L32: 0 | M32: 1 | N32: 0 | O32: 2 | P32: 1 | Q32: 3 | R32: 1 | S32: =SUM(E32:R32) -> 18 | T32: =S32/$S$15 -> 0.0079751883
D33: Carona mulher | E33: 2 | F33: 4 | G33: 2 | H33: 2 | I33: 0 | J33: 0 | K33: 0 | L33: 0 | M33: 4 | N33: 4 | O33: 3 | P33: 0 | Q33: 3 | R33: 0 | S33: =SUM(E33:R33) -> 24 | T33: =S33/$S$15 -> 0.010633584
D34: Carona homem | E34: 0 | F34: 0 | G34: 0 | H34: 0 | I34: 0 | J34: 0 | K34: 0 | L34: 0 | M34: 1 | N34: 0 | O34: 1 | P34: 0 | Q34: 0 | R34: 0 | S34: =SUM(E34:R34) -> 2 | T34: =S34/$S$15 -> 0.00088613203
D35: Cargueira tradicional | E35: 13 | F35: 6 | G35: 11 | H35: 8 | I35: 7 | J35: 6 | K35: 7 | L35: 3 | M35: 8 | N35: 10 | O35: 4 | P35: 9 | Q35: 11 | R35: 2 | S35: =SUM(E35:R35) -> 105 | T35: =S35/$S$15 -> 0.046521932
D36: Adaptada a carga | E36: 20 | F36: 19 | G36: 5 | H36: 5 | I36: 5 | J36: 6 | K36: 7 | L36: 7 | M36: 4 | N36: 2 | O36: 14 | P36: 12 | Q36: 11 | R36: 4 | S36: =SUM(E36:R36) -> 121 | T36: =S36/$S$15 -> 0.053610988
D37: Serviço | E37: 0 | F37: 0 | G37: 3 | H37: 4 | I37: 8 | J37: 1 | K37: 7 | L37: 2 | M37: 2 | N37: 5 | O37: 0 | P37: 2 | Q37: 0 | R37: 0 | S37: =SUM(E37:R37) -> 34 | T37: =S37/$S$15 -> 0.015064245
D38: Serviço APP | E38: 0 | F38: 5 | G38: 3 | H38: 7 | I38: 8 | J38: 27 | K38: 20 | L38: 26 | M38: 29 | N38: 27 | O38: 15 | P38: 15 | Q38: 23 | R38: 27 | S38: =SUM(E38:R38) -> 232 | T38: =S38/$S$15 -> 0.10279132
D39: Contramão | E39: 4 | F39: 5 | G39: 8 | H39: 4 | I39: 1 | J39: 5 | K39: 4 | L39: 6 | M39: 8 | N39: 11 | O39: 4 | P39: 3 | Q39: 2 | R39: 1 | S39: =SUM(E39:R39) -> 66 | T39: =S39/$S$15 -> 0.029242357
D40: Contramão para conversão | E40: 0 | F40: 0 | G40: 0 | H40: 0 | I40: 0 | J40: 1 | K40: 1 | L40: 1 | M40: 0 | N40: 0 | O40: 1 | P40: 8 | Q40: 4 | R40: 0 | S40: =SUM(E40:R40) -> 16 | T40: =S40/$S$15 -> 0.0070890563
D41: Bike PE | E41: 4 | F41: 0 | G41: 8 | H41: 1 | I41: 4 | J41: 5 | K41: 9 | L41: 2 | M41: 8 | N41: 3 | O41: 8 | P41: 9 | Q41: 9 | R41: 7 | S41: =SUM(E41:R41) -> 77 | T41: =S41/$S$15 -> 0.034116083
D42: Elétrica | E42: 1 | F42: 0 | G42: 0 | H42: 1 | I42: 0 | J42: 0 | K42: 1 | L42: 2 | M42: 0 | N42: 0 | O42: 1 | P42: 0 | Q42: 1 | R42: 1 | S42: =SUM(E42:R42) -> 8 | T42: =S42/$S$15 -> 0.0035445281
D43: Motorizada | E43: 1 | F43: 0 | G43: 0 | H43: 0 | I43: 0 | J43: 0 | K43: 0 | L43: 1 | M43: 1 | N43: 0 | O43: 0 | P43: 1 | Q43: 0 | R43: 0 | S43: =SUM(E43:R43) -> 4 | T43: =S43/$S$15 -> 0.0017722641
...

Sheet CONFFLUXO
A1: =Fluxo!A2 -> TOTAL | F1: 2 | G1: {=TRANSPOSE(Dados!2:2)}
F2: 3
A3: =Dados!C3 -> Rui Barbosa | B3: =Dados!D3 -> Jaqueira | F3: 4 | G3: ORIGEM | Q3: =HLOOKUP($A$1,Dados!$E$2:$T$14,F1,0) -> 10
A4: =Dados!C4 -> Rui Barbosa | B4: =Dados!D4 -> Padre Roma | F4: 5 | G4: DESTINO | Q4: =HLOOKUP($A$1,Dados!$E$2:$T$14,F2,0) -> 1
A5: =Dados!C5 -> Rui Barbosa | B5: =Dados!D5 -> Tamarineira | F5: 6 | G5: 6 | Q5: =HLOOKUP($A$1,Dados!$E$2:$T$14,F3,0) -> 11
A6: =Dados!C6 -> Parnamirim | B6: =Dados!D6 -> Rui Barbosa | F6: 7 | G6: 7 | Q6: =HLOOKUP($A$1,Dados!$E$2:$T$14,F4,0) -> 128
A7: =Dados!C7 -> Parnamirim | B7: =Dados!D7 -> Jaqueira | F7: 8 | G7: 8 | Q7: =HLOOKUP($A$1,Dados!$E$2:$T$14,F5,0) -> 572
A8: =Dados!C8 -> Parnamirim | B8: =Dados!D8 -> Padre Roma | F8: 9 | G8: 9 | Q8: =HLOOKUP($A$1,Dados!$E$2:$T$14,F6,0) -> 29
A9: =Dados!C9 -> Padre Roma | B9: =Dados!D9 -> Parnamirim | F9: 10 | G9: 10 | Q9: =HLOOKUP($A$1,Dados!$E$2:$T$14,F7,0) -> 593
A10: =Dados!C10 -> Padre Roma | B10: =Dados!D10 -> Rui Barbosa | F10: 11 | G10: 11 | Q10: =HLOOKUP($A$1,Dados!$E$2:$T$14,F8,0) -> 749
A11: =Dados!C11 -> Padre Roma | B11: =Dados!D11 -> Jaqueira | F11: 12 | G11: 12 | Q11: =HLOOKUP($A$1,Dados!$E$2:$T$14,F9,0) -> 6
A12: =Dados!C12 -> Jaqueira | B12: =Dados!D12 -> Padre Roma | F12: 13 | G12: 13 | Q12: =HLOOKUP($A$1,Dados!$E$2:$T$14,F10,0) -> 8
A13: =Dados!C13 -> Jaqueira | B13: =Dados!D13 -> Parnamirim | G13: 14 | Q13: =HLOOKUP($A$1,Dados!$E$2:$T$14,F11,0) -> 148
A14: =Dados!C14 -> Jaqueira | B14: =Dados!D14 -> Rui Barbosa | G14: 15 | Q14: =HLOOKUP($A$1,Dados!$E$2:$T$14,F12,0) -> 2
G15: 16
G16: 17
G17: 18
G18: 19

Sheet Gráficos
A1: Ciclistas por hora
A2: Horário início | B2: =Dados!E2 -> 6 | C2: =Dados!F2 -> 7 | D2: =Dados!G2 -> 8 | E2: =Dados!H2 -> 9 | F2: =Dados!I2 -> 10 | G2: =Dados!J2 -> 11 | H2: =Dados!K2 -> 12 | I2: =Dados!L2 -> 13 | ... O2: =Dados!R2 -> 19
A3: Homens | B3: =Dados!E15-B4-B5 -> 204 | C3: =Dados!F15-C4-C5 -> 273 | D3: =Dados!G15-D4-D5 -> 135 | E3: =Dados!H15-E4-E5 -> 99 | F3: =Dados!I15-F4-F5 -> 74 | G3: =Dados!J15-G4-G5 -> 93 | H3: =Dados!K15-H4-H5 -> 105 | I3: =Dados!L15-I4-I5 -> 95 | ... O3: =Dados!R15-O4-O5 -> 113
A4: Mulheres | B4: =Dados!E20 -> 24 | C4: =Dados!F20 -> 17 | D4: =Dados!G20 -> 31 | E4: =Dados!H20 -> 14 | F4: =Dados!I20 -> 11 | G4: =Dados!J20 -> 10 | H4: =Dados!K20 -> 15 | I4: =Dados!L20 -> 7 | ... O4: =Dados!R20 -> 17
A5: Crianças e adolescentes | B5: =Dados!E21 -> 3 | C5: =Dados!F21 -> 3 | D5: =Dados!G21 -> 1 | E5: =Dados!H21 -> 0 | F5: =Dados!I21 -> 4 | G5: =Dados!J21 -> 1 | H5: =Dados!K21 -> 5 | I5: =Dados!L21 -> 5 | ... O5: =Dados!R21 -> 1
A7: Ciclistas por hora %
A8: Horário | B8: 6 | C8: 7 | D8: 8 | E8: 9 | F8: 10 | G8: 11 | H8: 12 | I8: 13 | J8: 14 | K8: 15 | L8: 16 | M8: 17 | N8: 18 | O8: 19
A9: Mulheres | B9: =B4/Dados!E$15 -> 0.1038961 | C9: =C4/Dados!F$15 -> 0.058020478 | D9: =D4/Dados!G$15 -> 0.18562874 | E9: =E4/Dados!H$15 -> 0.12389381 | F9: =F4/Dados!I$15 -> 0.12359551 | G9: =G4/Dados!J$15 -> 0.096153846 | H9: =H4/Dados!K$15 -> 0.12 | I9: =I4/Dados!L$15 -> 0.065420561 | ... O9: =O4/Dados!R$15 -> 0.12977099
A10: Crianças e adolescentes | B10: =B5/Dados!E$15 -> 0.012987013 | C10: =C5/Dados!F$15 -> 0.010238908 | D10: =D5/Dados!G$15 -> 0.005988024 | E10: =E5/Dados!H$15 -> 0 | F10: =F5/Dados!I$15 -> 0.04494382 | G10: =G5/Dados!J$15 -> 0.0096153846 | H10: =H5/Dados!K$15 -> 0.04 | I10: =I5/Dados!L$15 -> 0.046728972 | ... O10: =O5/Dados!R$15 -> 0.0076335878
A12: =Dados!D19 -> Característica | B12: =Dados!T19 -> %
A13: =Dados!D20 -> Mulher | B13: =Dados!T20 -> 0.10766504
A14: =Dados!D21 -> Crianças e adolescentes | B14: =Dados!T21 -> 0.019494905
A15: =Dados!D22 -> Capacete | B15: =Dados!T22 -> 0.10722198
A16: Caronas | B16: =Dados!T23 -> 0.019494905
A17: =Dados!D35 -> Cargueira tradicional | B17: =Dados!T24 -> 0.10013292
A18: =Dados!D37 -> Serviço | B18: =Dados!T25 -> 0.11785556
A19: =Dados!D39 -> Contramão | B19: =Dados!T26 -> 0.036331413
A20: =Dados!D27 -> Calçada | B20: =Dados!T27 -> 0.022596367

Sheet Fluxo
A1: HORÁRIO | E1: =UPPER(CONFFLUXO!A3) -> RUI BARBOSA
A2: TOTAL | E2: =SUM(E3:G3) -> 22
E3: =CONFFLUXO!Q3 -> 10 | F3: =CONFFLUXO!Q4 -> 1 | G3: =CONFFLUXO!Q5 -> 11
A5: =UPPER(CONFFLUXO!A12) -> JAQUEIRA | B5: =SUM(C5:C7) -> 158 | C5: =CONFFLUXO!Q14 -> 2 | I5: =CONFFLUXO!Q6 -> 128 | J5: =SUM(I5:I7) -> 729 | K5: =UPPER(CONFFLUXO!A6) -> PARNAMIRIM
C6: =CONFFLUXO!Q13 -> 148 | F6: =SUM(E3:G3,I5:I7,E9:G9,C5:C7) -> 2257 | I6: =CONFFLUXO!Q7 -> 572
C7: =CONFFLUXO!Q12 -> 8 | I7: =CONFFLUXO!Q8 -> 29
E9: =CONFFLUXO!Q11 -> 6 | F9: =CONFFLUXO!Q10 -> 749 | G9: =CONFFLUXO!Q9 -> 593
E10: =SUM(E9:G9) -> 1348
E11: =UPPER(CONFFLUXO!A9) -> PADRE ROMA | K11: =MAX(3:3,I:I,9:9,C:C) -> 749

Sheet Coordenadas
A1: Norte
A2: Leste
A3: Sul
A4: Oeste
