Workbook

Sheet Resumo
A1: Cruzamento | B1: Av. Visconde de Suassuna x R. do Hospício
A2: Data | B2: 43516
A3: Coordenadas Geográficas | B3: -8.05508, -34.88226
A4: Relatório | B4: https://docs.google.com/document/d/1r9pVMhuvnT2uoo3wABMjlGDwW4v1dQ-Y/edit
A5: Total | B5: =Dados!Q15 -> 1532
A6: Máximo em um hora | B6: =MAX(Dados!C15:P15) -> 149
A7: Mulher | B7: =Dados!R20 -> 0.088120104
A8: Crianças e adolescentes | B8: =Dados!R21 -> 0.019582245
A9: Capacete | B9: =Dados!R22 -> 0.048302872
A10: Caronas | B10: =Dados!R23 -> 0.05613577
A11: Cargueiras | B11: =Dados!R24 -> 0.20430809
A12: Serviço | B12: =Dados!R25 -> 0.065926893
A13: Contramão | B13: =Dados!R26 -> 0.35182768
A14: Calçada | B14: =Dados!R27 -> 0.054830287

Sheet Dados
A1: Dados quantitativos e sentido de deslocamento
A2: ORIGEM | B2: DESTINO | C2: 6 | D2: 7 | E2: 8 | F2: 9 | G2: 10 | H2: 11 | I2: 12 | J2: 13 | K2: 14 | L2: 15 | M2: 16 | N2: 17 | O2: 18 | P2: 19 | Q2: TOTAL | R2: %
A3: Santo Amaro | B3: Espinheiro | C3: =ROUND(IF(ISBLANK(Original!CD3),'Base projeção'!C3*'Base projeção'!$A$16,Original!C3),0) -> 14 | D3: =ROUND(IF(ISBLANK(Original!CE3),'Base projeção'!D3*'Base projeção'!$A$16,Original!D3),0) -> 17 | E3: =ROUND(IF(ISBLANK(Original!CF3),'Base projeção'!E3*'Base projeção'!$A$16,Original!E3),0) -> 8 | F3: =ROUND(IF(ISBLANK(Original!CG3),'Base projeção'!F3*'Base projeção'!$A$16,Original!F3),0) -> 7 | G3: =ROUND(IF(ISBLANK(Original!CH3),'Base projeção'!G3*'Base projeção'!$A$16,Original!G3),0) -> 23 | H3: =ROUND(IF(ISBLANK(Original!CI3),'Base projeção'!H3*'Base projeção'!$A$16,Original!H3),0) -> 13 | I3: =ROUND(IF(ISBLANK(Original!CJ3),'Base projeção'!I3*'Base projeção'!$A$16,Original!I3),0) -> 8 | J3: =ROUND(IF(ISBLANK(Original!CK3),'Base projeção'!J3*'Base projeção'!$A$16,Original!J3),0) -> 6 | ... P3: =ROUND(IF(ISBLANK(Original!CQ3),'Base projeção'!P3*'Base projeção'!$A$16,Original!P3),0) -> 11 | Q3: =SUM(C3:P3) -> 150 | R3: =Q3/$Q$15 -> 0.097911227
A4: Santo Amaro | B4: Boa Vista | C4: =ROUND(IF(ISBLANK(Original!CD4),'Base projeção'!C4*'Base projeção'!$A$16,Original!C4),0) -> 1 | D4: =ROUND(IF(ISBLANK(Original!CE4),'Base projeção'!D4*'Base projeção'!$A$16,Original!D4),0) -> 1 | E4: =ROUND(IF(ISBLANK(Original!CF4),'Base projeção'!E4*'Base projeção'!$A$16,Original!E4),0) -> 4 | F4: =ROUND(IF(ISBLANK(Original!CG4),'Base projeção'!F4*'Base projeção'!$A$16,Original!F4),0) -> 1 | G4: =ROUND(IF(ISBLANK(Original!CH4),'Base projeção'!G4*'Base projeção'!$A$16,Original!G4),0) -> 4 | H4: =ROUND(IF(ISBLANK(Original!CI4),'Base projeção'!H4*'Base projeção'!$A$16,Original!H4),0) -> 1 | I4: =ROUND(IF(ISBLANK(Original!CJ4),'Base projeção'!I4*'Base projeção'!$A$16,Original!I4),0) -> 0 | J4: =ROUND(IF(ISBLANK(Original!CK4),'Base projeção'!J4*'Base projeção'!$A$16,Original!J4),0) -> 1 | ... P4: =ROUND(IF(ISBLANK(Original!CQ4),'Base projeção'!P4*'Base projeção'!$A$16,Original!P4),0) -> 0 | Q4: =SUM(C4:P4) -> 19 | R4: =Q4/$Q$15 -> 0.012402089
A5: Santo Amaro | B5: Bairro do Recife | C5: =ROUND(IF(ISBLANK(Original!CD5),'Base projeção'!C5*'Base projeção'!$A$16,Original!C5),0) -> 1 | D5: =ROUND(IF(ISBLANK(Original!CE5),'Base projeção'!D5*'Base projeção'!$A$16,Original!D5),0) -> 1 | E5: =ROUND(IF(ISBLANK(Original!CF5),'Base projeção'!E5*'Base projeção'!$A$16,Original!E5),0) -> 0 | F5: =ROUND(IF(ISBLANK(Original!CG5),'Base projeção'!F5*'Base projeção'!$A$16,Original!F5),0) -> 0 | G5: =ROUND(IF(ISBLANK(Original!CH5),'Base projeção'!G5*'Base projeção'!$A$16,Original!G5),0) -> 1 | H5: =ROUND(IF(ISBLANK(Original!CI5),'Base projeção'!H5*'Base projeção'!$A$16,Original!H5),0) -> 4 | I5: =ROUND(IF(ISBLANK(Original!CJ5),'Base projeção'!I5*'Base projeção'!$A$16,Original!I5),0) -> 1 | J5: =ROUND(IF(ISBLANK(Original!CK5),'Base projeção'!J5*'Base projeção'!$A$16,Original!J5),0) -> 0 | ... P5: =ROUND(IF(ISBLANK(Original!CQ5),'Base projeção'!P5*'Base projeção'!$A$16,Original!P5),0) -> 0 | Q5: =SUM(C5:P5) -> 16 | R5: =Q5/$Q$15 -> 0.010443864
A6: Bairro do Recife | B6: Santo Amaro | C6: =ROUND(IF(ISBLANK(Original!CD6),'Base projeção'!C6*'Base projeção'!$A$16,Original!C6),0) -> 1 | D6: =ROUND(IF(ISBLANK(Original!CE6),'Base projeção'!D6*'Base projeção'!$A$16,Original!D6),0) -> 4 | E6: =ROUND(IF(ISBLANK(Original!CF6),'Base projeção'!E6*'Base projeção'!$A$16,Original!E6),0) -> 3 | F6: =ROUND(IF(ISBLANK(Original!CG6),'Base projeção'!F6*'Base projeção'!$A$16,Original!F6),0) -> 1 | G6: =ROUND(IF(ISBLANK(Original!CH6),'Base projeção'!G6*'Base projeção'!$A$16,Original!G6),0) -> 11 | H6: =ROUND(IF(ISBLANK(Original!CI6),'Base projeção'!H6*'Base projeção'!$A$16,Original!H6),0) -> 13 | I6: =ROUND(IF(ISBLANK(Original!CJ6),'Base projeção'!I6*'Base projeção'!$A$16,Original!I6),0) -> 4 | J6: =ROUND(IF(ISBLANK(Original!CK6),'Base projeção'!J6*'Base projeção'!$A$16,Original!J6),0) -> 1 | ... P6: =ROUND(IF(ISBLANK(Original!CQ6),'Base projeção'!P6*'Base projeção'!$A$16,Original!P6),0) -> 7 | Q6: =SUM(C6:P6) -> 62 | R6: =Q6/$Q$15 -> 0.040469974
A7: Bairro do Recife | B7: Espinheiro | C7: =ROUND(IF(ISBLANK(Original!CD7),'Base projeção'!C7*'Base projeção'!$A$16,Original!C7),0) -> 23 | D7: =ROUND(IF(ISBLANK(Original!CE7),'Base projeção'!D7*'Base projeção'!$A$16,Original!D7),0) -> 17 | E7: =ROUND(IF(ISBLANK(Original!CF7),'Base projeção'!E7*'Base projeção'!$A$16,Original!E7),0) -> 50 | F7: =ROUND(IF(ISBLANK(Original!CG7),'Base projeção'!F7*'Base projeção'!$A$16,Original!F7),0) -> 25 | G7: =ROUND(IF(ISBLANK(Original!CH7),'Base projeção'!G7*'Base projeção'!$A$16,Original!G7),0) -> 16 | H7: =ROUND(IF(ISBLANK(Original!CI7),'Base projeção'!H7*'Base projeção'!$A$16,Original!H7),0) -> 23 | I7: =ROUND(IF(ISBLANK(Original!CJ7),'Base projeção'!I7*'Base projeção'!$A$16,Original!I7),0) -> 27 | J7: =ROUND(IF(ISBLANK(Original!CK7),'Base projeção'!J7*'Base projeção'!$A$16,Original!J7),0) -> 21 | ... P7: =ROUND(IF(ISBLANK(Original!CQ7),'Base projeção'!P7*'Base projeção'!$A$16,Original!P7),0) -> 10 | Q7: =SUM(C7:P7) -> 332 | R7: =Q7/$Q$15 -> 0.21671018
A8: Bairro do Recife | B8: Boa Vista | C8: =ROUND(IF(ISBLANK(Original!CD8),'Base projeção'!C8*'Base projeção'!$A$16,Original!C8),0) -> 1 | D8: =ROUND(IF(ISBLANK(Original!CE8),'Base projeção'!D8*'Base projeção'!$A$16,Original!D8),0) -> 4 | E8: =ROUND(IF(ISBLANK(Original!CF8),'Base projeção'!E8*'Base projeção'!$A$16,Original!E8),0) -> 1 | F8: =ROUND(IF(ISBLANK(Original!CG8),'Base projeção'!F8*'Base projeção'!$A$16,Original!F8),0) -> 1 | G8: =ROUND(IF(ISBLANK(Original!CH8),'Base projeção'!G8*'Base projeção'!$A$16,Original!G8),0) -> 0 | H8: =ROUND(IF(ISBLANK(Original!CI8),'Base projeção'!H8*'Base projeção'!$A$16,Original!H8),0) -> 0 | I8: =ROUND(IF(ISBLANK(Original!CJ8),'Base projeção'!I8*'Base projeção'!$A$16,Original!I8),0) -> 3 | J8: =ROUND(IF(ISBLANK(Original!CK8),'Base projeção'!J8*'Base projeção'!$A$16,Original!J8),0) -> 0 | ... P8: =ROUND(IF(ISBLANK(Original!CQ8),'Base projeção'!P8*'Base projeção'!$A$16,Original!P8),0) -> 1 | Q8: =SUM(C8:P8) -> 18 | R8: =Q8/$Q$15 -> 0.011749347
A9: Boa Vista | B9: Bairro do Recife | C9: =ROUND(IF(ISBLANK(Original!CD9),'Base projeção'!C9*'Base projeção'!$A$16,Original!C9),0) -> 0 | D9: =ROUND(IF(ISBLANK(Original!CE9),'Base projeção'!D9*'Base projeção'!$A$16,Original!D9),0) -> 3 | E9: =ROUND(IF(ISBLANK(Original!CF9),'Base projeção'!E9*'Base projeção'!$A$16,Original!E9),0) -> 1 | F9: =ROUND(IF(ISBLANK(Original!CG9),'Base projeção'!F9*'Base projeção'!$A$16,Original!F9),0) -> 6 | G9: =ROUND(IF(ISBLANK(Original!CH9),'Base projeção'!G9*'Base projeção'!$A$16,Original!G9),0) -> 3 | H9: =ROUND(IF(ISBLANK(Original!CI9),'Base projeção'!H9*'Base projeção'!$A$16,Original!H9),0) -> 1 | I9: =ROUND(IF(ISBLANK(Original!CJ9),'Base projeção'!I9*'Base projeção'!$A$16,Original!I9),0) -> 3 | J9: =ROUND(IF(ISBLANK(Original!CK9),'Base projeção'!J9*'Base projeção'!$A$16,Original!J9),0) -> 0 | ... P9: =ROUND(IF(ISBLANK(Original!CQ9),'Base projeção'!P9*'Base projeção'!$A$16,Original!P9),0) -> 4 | Q9: =SUM(C9:P9) -> 43 | R9: =Q9/$Q$15 -> 0.028067885
A10: Boa Vista | B10: Santo Amaro | C10: =ROUND(IF(ISBLANK(Original!CD10),'Base projeção'!C10*'Base projeção'!$A$16,Original!C10),0) -> 4 | D10: =ROUND(IF(ISBLANK(Original!CE10),'Base projeção'!D10*'Base projeção'!$A$16,Original!D10),0) -> 18 | E10: =ROUND(IF(ISBLANK(Original!CF10),'Base projeção'!E10*'Base projeção'!$A$16,Original!E10),0) -> 11 | F10: =ROUND(IF(ISBLANK(Original!CG10),'Base projeção'!F10*'Base projeção'!$A$16,Original!F10),0) -> 20 | G10: =ROUND(IF(ISBLANK(Original!CH10),'Base projeção'!G10*'Base projeção'!$A$16,Original!G10),0) -> 14 | H10: =ROUND(IF(ISBLANK(Original!CI10),'Base projeção'!H10*'Base projeção'!$A$16,Original!H10),0) -> 10 | I10: =ROUND(IF(ISBLANK(Original!CJ10),'Base projeção'!I10*'Base projeção'!$A$16,Original!I10),0) -> 14 | J10: =ROUND(IF(ISBLANK(Original!CK10),'Base projeção'!J10*'Base projeção'!$A$16,Original!J10),0) -> 8 | ... P10: =ROUND(IF(ISBLANK(Original!CQ10),'Base projeção'!P10*'Base projeção'!$A$16,Original!P10),0) -> 23 | Q10: =SUM(C10:P10) -> 249 | R10: =Q10/$Q$15 -> 0.16253264
A11: Boa Vista | B11: Espinheiro | C11: =ROUND(IF(ISBLANK(Original!CD11),'Base projeção'!C11*'Base projeção'!$A$16,Original!C11),0) -> 1 | D11: =ROUND(IF(ISBLANK(Original!CE11),'Base projeção'!D11*'Base projeção'!$A$16,Original!D11),0) -> 1 | E11: =ROUND(IF(ISBLANK(Original!CF11),'Base projeção'!E11*'Base projeção'!$A$16,Original!E11),0) -> 3 | F11: =ROUND(IF(ISBLANK(Original!CG11),'Base projeção'!F11*'Base projeção'!$A$16,Original!F11),0) -> 3 | G11: =ROUND(IF(ISBLANK(Original!CH11),'Base projeção'!G11*'Base projeção'!$A$16,Original!G11),0) -> 3 | H11: =ROUND(IF(ISBLANK(Original!CI11),'Base projeção'!H11*'Base projeção'!$A$16,Original!H11),0) -> 1 | I11: =ROUND(IF(ISBLANK(Original!CJ11),'Base projeção'!I11*'Base projeção'!$A$16,Original!I11),0) -> 4 | J11: =ROUND(IF(ISBLANK(Original!CK11),'Base projeção'!J11*'Base projeção'!$A$16,Original!J11),0) -> 1 | ... P11: =ROUND(IF(ISBLANK(Original!CQ11),'Base projeção'!P11*'Base projeção'!$A$16,Original!P11),0) -> 0 | Q11: =SUM(C11:P11) -> 27 | R11: =Q11/$Q$15 -> 0.017624021
A12: Espinheiro | B12: Boa Vista | C12: =ROUND(IF(ISBLANK(Original!CD12),'Base projeção'!C12*'Base projeção'!$A$16,Original!C12),0) -> 3 | D12: =ROUND(IF(ISBLANK(Original!CE12),'Base projeção'!D12*'Base projeção'!$A$16,Original!D12),0) -> 0 | E12: =ROUND(IF(ISBLANK(Original!CF12),'Base projeção'!E12*'Base projeção'!$A$16,Original!E12),0) -> 1 | F12: =ROUND(IF(ISBLANK(Original!CG12),'Base projeção'!F12*'Base projeção'!$A$16,Original!F12),0) -> 3 | G12: =ROUND(IF(ISBLANK(Original!CH12),'Base projeção'!G12*'Base projeção'!$A$16,Original!G12),0) -> 4 | H12: =ROUND(IF(ISBLANK(Original!CI12),'Base projeção'!H12*'Base projeção'!$A$16,Original!H12),0) -> 6 | I12: =ROUND(IF(ISBLANK(Original!CJ12),'Base projeção'!I12*'Base projeção'!$A$16,Original!I12),0) -> 1 | J12: =ROUND(IF(ISBLANK(Original!CK12),'Base projeção'!J12*'Base projeção'!$A$16,Original!J12),0) -> 4 | ... P12: =ROUND(IF(ISBLANK(Original!CQ12),'Base projeção'!P12*'Base projeção'!$A$16,Original!P12),0) -> 0 | Q12: =SUM(C12:P12) -> 31 | R12: =Q12/$Q$15 -> 0.020234987
A13: Espinheiro | B13: Bairro do Recife | C13: =ROUND(IF(ISBLANK(Original!CD13),'Base projeção'!C13*'Base projeção'!$A$16,Original!C13),0) -> 16 | D13: =ROUND(IF(ISBLANK(Original!CE13),'Base projeção'!D13*'Base projeção'!$A$16,Original!D13),0) -> 16 | E13: =ROUND(IF(ISBLANK(Original!CF13),'Base projeção'!E13*'Base projeção'!$A$16,Original!E13),0) -> 4 | F13: =ROUND(IF(ISBLANK(Original!CG13),'Base projeção'!F13*'Base projeção'!$A$16,Original!F13),0) -> 17 | G13: =ROUND(IF(ISBLANK(Original!CH13),'Base projeção'!G13*'Base projeção'!$A$16,Original!G13),0) -> 17 | H13: =ROUND(IF(ISBLANK(Original!CI13),'Base projeção'!H13*'Base projeção'!$A$16,Original!H13),0) -> 14 | I13: =ROUND(IF(ISBLANK(Original!CJ13),'Base projeção'!I13*'Base projeção'!$A$16,Original!I13),0) -> 25 | J13: =ROUND(IF(ISBLANK(Original!CK13),'Base projeção'!J13*'Base projeção'!$A$16,Original!J13),0) -> 13 | ... P13: =ROUND(IF(ISBLANK(Original!CQ13),'Base projeção'!P13*'Base projeção'!$A$16,Original!P13),0) -> 7 | Q13: =SUM(C13:P13) -> 212 | R13: =Q13/$Q$15 -> 0.1383812
A14: Espinheiro | B14: Santo Amaro | C14: =ROUND(IF(ISBLANK(Original!CD14),'Base projeção'!C14*'Base projeção'!$A$16,Original!C14),0) -> 14 | D14: =ROUND(IF(ISBLANK(Original!CE14),'Base projeção'!D14*'Base projeção'!$A$16,Original!D14),0) -> 7 | E14: =ROUND(IF(ISBLANK(Original!CF14),'Base projeção'!E14*'Base projeção'!$A$16,Original!E14),0) -> 17 | F14: =ROUND(IF(ISBLANK(Original!CG14),'Base projeção'!F14*'Base projeção'!$A$16,Original!F14),0) -> 16 | G14: =ROUND(IF(ISBLANK(Original!CH14),'Base projeção'!G14*'Base projeção'!$A$16,Original!G14),0) -> 20 | H14: =ROUND(IF(ISBLANK(Original!CI14),'Base projeção'!H14*'Base projeção'!$A$16,Original!H14),0) -> 44 | I14: =ROUND(IF(ISBLANK(Original!CJ14),'Base projeção'!I14*'Base projeção'!$A$16,Original!I14),0) -> 44 | J14: =ROUND(IF(ISBLANK(Original!CK14),'Base projeção'!J14*'Base projeção'!$A$16,Original!J14),0) -> 21 | ... P14: =ROUND(IF(ISBLANK(Original!CQ14),'Base projeção'!P14*'Base projeção'!$A$16,Original!P14),0) -> 30 | Q14: =SUM(C14:P14) -> 373 | R14: =Q14/$Q$15 -> 0.24347258
B15: TOTAL | C15: =SUM(C$3:C$14) -> 79 | D15: =SUM(D$3:D$14) -> 89 | E15: =SUM(E$3:E$14) -> 103 | F15: =SUM(F$3:F$14) -> 100 | G15: =SUM(G$3:G$14) -> 116 | H15: =SUM(H$3:H$14) -> 130 | I15: =SUM(I$3:I$14) -> 134 | J15: =SUM(J$3:J$14) -> 76 | ... Q15: =SUM(Q$3:Q$14) -> 1532
B16: Percentual | C16: =C15/$Q$15 -> 0.05156658 | D16: =D15/$Q$15 -> 0.058093995 | E16: =E15/$Q$15 -> 0.067232376 | F16: =F15/$Q$15 -> 0.065274151 | G16: =G15/$Q$15 -> 0.075718016 | H16: =H15/$Q$15 -> 0.084856397 | I16: =I15/$Q$15 -> 0.087467363 | J16: =J15/$Q$15 -> 0.049608355 | ... P16: =P15/$Q$15 -> 0.060704961 | Q16: =SUM(C16:P16) -> 1
A18: Dados qualitativos padrões
B19: Característica | C19: 6 | D19: 7 | E19: 8 | F19: 9 | G19: 10 | H19: 11 | I19: 12 | J19: 13 | K19: 14 | L19: 15 | M19: 16 | N19: 17 | O19: 18 | P19: 19 | Q19: TOTAL | R19: %
B20: Mulher | C20: =ROUND(IF(ISBLANK(Original!C20),'Base projeção'!C20*'Base projeção'!$A$16,Original!C20),0) -> 6 | D20: =ROUND(IF(ISBLANK(Original!D20),'Base projeção'!D20*'Base projeção'!$A$16,Original!D20),0) -> 13 | E20: =ROUND(IF(ISBLANK(Original!E20),'Base projeção'!E20*'Base projeção'!$A$16,Original!E20),0) -> 13 | F20: =ROUND(IF(ISBLANK(Original!F20),'Base projeção'!F20*'Base projeção'!$A$16,Original!F20),0) -> 1 | G20: =ROUND(IF(ISBLANK(Original!G20),'Base projeção'!G20*'Base projeção'!$A$16,Original!G20),0) -> 6 | H20: =ROUND(IF(ISBLANK(Original!H20),'Base projeção'!H20*'Base projeção'!$A$16,Original!H20),0) -> 8 | I20: =ROUND(IF(ISBLANK(Original!I20),'Base projeção'!I20*'Base projeção'!$A$16,Original!I20),0) -> 15 | J20: =ROUND(IF(ISBLANK(Original!J20),'Base projeção'!J20*'Base projeção'!$A$16,Original!J20),0) -> 8 | ... P20: =ROUND(IF(ISBLANK(Original!P20),'Base projeção'!P20*'Base projeção'!$A$16,Original!P20),0) -> 8 | Q20: =SUM(C20:P20) -> 135 | R20: =Q20/$Q$15 -> 0.088120104
B21: Crianças e adolescentes | C21: =ROUND(IF(ISBLANK(Original!C21),'Base projeção'!C21*'Base projeção'!$A$16,Original!C21),0) -> 0 | D21: =ROUND(IF(ISBLANK(Original!D21),'Base projeção'!D21*'Base projeção'!$A$16,Original!D21),0) -> 0 | E21: =ROUND(IF(ISBLANK(Original!E21),'Base projeção'!E21*'Base projeção'!$A$16,Original!E21),0) -> 0 | F21: =ROUND(IF(ISBLANK(Original!F21),'Base projeção'!F21*'Base projeção'!$A$16,Original!F21),0) -> 0 | G21: =ROUND(IF(ISBLANK(Original!G21),'Base projeção'!G21*'Base projeção'!$A$16,Original!G21),0) -> 1 | H21: =ROUND(IF(ISBLANK(Original!H21),'Base projeção'!H21*'Base projeção'!$A$16,Original!H21),0) -> 6 | I21: =ROUND(IF(ISBLANK(Original!I21),'Base projeção'!I21*'Base projeção'!$A$16,Original!I21),0) -> 2 | J21: =ROUND(IF(ISBLANK(Original!J21),'Base projeção'!J21*'Base projeção'!$A$16,Original!J21),0) -> 1 | ... P21: =ROUND(IF(ISBLANK(Original!P21),'Base projeção'!P21*'Base projeção'!$A$16,Original!P21),0) -> 4 | Q21: =SUM(C21:P21) -> 30 | R21: =Q21/$Q$15 -> 0.019582245
B22: Capacete | C22: =ROUND(IF(ISBLANK(Original!C22),'Base projeção'!C22*'Base projeção'!$A$16,Original!C22),0) -> 3 | D22: =ROUND(IF(ISBLANK(Original!D22),'Base projeção'!D22*'Base projeção'!$A$16,Original!D22),0) -> 0 | E22: =ROUND(IF(ISBLANK(Original!E22),'Base projeção'!E22*'Base projeção'!$A$16,Original!E22),0) -> 7 | F22: =ROUND(IF(ISBLANK(Original!F22),'Base projeção'!F22*'Base projeção'!$A$16,Original!F22),0) -> 3 | G22: =ROUND(IF(ISBLANK(Original!G22),'Base projeção'!G22*'Base projeção'!$A$16,Original!G22),0) -> 6 | H22: =ROUND(IF(ISBLANK(Original!H22),'Base projeção'!H22*'Base projeção'!$A$16,Original!H22),0) -> 8 | I22: =ROUND(IF(ISBLANK(Original!I22),'Base projeção'!I22*'Base projeção'!$A$16,Original!I22),0) -> 4 | J22: =ROUND(IF(ISBLANK(Original!J22),'Base projeção'!J22*'Base projeção'!$A$16,Original!J22),0) -> 0 | ... P22: =ROUND(IF(ISBLANK(Original!P22),'Base projeção'!P22*'Base projeção'!$A$16,Original!P22),0) -> 4 | Q22: =SUM(C22:P22) -> 74 | R22: =Q22/$Q$15 -> 0.048302872
B23: Caronas | C23: =SUM(C31:C33) -> 4 | D23: =SUM(D31:D33) -> 11 | E23: =SUM(E31:E33) -> 1 | F23: =SUM(F31:F33) -> 4 | G23: =SUM(G31:G33) -> 8 | H23: =SUM(H31:H33) -> 10 | I23: =SUM(I31:I33) -> 9 | J23: =SUM(J31:J33) -> 5 | ... P23: =SUM(P31:P33) -> 1 | Q23: =SUM(C23:P23) -> 86 | R23: =Q23/$Q$15 -> 0.05613577
B24: Cargueiras | C24: =SUM(C34:C35) -> 13 | D24: =SUM(D34:D35) -> 18 | E24: =SUM(E34:E35) -> 28 | F24: =SUM(F34:F35) -> 32 | G24: =SUM(G34:G35) -> 35 | H24: =SUM(H34:H35) -> 35 | I24: =SUM(I34:I35) -> 17 | J24: =SUM(J34:J35) -> 20 | ... P24: =SUM(P34:P35) -> 9 | Q24: =SUM(C24:P24) -> 313 | R24: =Q24/$Q$15 -> 0.20430809
B25: Serviço | C25: =SUM(C36:C37) -> 7 | D25: =SUM(D36:D37) -> 10 | E25: =SUM(E36:E37) -> 13 | F25: =SUM(F36:F37) -> 16 | G25: =SUM(G36:G37) -> 14 | H25: =SUM(H36:H37) -> 7 | I25: =SUM(I36:I37) -> 8 | J25: =SUM(J36:J37) -> 4 | ... P25: =SUM(P36:P37) -> 3 | Q25: =SUM(C25:P25) -> 101 | R25: =Q25/$Q$15 -> 0.065926893
B26: Contramão | C26: =SUM(C38:C39) -> 30 | D26: =SUM(D38:D39) -> 17 | E26: =SUM(E38:E39) -> 34 | F26: =SUM(F38:F39) -> 36 | G26: =SUM(G38:G39) -> 38 | H26: =SUM(H38:H39) -> 51 | I26: =SUM(I38:I39) -> 41 | J26: =SUM(J38:J39) -> 33 | ... P26: =SUM(P38:P39) -> 34 | Q26: =SUM(C26:P26) -> 539 | R26: =Q26/$Q$15 -> 0.35182768
B27: Calçada | C27: =ROUND(IF(ISBLANK(Original!C32),'Base projeção'!C32*'Base projeção'!$A$16,Original!C32),0) -> 4 | D27: =ROUND(IF(ISBLANK(Original!D32),'Base projeção'!D32*'Base projeção'!$A$16,Original!D32),0) -> 7 | E27: =ROUND(IF(ISBLANK(Original!E32),'Base projeção'!E32*'Base projeção'!$A$16,Original!E32),0) -> 4 | F27: =ROUND(IF(ISBLANK(Original!F32),'Base projeção'!F32*'Base projeção'!$A$16,Original!F32),0) -> 8 | G27: =ROUND(IF(ISBLANK(Original!G32),'Base projeção'!G32*'Base projeção'!$A$16,Original!G32),0) -> 14 | H27: =ROUND(IF(ISBLANK(Original!H32),'Base projeção'!H32*'Base projeção'!$A$16,Original!H32),0) -> 17 | I27: =ROUND(IF(ISBLANK(Original!I32),'Base projeção'!I32*'Base projeção'!$A$16,Original!I32),0) -> 6 | J27: =ROUND(IF(ISBLANK(Original!J32),'Base projeção'!J32*'Base projeção'!$A$16,Original!J32),0) -> 4 | ... P27: =ROUND(IF(ISBLANK(Original!P32),'Base projeção'!P32*'Base projeção'!$A$16,Original!P32),0) -> 6 | Q27: =SUM(C27:P27) -> 84 | R27: =Q27/$Q$15 -> 0.054830287
A29: Dados qualitativos das observações
B30: Característica | C30: 6 | D30: 7 | E30: 8 | F30: 9 | G30: 10 | H30: 11 | I30: 12 | J30: 13 | K30: 14 | L30: 15 | M30: 16 | N30: 17 | O30: 18 | P30: 19 | Q30: TOTAL | R30: %
B31: Carona criança | C31: =ROUND(IF(ISBLANK(Original!C23),'Base projeção'!C23*'Base projeção'!$A$16,Original!C23),0) -> 4 | D31: =ROUND(IF(ISBLANK(Original!D23),'Base projeção'!D23*'Base projeção'!$A$16,Original!D23),0) -> 0 | E31: =ROUND(IF(ISBLANK(Original!E23),'Base projeção'!E23*'Base projeção'!$A$16,Original!E23),0) -> 0 | F31: =ROUND(IF(ISBLANK(Original!F23),'Base projeção'!F23*'Base projeção'!$A$16,Original!F23),0) -> 0 | G31: =ROUND(IF(ISBLANK(Original!G23),'Base projeção'!G23*'Base projeção'!$A$16,Original!G23),0) -> 4 | H31: =ROUND(IF(ISBLANK(Original!H23),'Base projeção'!H23*'Base projeção'!$A$16,Original!H23),0) -> 3 | I31: =ROUND(IF(ISBLANK(Original!I23),'Base projeção'!I23*'Base projeção'!$A$16,Original!I23),0) -> 6 | J31: =ROUND(IF(ISBLANK(Original!J23),'Base projeção'!J23*'Base projeção'!$A$16,Original!J23),0) -> 2 | ... P31: =ROUND(IF(ISBLANK(Original!P23),'Base projeção'!P23*'Base projeção'!$A$16,Original!P23),0) -> 1 | Q31: =SUM(C31:P31) -> 36 | R31: =Q31/$Q$15 -> 0.023498695
B32: Carona mulher | C32: =ROUND(IF(ISBLANK(Original!C24),'Base projeção'!C24*'Base projeção'!$A$16,Original!C24),0) -> 0 | D32: =ROUND(IF(ISBLANK(Original!D24),'Base projeção'!D24*'Base projeção'!$A$16,Original!D24),0) -> 11 | E32: =ROUND(IF(ISBLANK(Original!E24),'Base projeção'!E24*'Base projeção'!$A$16,Original!E24),0) -> 0 | F32: =ROUND(IF(ISBLANK(Original!F24),'Base projeção'!F24*'Base projeção'!$A$16,Original!F24),0) -> 1 | G32: =ROUND(IF(ISBLANK(Original!G24),'Base projeção'!G24*'Base projeção'!$A$16,Original!G24),0) -> 4 | H32: =ROUND(IF(ISBLANK(Original!H24),'Base projeção'!H24*'Base projeção'!$A$16,Original!H24),0) -> 6 | I32: =ROUND(IF(ISBLANK(Original!I24),'Base projeção'!I24*'Base projeção'!$A$16,Original!I24),0) -> 2 | J32: =ROUND(IF(ISBLANK(Original!J24),'Base projeção'!J24*'Base projeção'!$A$16,Original!J24),0) -> 1 | ... P32: =ROUND(IF(ISBLANK(Original!P24),'Base projeção'!P24*'Base projeção'!$A$16,Original!P24),0) -> 0 | Q32: =SUM(C32:P32) -> 41 | R32: =Q32/$Q$15 -> 0.026762402
B33: Carona homem | C33: =ROUND(IF(ISBLANK(Original!C25),'Base projeção'!C25*'Base projeção'!$A$16,Original!C25),0) -> 0 | D33: =ROUND(IF(ISBLANK(Original!D25),'Base projeção'!D25*'Base projeção'!$A$16,Original!D25),0) -> 0 | E33: =ROUND(IF(ISBLANK(Original!E25),'Base projeção'!E25*'Base projeção'!$A$16,Original!E25),0) -> 1 | F33: =ROUND(IF(ISBLANK(Original!F25),'Base projeção'!F25*'Base projeção'!$A$16,Original!F25),0) -> 3 | G33: =ROUND(IF(ISBLANK(Original!G25),'Base projeção'!G25*'Base projeção'!$A$16,Original!G25),0) -> 0 | H33: =ROUND(IF(ISBLANK(Original!H25),'Base projeção'!H25*'Base projeção'!$A$16,Original!H25),0) -> 1 | I33: =ROUND(IF(ISBLANK(Original!I25),'Base projeção'!I25*'Base projeção'!$A$16,Original!I25),0) -> 1 | J33: =ROUND(IF(ISBLANK(Original!J25),'Base projeção'!J25*'Base projeção'!$A$16,Original!J25),0) -> 2 | ... P33: =ROUND(IF(ISBLANK(Original!P25),'Base projeção'!P25*'Base projeção'!$A$16,Original!P25),0) -> 0 | Q33: =SUM(C33:P33) -> 9 | R33: =Q33/$Q$15 -> 0.0058746736
B34: Cargueira | C34: =ROUND(IF(ISBLANK(Original!C26),'Base projeção'!C26*'Base projeção'!$A$16,Original!C26),0) -> 13 | D34: =ROUND(IF(ISBLANK(Original!D26),'Base projeção'!D26*'Base projeção'!$A$16,Original!D26),0) -> 18 | E34: =ROUND(IF(ISBLANK(Original!E26),'Base projeção'!E26*'Base projeção'!$A$16,Original!E26),0) -> 28 | F34: =ROUND(IF(ISBLANK(Original!F26),'Base projeção'!F26*'Base projeção'!$A$16,Original!F26),0) -> 28 | G34: =ROUND(IF(ISBLANK(Original!G26),'Base projeção'!G26*'Base projeção'!$A$16,Original!G26),0) -> 35 | H34: =ROUND(IF(ISBLANK(Original!H26),'Base projeção'!H26*'Base projeção'!$A$16,Original!H26),0) -> 35 | I34: =ROUND(IF(ISBLANK(Original!I26),'Base projeção'!I26*'Base projeção'!$A$16,Original!I26),0) -> 11 | J34: =ROUND(IF(ISBLANK(Original!J26),'Base projeção'!J26*'Base projeção'!$A$16,Original!J26),0) -> 11 | ... P34: =ROUND(IF(ISBLANK(Original!P26),'Base projeção'!P26*'Base projeção'!$A$16,Original!P26),0) -> 8 | Q34: =SUM(C34:P34) -> 266 | R34: =Q34/$Q$15 -> 0.17362924
B35: Adaptada a carga | C35: =ROUND(IF(ISBLANK(Original!C27),'Base projeção'!C27*'Base projeção'!$A$16,Original!C27),0) -> 0 | D35: =ROUND(IF(ISBLANK(Original!D27),'Base projeção'!D27*'Base projeção'!$A$16,Original!D27),0) -> 0 | E35: =ROUND(IF(ISBLANK(Original!E27),'Base projeção'!E27*'Base projeção'!$A$16,Original!E27),0) -> 0 | F35: =ROUND(IF(ISBLANK(Original!F27),'Base projeção'!F27*'Base projeção'!$A$16,Original!F27),0) -> 4 | G35: =ROUND(IF(ISBLANK(Original!G27),'Base projeção'!G27*'Base projeção'!$A$16,Original!G27),0) -> 0 | H35: =ROUND(IF(ISBLANK(Original!H27),'Base projeção'!H27*'Base projeção'!$A$16,Original!H27),0) -> 0 | I35: =ROUND(IF(ISBLANK(Original!I27),'Base projeção'!I27*'Base projeção'!$A$16,Original!I27),0) -> 6 | J35: =ROUND(IF(ISBLANK(Original!J27),'Base projeção'!J27*'Base projeção'!$A$16,Original!J27),0) -> 9 | ... P35: =ROUND(IF(ISBLANK(Original!P27),'Base projeção'!P27*'Base projeção'!$A$16,Original!P27),0) -> 1 | Q35: =SUM(C35:P35) -> 47
B36: Serviço | C36: =ROUND(IF(ISBLANK(Original!C28),'Base projeção'!C28*'Base projeção'!$A$16,Original!C28),0) -> 7 | D36: =ROUND(IF(ISBLANK(Original!D28),'Base projeção'!D28*'Base projeção'!$A$16,Original!D28),0) -> 10 | E36: =ROUND(IF(ISBLANK(Original!E28),'Base projeção'!E28*'Base projeção'!$A$16,Original!E28),0) -> 13 | F36: =ROUND(IF(ISBLANK(Original!F28),'Base projeção'!F28*'Base projeção'!$A$16,Original!F28),0) -> 16 | G36: =ROUND(IF(ISBLANK(Original!G28),'Base projeção'!G28*'Base projeção'!$A$16,Original!G28),0) -> 14 | H36: =ROUND(IF(ISBLANK(Original!H28),'Base projeção'!H28*'Base projeção'!$A$16,Original!H28),0) -> 7 | I36: =ROUND(IF(ISBLANK(Original!I28),'Base projeção'!I28*'Base projeção'!$A$16,Original!I28),0) -> 8 | J36: =ROUND(IF(ISBLANK(Original!J28),'Base projeção'!J28*'Base projeção'!$A$16,Original!J28),0) -> 4 | ... P36: =ROUND(IF(ISBLANK(Original!P28),'Base projeção'!P28*'Base projeção'!$A$16,Original!P28),0) -> 3 | Q36: =SUM(C36:P36) -> 101 | R36: =Q36/$Q$15 -> 0.065926893
B37: Serviço App | C37: =ROUND(IF(ISBLANK(Original!C29),'Base projeção'!C29*'Base projeção'!$A$16,Original!C29),0) -> 0 | D37: =ROUND(IF(ISBLANK(Original!D29),'Base projeção'!D29*'Base projeção'!$A$16,Original!D29),0) -> 0 | E37: =ROUND(IF(ISBLANK(Original!E29),'Base projeção'!E29*'Base projeção'!$A$16,Original!E29),0) -> 0 | F37: =ROUND(IF(ISBLANK(Original!F29),'Base projeção'!F29*'Base projeção'!$A$16,Original!F29),0) -> 0 | G37: =ROUND(IF(ISBLANK(Original!G29),'Base projeção'!G29*'Base projeção'!$A$16,Original!G29),0) -> 0 | H37: =ROUND(IF(ISBLANK(Original!H29),'Base projeção'!H29*'Base projeção'!$A$16,Original!H29),0) -> 0 | I37: =ROUND(IF(ISBLANK(Original!I29),'Base projeção'!I29*'Base projeção'!$A$16,Original!I29),0) -> 0 | J37: =ROUND(IF(ISBLANK(Original!J29),'Base projeção'!J29*'Base projeção'!$A$16,Original!J29),0) -> 0 | ... P37: =ROUND(IF(ISBLANK(Original!P29),'Base projeção'!P29*'Base projeção'!$A$16,Original!P29),0) -> 0 | Q37: =SUM(C37:P37) -> 0
B38: Contramao | C38: =ROUND(IF(ISBLANK(Original!C30),'Base projeção'!C30*'Base projeção'!$A$16,Original!C30),0) -> 30 | D38: =ROUND(IF(ISBLANK(Original!D30),'Base projeção'!D30*'Base projeção'!$A$16,Original!D30),0) -> 17 | E38: =ROUND(IF(ISBLANK(Original!E30),'Base projeção'!E30*'Base projeção'!$A$16,Original!E30),0) -> 18 | F38: =ROUND(IF(ISBLANK(Original!F30),'Base projeção'!F30*'Base projeção'!$A$16,Original!F30),0) -> 16 | G38: =ROUND(IF(ISBLANK(Original!G30),'Base projeção'!G30*'Base projeção'!$A$16,Original!G30),0) -> 31 | H38: =ROUND(IF(ISBLANK(Original!H30),'Base projeção'!H30*'Base projeção'!$A$16,Original!H30),0) -> 44 | I38: =ROUND(IF(ISBLANK(Original!I30),'Base projeção'!I30*'Base projeção'!$A$16,Original!I30),0) -> 19 | J38: =ROUND(IF(ISBLANK(Original!J30),'Base projeção'!J30*'Base projeção'!$A$16,Original!J30),0) -> 14 | ... P38: =ROUND(IF(ISBLANK(Original!P30),'Base projeção'!P30*'Base projeção'!$A$16,Original!P30),0) -> 1 | Q38: =SUM(C38:P38) -> 270 | R38: =Q38/$Q$15 -> 0.17624021
B39: Contramão para conversão | C39: =ROUND(IF(ISBLANK(Original!C31),'Base projeção'!C31*'Base projeção'!$A$16,Original!C31),0) -> 0 | D39: =ROUND(IF(ISBLANK(Original!D31),'Base projeção'!D31*'Base projeção'!$A$16,Original!D31),0) -> 0 | E39: =ROUND(IF(ISBLANK(Original!E31),'Base projeção'!E31*'Base projeção'!$A$16,Original!E31),0) -> 16 | F39: =ROUND(IF(ISBLANK(Original!F31),'Base projeção'!F31*'Base projeção'!$A$16,Original!F31),0) -> 20 | G39: =ROUND(IF(ISBLANK(Original!G31),'Base projeção'!G31*'Base projeção'!$A$16,Original!G31),0) -> 7 | H39: =ROUND(IF(ISBLANK(Original!H31),'Base projeção'!H31*'Base projeção'!$A$16,Original!H31),0) -> 7 | I39: =ROUND(IF(ISBLANK(Original!I31),'Base projeção'!I31*'Base projeção'!$A$16,Original!I31),0) -> 22 | J39: =ROUND(IF(ISBLANK(Original!J31),'Base projeção'!J31*'Base projeção'!$A$16,Original!J31),0) -> 19 | ... P39: =ROUND(IF(ISBLANK(Original!P31),'Base projeção'!P31*'Base projeção'!$A$16,Original!P31),0) -> 33 | Q39: =SUM(C39:P39) -> 269 | R39: =Q39/$Q$15 -> 0.17558747
B40: Bike PE | I40: 13 | J40: 6 | M40: 0 | N40: 20 | O40: 16 | Q40: =SUM(C40:P40) -> 55 | R40: =Q40/$Q$15 -> 0.035900783
B41: Triciclo | I41: 0 | J41: 0 | M41: 0 | N41: 0 | O41: 0 | Q41: =SUM(C41:P41) -> 0 | R41: =Q41/$Q$15 -> 0
B42: Eletrica | I42: 0 | J42: 0 | M42: 0 | N42: 0 | O42: 0 | Q42: =SUM(C42:P42) -> 0 | R42: =Q42/$Q$15 -> 0
...

Sheet Original
A1: Dados quantitativos e sentido de deslocamento
A2: ORIGEM | B2: DESTINO | C2: 6 | D2: 7 | E2: 8 | F2: 9 | G2: 10 | H2: 11 | I2: 12 | J2: 13 | K2: 14 | L2: 15 | M2: 16 | N2: 17 | O2: 18 | P2: 19 | Q2: TOTAL | R2: %
A3: Santo Amaro | B3: Espinheiro | I3: 9 | J3: 2 | M3: 6 | N3: 3 | O3: 2 | Q3: =SUM(C3:P3) -> 22 | R3: =Q3/$Q$15 -> 0.035656402
A4: Santo Amaro | B4: Boa Vista | I4: 23 | J4: 21 | M4: 23 | N4: 25 | O4: 15 | Q4: =SUM(C4:P4) -> 107 | R4: =Q4/$Q$15 -> 0.17341977
A5: Santo Amaro | B5: Bairro do Recife | I5: 1 | J5: 1 | M5: 1 | N5: 1 | O5: 1 | Q5: =SUM(C5:P5) -> 5 | R5: =Q5/$Q$15 -> 0.0081037277
A6: Bairro do Recife | B6: Santo Amaro | I6: 4 | J6: 3 | M6: 3 | N6: 4 | O6: 4 | Q6: =SUM(C6:P6) -> 18 | R6: =Q6/$Q$15 -> 0.02917342
A7: Bairro do Recife | B7: Espinheiro | I7: 22 | J7: 19 | M7: 21 | N7: 39 | O7: 33 | Q7: =SUM(C7:P7) -> 134 | R7: =Q7/$Q$15 -> 0.2171799
A8: Bairro do Recife | B8: Boa Vista | I8: 0 | J8: 0 | M8: 0 | N8: 2 | O8: 6 | Q8: =SUM(C8:P8) -> 8 | R8: =Q8/$Q$15 -> 0.012965964
A9: Boa Vista | B9: Bairro do Recife | I9: 0 | J9: 0 | M9: 1 | N9: 1 | O9: 1 | Q9: =SUM(C9:P9) -> 3 | R9: =Q9/$Q$15 -> 0.0048622366
A10: Boa Vista | B10: Santo Amaro | I10: 13 | J10: 15 | M10: 16 | N10: 17 | O10: 34 | Q10: =SUM(C10:P10) -> 95 | R10: =Q10/$Q$15 -> 0.15397083
A11: Boa Vista | B11: Espinheiro | I11: 24 | J11: 22 | M11: 33 | N11: 52 | O11: 36 | Q11: =SUM(C11:P11) -> 167 | R11: =Q11/$Q$15 -> 0.27066451
A12: Espinheiro | B12: Boa Vista | I12: 11 | J12: 9 | M12: 9 | N12: 7 | O12: 14 | Q12: =SUM(C12:P12) -> 50 | R12: =Q12/$Q$15 -> 0.081037277
A13: Espinheiro | B13: Bairro do Recife | I13: 1 | J13: 0 | M13: 2 | N13: 0 | O13: 2 | Q13: =SUM(C13:P13) -> 5 | R13: =Q13/$Q$15 -> 0.0081037277
A14: Espinheiro | B14: Santo Amaro | I14: 2 | J14: 1 | M14: 0 | N14: 0 | O14: 0 | Q14: =SUM(C14:P14) -> 3 | R14: =Q14/$Q$15 -> 0.0048622366
B15: TOTAL | C15: =SUM(C$3:C$14) -> 0 | D15: =SUM(D$3:D$14) -> 0 | E15: =SUM(E$3:E$14) -> 0 | F15: =SUM(F$3:F$14) -> 0 | G15: =SUM(G$3:G$14) -> 0 | H15: =SUM(H$3:H$14) -> 0 | I15: =SUM(I$3:I$14) -> 110 | J15: =SUM(J$3:J$14) -> 93 | ... Q15: =SUM(Q$3:Q$14) -> 617
B16: Percentual | C16: =C15/$Q$15 -> 0 | D16: =D15/$Q$15 -> 0 | E16: =E15/$Q$15 -> 0 | F16: =F15/$Q$15 -> 0 | G16: =G15/$Q$15 -> 0 | H16: =H15/$Q$15 -> 0 | I16: =I15/$Q$15 -> 0.17828201 | J16: =J15/$Q$15 -> 0.15072934 | ... P16: =P15/$Q$15 -> 0 | Q16: =SUM(C16:P16) -> 1
A18: Dados qualitativos padrões
B19: Característica | C19: 6 | D19: 7 | E19: 8 | F19: 9 | G19: 10 | H19: 11 | I19: 12 | J19: 13 | K19: 14 | L19: 15 | M19: 16 | N19: 17 | O19: 18 | P19: 19 | Q19: TOTAL | R19: %
B20: Mulher | I20: 15 | J20: 8 | M20: 13 | N20: 18 | O20: 15 | Q20: =SUM(C20:P20) -> 69 | R20: =Q20/$Q$15 -> 0.11183144
B21: Crianças e adolescentes | I21: 2 | J21: 1 | M21: 0 | N21: 1 | O21: 11 | Q21: =SUM(C21:P21) -> 15 | R21: =Q21/$Q$15 -> 0.024311183
B22: Capacete | I22: 4 | J22: 0 | M22: 8 | N22: 14 | O22: 8 | Q22: =SUM(C22:P22) -> 34 | R22: =Q22/$Q$15 -> 0.055105348
B23: Carona criança | I23: 6 | J23: 2 | M23: 1 | N23: 13 | O23: 2 | Q23: =SUM(C23:P23) -> 24 | R23: =Q23/$Q$15 -> 0.038897893
B24: Carona mulher | I24: 2 | J24: 1 | M24: 2 | N24: 2 | O24: 2 | Q24: =SUM(C24:P24) -> 9 | R24: =Q24/$Q$15 -> 0.01458671
B25: Carona homem | I25: 1 | J25: 2 | M25: 0 | N25: 0 | O25: 1 | Q25: =SUM(C25:P25) -> 4 | R25: =Q25/$Q$15 -> 0.0064829822
B26: Cargueira | I26: 11 | J26: 11 | M26: 16 | N26: 7 | O26: 5 | Q26: =SUM(C26:P26) -> 50 | R26: =Q26/$Q$15 -> 0.081037277
B27: Adaptada a carga | I27: 6 | J27: 9 | M27: 5 | N27: 3 | O27: 10 | Q27: =SUM(C27:P27) -> 33
B28: Serviço | I28: 8 | J28: 4 | M28: 2 | N28: 0 | O28: 0 | Q28: =SUM(C28:P28) -> 14 | R28: =Q28/$Q$15 -> 0.022690438
B29: Serviço App | Q29: =SUM(C29:P29) -> 0
B30: Contramao | I30: 19 | J30: 14 | M30: 11 | N30: 4 | O30: 24 | Q30: =SUM(C30:P30) -> 72 | R30: =Q30/$Q$15 -> 0.11669368
B31: Contramão para conversão | I31: 22 | J31: 19 | M31: 29 | N31: 43 | O31: 23 | Q31: =SUM(C31:P31) -> 136 | R31: =Q31/$Q$15 -> 0.22042139
B32: Calçada | I32: 6 | J32: 4 | M32: 0 | N32: 0 | O32: 7 | Q32: =SUM(C32:P32) -> 17 | R32: =Q32/$Q$15 -> 0.027552674
A34: Dados qualitativos das observações
B35: Característica | C35: 6 | D35: 7 | E35: 8 | F35: 9 | G35: 10 | H35: 11 | I35: 12 | J35: 13 | K35: 14 | L35: 15 | M35: 16 | N35: 17 | O35: 18 | P35: 19 | Q35: TOTAL | R35: %
B36: Bike PE | I36: 13 | J36: 6 | M36: 0 | N36: 20 | O36: 16 | Q36: =SUM(C36:P36) -> 55 | R36: =Q36/$Q$15 -> 0.089141005
B37: Triciclo | I37: 0 | J37: 0 | M37: 0 | N37: 0 | O37: 0 | Q37: =SUM(C37:P37) -> 0 | R37: =Q37/$Q$15 -> 0
B38: Eletrica | I38: 0 | J38: 0 | M38: 0 | N38: 0 | O38: 0 | Q38: =SUM(C38:P38) -> 0 | R38: =Q38/$Q$15 -> 0
B39: Skate | I39: 0 | J39: 0 | M39: 0 | N39: 0 | O39: 0 | Q39: =SUM(C39:P39) -> 0 | R39: =Q39/$Q$15 -> 0
B40: Grupos de pedal | I40: 0 | J40: 0 | M40: 0 | N40: 0 | O40: 0 | Q40: =SUM(C40:P40) -> 0 | R40: =Q40/$Q$15 -> 0
B41: Faixa Azul | I41: 0 | J41: 0 | M41: 0 | N41: 0 | O41: 0
B42: Pedestre empurrando | I42: 2 | J42: 3 | M42: 3 | N42: 1 | O42: 0

Sheet Base projeção
A1: Dados quantitativos e sentido de deslocamento
A2: ORIGEM | B2: DESTINO | C2: 6 | D2: 7 | E2: 8 | F2: 9 | G2: 10 | H2: 11 | I2: 12 | J2: 13 | K2: 14 | L2: 15 | M2: 16 | N2: 17 | O2: 18 | P2: 19 | Q2: TOTAL | R2: %
A3: Santo Amaro | B3: Espinheiro | C3: 10 | D3: 12 | E3: 6 | F3: 5 | G3: 16 | H3: 9 | I3: 6 | J3: 4 | K3: 12 | L3: 3 | M3: 9 | N3: 2 | O3: 4 | P3: 8 | Q3: =SUM(C3:P3) -> 106 | R3: =Q3/$Q$15 -> 0.096980787
A4: Santo Amaro | B4: Boa Vista | C4: 1 | D4: 1 | E4: 3 | F4: 1 | G4: 3 | H4: 1 | I4: 0 | J4: 1 | K4: 0 | L4: 2 | M4: 1 | N4: 1 | O4: 1 | P4: 0 | Q4: =SUM(C4:P4) -> 16 | R4: =Q4/$Q$15 -> 0.014638609
A5: Santo Amaro | B5: Bairro do Recife | C5: 1 | D5: 1 | E5: 0 | F5: 0 | G5: 1 | H5: 3 | I5: 1 | J5: 0 | K5: 4 | L5: 1 | M5: 0 | N5: 0 | O5: 1 | P5: 0 | Q5: =SUM(C5:P5) -> 13 | R5: =Q5/$Q$15 -> 0.01189387
A6: Bairro do Recife | B6: Santo Amaro | C6: 1 | D6: 3 | E6: 2 | F6: 1 | G6: 8 | H6: 9 | I6: 3 | J6: 1 | K6: 5 | L6: 2 | M6: 0 | N6: 2 | O6: 3 | P6: 5 | Q6: =SUM(C6:P6) -> 45 | R6: =Q6/$Q$15 -> 0.041171089
A7: Bairro do Recife | B7: Espinheiro | C7: 16 | D7: 12 | E7: 35 | F7: 18 | G7: 11 | H7: 16 | I7: 19 | J7: 15 | K7: 18 | L7: 19 | M7: 18 | N7: 16 | O7: 14 | P7: 7 | Q7: =SUM(C7:P7) -> 234 | R7: =Q7/$Q$15 -> 0.21408966
A8: Bairro do Recife | B8: Boa Vista | C8: 1 | D8: 3 | E8: 1 | F8: 1 | G8: 0 | H8: 0 | I8: 2 | J8: 0 | K8: 3 | L8: 1 | M8: 1 | N8: 1 | O8: 0 | P8: 1 | Q8: =SUM(C8:P8) -> 15 | R8: =Q8/$Q$15 -> 0.013723696
A9: Boa Vista | B9: Bairro do Recife | C9: 0 | D9: 2 | E9: 1 | F9: 4 | G9: 2 | H9: 1 | I9: 2 | J9: 0 | K9: 3 | L9: 0 | M9: 4 | N9: 4 | O9: 4 | P9: 3 | Q9: =SUM(C9:P9) -> 30 | R9: =Q9/$Q$15 -> 0.027447393
A10: Boa Vista | B10: Santo Amaro | C10: 3 | D10: 13 | E10: 8 | F10: 14 | G10: 10 | H10: 7 | I10: 10 | J10: 6 | K10: 11 | L10: 10 | M10: 20 | N10: 22 | O10: 27 | P10: 16 | Q10: =SUM(C10:P10) -> 177 | R10: =Q10/$Q$15 -> 0.16193962
A11: Boa Vista | B11: Espinheiro | C11: 1 | D11: 1 | E11: 2 | F11: 2 | G11: 2 | H11: 1 | I11: 3 | J11: 1 | K11: 1 | L11: 0 | M11: 1 | N11: 3 | O11: 3 | P11: 0 | Q11: =SUM(C11:P11) -> 21 | R11: =Q11/$Q$15 -> 0.019213175
A12: Espinheiro | B12: Boa Vista | C12: 2 | D12: 0 | E12: 1 | F12: 2 | G12: 3 | H12: 4 | I12: 1 | J12: 3 | K12: 2 | L12: 1 | M12: 3 | N12: 0 | O12: 1 | P12: 0 | Q12: =SUM(C12:P12) -> 23 | R12: =Q12/$Q$15 -> 0.021043001
A13: Espinheiro | B13: Bairro do Recife | C13: 11 | D13: 11 | E13: 3 | F13: 12 | G13: 12 | H13: 10 | I13: 18 | J13: 9 | K13: 7 | L13: 13 | M13: 10 | N13: 18 | O13: 11 | P13: 5 | Q13: =SUM(C13:P13) -> 150 | R13: =Q13/$Q$15 -> 0.13723696
A14: Espinheiro | B14: Santo Amaro | C14: 10 | D14: 5 | E14: 12 | F14: 11 | G14: 14 | H14: 31 | I14: 31 | J14: 15 | K14: 14 | L14: 19 | M14: 15 | N14: 37 | O14: 28 | P14: 21 | Q14: =SUM(C14:P14) -> 263 | R14: =Q14/$Q$15 -> 0.24062214
A15: AUMENTO | B15: TOTAL | C15: =SUM(C$3:C$14) -> 57 | D15: =SUM(D$3:D$14) -> 64 | E15: =SUM(E$3:E$14) -> 74 | F15: =SUM(F$3:F$14) -> 71 | G15: =SUM(G$3:G$14) -> 82 | H15: =SUM(H$3:H$14) -> 92 | I15: =SUM(I$3:I$14) -> 96 | J15: =SUM(J$3:J$14) -> 55 | ... Q15: =SUM(Q$3:Q$14) -> 1093
A16: =Original!Q15/SUM(I15:J15,M15:O15) -> 1.4151376 | B16: Percentual | C16: =C15/$Q$15 -> 0.052150046 | D16: =D15/$Q$15 -> 0.058554437 | E16: =E15/$Q$15 -> 0.067703568 | F16: =F15/$Q$15 -> 0.064958829 | G16: =G15/$Q$15 -> 0.075022873 | H16: =H15/$Q$15 -> 0.084172004 | I16: =I15/$Q$15 -> 0.087831656 | J16: =J15/$Q$15 -> 0.05032022 | ... P16: =P15/$Q$15 -> 0.060384263 | Q16: =SUM(C16:P16) -> 1
A18: Dados qualitativos padrões
B19: Característica | C19: 6 | D19: 7 | E19: 8 | F19: 9 | G19: 10 | H19: 11 | I19: 12 | J19: 13 | K19: 14 | L19: 15 | M19: 16 | N19: 17 | O19: 18 | P19: 19 | Q19: TOTAL | R19: %
B20: Mulher | C20: 4 | D20: 9 | E20: 9 | F20: 1 | G20: 4 | H20: 6 | I20: 2 | J20: 3 | K20: 7 | L20: 1 | M20: 6 | N20: 7 | O20: 7 | P20: 6 | Q20: =SUM(C20:P20) -> 72 | R20: =Q20/$Q$15 -> 0.065873742
B21: Crianças e adolescentes | C21: 0 | D21: 0 | E21: 0 | F21: 0 | G21: 1 | H21: 4 | I21: 4 | J21: 4 | K21: 3 | L21: 0 | M21: 0 | N21: 1 | O21: 5 | P21: 3 | Q21: =SUM(C21:P21) -> 25 | R21: =Q21/$Q$15 -> 0.022872827
B22: Capacete | C22: 2 | D22: 0 | E22: 5 | F22: 2 | G22: 4 | H22: 6 | I22: 7 | J22: 5 | K22: 4 | L22: 2 | M22: 4 | N22: 11 | O22: 15 | P22: 3 | Q22: =SUM(C22:P22) -> 70 | R22: =Q22/$Q$15 -> 0.064043916
B23: Carona criança | C23: 3 | D23: 0 | E23: 0 | F23: 0 | G23: 3 | H23: 2 | I23: 5 | J23: 5 | K23: 0 | L23: 0 | M23: 0 | N23: 0 | O23: 0 | P23: 1 | Q23: =SUM(C23:P23) -> 19 | R23: =Q23/$Q$15 -> 0.017383349
B24: Carona mulher | C24: 0 | D24: 8 | E24: 0 | F24: 1 | G24: 3 | H24: 4 | I24: 0 | J24: 1 | K24: 4 | L24: 3 | M24: 2 | N24: 6 | O24: 5 | P24: 0 | Q24: =SUM(C24:P24) -> 37 | R24: =Q24/$Q$15 -> 0.033851784
B25: Carona homem | C25: 0 | D25: 0 | E25: 1 | F25: 2 | G25: 0 | H25: 1 | I25: 0 | J25: 0 | K25: 0 | L25: 0 | M25: 0 | N25: 0 | O25: 1 | P25: 0 | Q25: =SUM(C25:P25) -> 5 | R25: =Q25/$Q$15 -> 0.0045745654
B26: Cargueira | C26: 9 | D26: 13 | E26: 20 | F26: 20 | G26: 25 | H26: 25 | I26: 29 | J26: 7 | K26: 19 | L26: 17 | M26: 18 | N26: 16 | O26: 7 | P26: 6 | Q26: =SUM(C26:P26) -> 231 | R26: =Q26/$Q$15 -> 0.21134492
B27: Adaptada a carga | C27: 0 | D27: 0 | E27: 0 | F27: 3 | G27: 0 | H27: 0 | I27: 4 | J27: 0 | K27: 4 | L27: 2 | M27: 1 | N27: 5 | O27: 7 | P27: 1 | Q27: =SUM(C27:P27) -> 27
B28: Serviço | C28: 5 | D28: 7 | E28: 9 | F28: 11 | G28: 10 | H28: 5 | I28: 3 | J28: 0 | K28: 12 | L28: 0 | M28: 10 | N28: 6 | O28: 4 | P28: 2 | Q28: =SUM(C28:P28) -> 84 | R28: =Q28/$Q$15 -> 0.076852699
B29: Serviço App | Q29: =SUM(C29:P29) -> 0
B30: Contramao | C30: 21 | D30: 12 | E30: 13 | F30: 11 | G30: 22 | H30: 31 | I30: 14 | J30: 3 | K30: 16 | L30: 13 | M30: 21 | N30: 17 | O30: 7 | P30: 1 | Q30: =SUM(C30:P30) -> 202 | R30: =Q30/$Q$15 -> 0.18481244
B31: Contramão para conversão | C31: 0 | D31: 0 | E31: 11 | F31: 14 | G31: 5 | H31: 5 | I31: 18 | J31: 9 | K31: 19 | L31: 16 | M31: 1 | N31: 18 | O31: 25 | P31: 23 | Q31: =SUM(C31:P31) -> 164 | R31: =Q31/$Q$15 -> 0.15004575
B32: Calçada | C32: 3 | D32: 5 | E32: 3 | F32: 6 | G32: 10 | H32: 12 | I32: 3 | J32: 1 | K32: 2 | L32: 3 | M32: 0 | N32: 2 | O32: 1 | P32: 4 | Q32: =SUM(C32:P32) -> 55 | R32: =Q32/$Q$15 -> 0.05032022
A34: Dados qualitativos das observações
B35: Característica | C35: 6 | D35: 7 | E35: 8 | F35: 9 | G35: 10 | H35: 11 | I35: 12 | J35: 13 | K35: 14 | L35: 15 | M35: 16 | N35: 17 | O35: 18 | P35: 19 | Q35: TOTAL | R35: %
B36: Bike PE | C36: 0 | D36: 0 | E36: 0 | F36: 0 | G36: 0 | H36: 5 | I36: 2 | J36: 2 | K36: 4 | L36: 1 | M36: 3 | N36: 5 | O36: 7 | P36: 7 | Q36: =SUM(C36:P36) -> 36 | R36: =Q36/$Q$15 -> 0.032936871
B37: Triciclo | C37: 0 | D37: 0 | E37: 0 | F37: 0 | G37: 1 | H37: 0 | I37: 0 | J37: 1 | K37: 0 | L37: 2 | M37: 0 | N37: 0 | O37: 0 | P37: 0 | Q37: =SUM(C37:P37) -> 4 | R37: =Q37/$Q$15 -> 0.0036596523
B38: Eletrica | C38: 0 | D38: 0 | E38: 0 | F38: 0 | G38: 0 | H38: 0 | I38: 0 | J38: 1 | K38: 0 | L38: 0 | M38: 1 | N38: 0 | O38: 0 | P38: 0 | Q38: =SUM(C38:P38) -> 2 | R38: =Q38/$Q$15 -> 0.0018298262
B39: Skate | C39: 0 | D39: 0 | E39: 0 | F39: 0 | G39: 0 | H39: 0 | I39: 2 | J39: 0 | K39: 0 | L39: 0 | M39: 1 | N39: 0 | O39: 0 | P39: 0 | Q39: =SUM(C39:P39) -> 3 | R39: =Q39/$Q$15 -> 0.0027447392
B40: Grupos de pedal | I40: 0 | J40: 0 | M40: 0 | N40: 0 | O40: 0 | Q40: =SUM(C40:P40) -> 0 | R40: =Q40/$Q$15 -> 0
B41: Faixa Azul | I41: 0 | J41: 0 | M41: 0 | N41: 0 | O41: 0
B42: Pedestre empurrando | I42: 2 | J42: 3 | M42: 3 | N42: 1 | O42: 0

Sheet CONFFLUXO
A1: =Fluxo!A2 -> TOTAL | F1: 2 | G1: {=TRANSPOSE(Dados!2:2)} -> ORIGEM
F2: 3 | G2: DESTINO
A3: =Dados!A3 -> Santo Amaro | B3: =Dados!B3 -> Espinheiro | F3: 4 | G3: 6 | Q3: =HLOOKUP($A$1,Dados!$C$2:$R$14,F1,0) -> 150
A4: =Dados!A4 -> Santo Amaro | B4: =Dados!B4 -> Boa Vista | F4: 5 | G4: 7 | Q4: =HLOOKUP($A$1,Dados!$C$2:$R$14,F2,0) -> 19
A5: =Dados!A5 -> Santo Amaro | B5: =Dados!B5 -> Bairro do Recife | F5: 6 | G5: 8 | Q5: =HLOOKUP($A$1,Dados!$C$2:$R$14,F3,0) -> 16
A6: =Dados!A6 -> Bairro do Recife | B6: =Dados!B6 -> Santo Amaro | F6: 7 | G6: 9 | Q6: =HLOOKUP($A$1,Dados!$C$2:$R$14,F4,0) -> 62
A7: =Dados!A7 -> Bairro do Recife | B7: =Dados!B7 -> Espinheiro | F7: 8 | G7: 10 | Q7: =HLOOKUP($A$1,Dados!$C$2:$R$14,F5,0) -> 332
A8: =Dados!A8 -> Bairro do Recife | B8: =Dados!B8 -> Boa Vista | F8: 9 | G8: 11 | Q8: =HLOOKUP($A$1,Dados!$C$2:$R$14,F6,0) -> 18
A9: =Dados!A9 -> Boa Vista | B9: =Dados!B9 -> Bairro do Recife | F9: 10 | G9: 12 | Q9: =HLOOKUP($A$1,Dados!$C$2:$R$14,F7,0) -> 43
A10: =Dados!A10 -> Boa Vista | B10: =Dados!B10 -> Santo Amaro | F10: 11 | G10: 13 | Q10: =HLOOKUP($A$1,Dados!$C$2:$R$14,F8,0) -> 249
A11: =Dados!A11 -> Boa Vista | B11: =Dados!B11 -> Espinheiro | F11: 12 | G11: 14 | Q11: =HLOOKUP($A$1,Dados!$C$2:$R$14,F9,0) -> 27
A12: =Dados!A12 -> Espinheiro | B12: =Dados!B12 -> Boa Vista | F12: 13 | G12: 15 | Q12: =HLOOKUP($A$1,Dados!$C$2:$R$14,F10,0) -> 31
A13: =Dados!A13 -> Espinheiro | B13: =Dados!B13 -> Bairro do Recife | G13: 16 | Q13: =HLOOKUP($A$1,Dados!$C$2:$R$14,F11,0) -> 212
A14: =Dados!A14 -> Espinheiro | B14: =Dados!B14 -> Santo Amaro | G14: 17 | Q14: =HLOOKUP($A$1,Dados!$C$2:$R$14,F12,0) -> 373
G15: 18
G16: 19
G17: TOTAL
G18: %

Sheet Gráficos
A1: Ciclistas por hora
A2: Horário início | B2: =Dados!C2 -> 6 | C2: =Dados!D2 -> 7 | D2: =Dados!E2 -> 8 | E2: =Dados!F2 -> 9 | F2: =Dados!G2 -> 10 | G2: =Dados!H2 -> 11 | H2: =Dados!I2 -> 12 | I2: =Dados!J2 -> 13 | ... O2: =Dados!P2 -> 19
A3: Homens | B3: =Dados!C15-B4-B5 -> 73 | C3: =Dados!D15-C4-C5 -> 76 | D3: =Dados!E15-D4-D5 -> 90 | E3: =Dados!F15-E4-E5 -> 99 | F3: =Dados!G15-F4-F5 -> 109 | G3: =Dados!H15-G4-G5 -> 116 | H3: =Dados!I15-H4-H5 -> 117 | I3: =Dados!J15-I4-I5 -> 67 | ... O3: =Dados!P15-O4-O5 -> 81
A4: Mulheres | B4: =Dados!C20 -> 6 | C4: =Dados!D20 -> 13 | D4: =Dados!E20 -> 13 | E4: =Dados!F20 -> 1 | F4: =Dados!G20 -> 6 | G4: =Dados!H20 -> 8 | H4: =Dados!I20 -> 15 | I4: =Dados!J20 -> 8 | ... O4: =Dados!P20 -> 8
A5: Crianças e adolescentes | B5: =Dados!C21 -> 0 | C5: =Dados!D21 -> 0 | D5: =Dados!E21 -> 0 | E5: =Dados!F21 -> 0 | F5: =Dados!G21 -> 1 | G5: =Dados!H21 -> 6 | H5: =Dados!I21 -> 2 | I5: =Dados!J21 -> 1 | ... O5: =Dados!P21 -> 4
A7: Ciclistas por hora %
A8: Horário | B8: 6 | C8: 7 | D8: 8 | E8: 9 | F8: 10 | G8: 11 | H8: 12 | I8: 13 | J8: 14 | K8: 15 | L8: 16 | M8: 17 | N8: 18 | O8: 19
A9: Mulheres | B9: =B4/Dados!C$15 -> 0.075949367 | C9: =C4/Dados!D$15 -> 0.14606742 | D9: =D4/Dados!E$15 -> 0.12621359 | E9: =E4/Dados!F$15 -> 0.01 | F9: =F4/Dados!G$15 -> 0.051724138 | G9: =G4/Dados!H$15 -> 0.061538462 | H9: =H4/Dados!I$15 -> 0.1119403 | I9: =I4/Dados!J$15 -> 0.10526316 | ... O9: =O4/Dados!P$15 -> 0.086021505
A10: Crianças e adolescentes | B10: =B5/Dados!C$15 -> 0 | C10: =C5/Dados!D$15 -> 0 | D10: =D5/Dados!E$15 -> 0 | E10: =E5/Dados!F$15 -> 0 | F10: =F5/Dados!G$15 -> 0.0086206897 | G10: =G5/Dados!H$15 -> 0.046153846 | H10: =H5/Dados!I$15 -> 0.014925373 | I10: =I5/Dados!J$15 -> 0.013157895 | ... O10: =O5/Dados!P$15 -> 0.043010753
A12: =Dados!B19 -> Característica | B12: =Dados!R19 -> %
A13: =Dados!B20 -> Mulher | B13: =Dados!R20 -> 0.088120104
A14: =Dados!B21 -> Crianças e adolescentes | B14: =Dados!R21 -> 0.019582245
A15: =Dados!B22 -> Capacete | B15: =Dados!R22 -> 0.048302872
A16: Caronas | B16: =SUM(Dados!R31:R33) -> 0.05613577
A17: =Dados!B34 -> Cargueira | B17: =Dados!R34 -> 0.17362924
A18: =Dados!B36 -> Serviço | B18: =Dados!R36 -> 0.065926893
A19: =Dados!B38 -> Contramao | B19: =Dados!R38 -> 0.17624021
A20: =Dados!B27 -> Calçada | B20: =Dados!R27 -> 0.054830287

Sheet Fluxo
A1: HORÁRIO | E1: =UPPER(CONFFLUXO!A3) -> SANTO AMARO
A2: TOTAL | E2: =SUM(E3:G3) -> 185
E3: =CONFFLUXO!Q3 -> 150 | F3: =CONFFLUXO!Q4 -> 19 | G3: =CONFFLUXO!Q5 -> 16
A5: =UPPER(CONFFLUXO!A12) -> ESPINHEIRO | B5: =SUM(C5:C7) -> 616 | C5: =CONFFLUXO!Q14 -> 373 | I5: =CONFFLUXO!Q6 -> 62 | J5: =SUM(I5:I7) -> 412 | K5: =UPPER(CONFFLUXO!A6) -> BAIRRO DO RECIFE
C6: =CONFFLUXO!Q13 -> 212 | F6: =SUM(E3:G3,I5:I7,E9:G9,C5:C7) -> 1532 | I6: =CONFFLUXO!Q7 -> 332
C7: =CONFFLUXO!Q12 -> 31 | I7: =CONFFLUXO!Q8 -> 18
E9: =CONFFLUXO!Q11 -> 27 | F9: =CONFFLUXO!Q10 -> 249 | G9: =CONFFLUXO!Q9 -> 43
E10: =SUM(E9:G9) -> 319
E11: =UPPER(CONFFLUXO!A9) -> BOA VISTA | K11: =MAX(3:3,I:I,9:9,C:C) -> 373
