Workbook

Sheet Resumo
A1: Cruzamento | B1: Av. Pres. Kennedy x Av. Antonio da Costa Azevedo
A2: Data | B2: 44482
A3: Coordenadas Geográficas | B3: -8.01313, -34.8724
A4: Relatório | B4: https://drive.google.com/file/d/1AbL1eCwbVc7cMkhXR7Amhx06A0LO9WA-/view?usp=sharing
A5: Total | B5: =Dados!R15 -> 4845
A6: Máximo em um hora | B6: =MAX(Dados!D15:Q15) -> 573
A7: Mulher | B7: =Dados!S20 -> 0.076780186
A8: Crianças e adolescentes | B8: =Dados!S21 -> 0.018163055
A9: Capacete | B9: =Dados!S22 -> 0.018575851
A10: Caronas | B10: =Dados!S23 -> 0.04871001
A11: Cargueiras | B11: =Dados!S24 -> 0.2245614
A12: Serviço | B12: =Dados!S25 -> 0.025799794
A13: Contramão | B13: =Dados!S26 -> 0.21919505
A14: Calçada | B14: =Dados!S27 -> 0.018575851

Sheet Dados
B1: Dados quantitativos e sentido de deslocamento
B2: ORIGEM | C2: DESTINO | D2: 6 | E2: 7 | F2: 8 | G2: 9 | H2: 10 | I2: 11 | J2: 12 | K2: 13 | L2: 14 | M2: 15 | N2: 16 | O2: 17 | P2: 18 | Q2: 19 | R2: TOTAL | S2: %
B3: Caixa D'água | C3: =B12 -> Peixinhos | D3: 42 | E3: 44 | F3: 55 | G3: 32 | H3: 50 | I3: 32 | J3: 38 | K3: 40 | L3: 28 | M3: 25 | N3: 50 | O3: 46 | P3: 42 | Q3: 27 | R3: =SUM(D3:Q3) -> 551 | S3: =R3/$R$15 -> 0.11372549
B4: =B3 -> Caixa D'água | C4: =B9 -> Olinda | D4: 69 | E4: 67 | F4: 59 | G4: 51 | H4: 52 | I4: 45 | J4: 56 | K4: 38 | L4: 26 | M4: 23 | N4: 44 | O4: 68 | P4: 50 | Q4: 28 | R4: =SUM(D4:Q4) -> 676 | S4: =R4/$R$15 -> 0.13952528
B5: =B3 -> Caixa D'água | C5: =B6 -> Jardim Brasil | D5: 4 | E5: 12 | F5: 10 | G5: 7 | H5: 12 | I5: 10 | J5: 18 | K5: 15 | L5: 7 | M5: 8 | N5: 7 | O5: 16 | P5: 15 | Q5: 10 | R5: =SUM(D5:Q5) -> 151 | S5: =R5/$R$15 -> 0.031166151
B6: Jardim Brasil | C6: =B3 -> Caixa D'água | D6: 14 | E6: 8 | F6: 10 | G6: 15 | H6: 19 | I6: 9 | J6: 18 | K6: 13 | L6: 6 | M6: 5 | N6: 17 | O6: 33 | P6: 14 | Q6: 9 | R6: =SUM(D6:Q6) -> 190 | S6: =R6/$R$15 -> 0.039215686
B7: =B6 -> Jardim Brasil | C7: =B12 -> Peixinhos | D7: 57 | E7: 63 | F7: 38 | G7: 35 | H7: 36 | I7: 45 | J7: 41 | K7: 36 | L7: 22 | M7: 22 | N7: 45 | O7: 71 | P7: 45 | Q7: 30 | R7: =SUM(D7:Q7) -> 586 | S7: =R7/$R$15 -> 0.12094943
B8: =B6 -> Jardim Brasil | C8: =B9 -> Olinda | D8: 16 | E8: 22 | F8: 19 | G8: 18 | H8: 18 | I8: 12 | J8: 15 | K8: 15 | L8: 11 | M8: 15 | N8: 21 | O8: 35 | P8: 13 | Q8: 10 | R8: =SUM(D8:Q8) -> 240 | S8: =R8/$R$15 -> 0.049535604
B9: Olinda | C9: =B6 -> Jardim Brasil | D9: 16 | E9: 18 | F9: 26 | G9: 39 | H9: 21 | I9: 20 | J9: 34 | K9: 20 | L9: 25 | M9: 25 | N9: 33 | O9: 64 | P9: 48 | Q9: 14 | R9: =SUM(D9:Q9) -> 403 | S9: =R9/$R$15 -> 0.083178535
B10: =B9 -> Olinda | C10: =B3 -> Caixa D'água | D10: 38 | E10: 55 | F10: 43 | G10: 39 | H10: 62 | I10: 32 | J10: 48 | K10: 36 | L10: 36 | M10: 41 | N10: 77 | O10: 80 | P10: 70 | Q10: 28 | R10: =SUM(D10:Q10) -> 685 | S10: =R10/$R$15 -> 0.14138287
B11: =B9 -> Olinda | C11: =B12 -> Peixinhos | D11: 7 | E11: 19 | F11: 26 | G11: 16 | H11: 23 | I11: 19 | J11: 17 | K11: 13 | L11: 16 | M11: 9 | N11: 21 | O11: 31 | P11: 7 | Q11: 13 | R11: =SUM(D11:Q11) -> 237 | S11: =R11/$R$15 -> 0.048916409
B12: Peixinhos | C12: =B9 -> Olinda | D12: 7 | E12: 12 | F12: 29 | G12: 11 | H12: 19 | I12: 19 | J12: 11 | K12: 8 | L12: 9 | M12: 3 | N12: 10 | O12: 11 | P12: 8 | Q12: 7 | R12: =SUM(D12:Q12) -> 164 | S12: =R12/$R$15 -> 0.033849329
B13: =B12 -> Peixinhos | C13: =B6 -> Jardim Brasil | D13: 27 | E13: 51 | F13: 35 | G13: 25 | H13: 29 | I13: 35 | J13: 25 | K13: 24 | L13: 31 | M13: 41 | N13: 44 | O13: 65 | P13: 50 | Q13: 40 | R13: =SUM(D13:Q13) -> 522 | S13: =R13/$R$15 -> 0.10773994
B14: =B12 -> Peixinhos | C14: =B3 -> Caixa D'água | D14: 21 | E14: 30 | F14: 29 | G14: 27 | H14: 42 | I14: 37 | J14: 32 | K14: 27 | L14: 30 | M14: 22 | N14: 32 | O14: 53 | P14: 38 | Q14: 20 | R14: =SUM(D14:Q14) -> 440 | S14: =R14/$R$15 -> 0.090815273
C15: TOTAL | D15: =SUM(D3:D14) -> 318 | E15: =SUM(E3:E14) -> 401 | F15: =SUM(F3:F14) -> 379 | G15: =SUM(G3:G14) -> 315 | H15: =SUM(H3:H14) -> 383 | I15: =SUM(I3:I14) -> 315 | J15: =SUM(J3:J14) -> 353 | K15: =SUM(K3:K14) -> 285 | ... Q15: =SUM(Q3:Q14) -> 236 | R15: =SUM(R$3:R$14) -> 4845
C16: Percentual | D16: =D15/$R$15 -> 0.065634675 | E16: =E15/$R$15 -> 0.082765738 | F16: =F15/$R$15 -> 0.078224974 | G16: =G15/$R$15 -> 0.06501548 | H16: =H15/$R$15 -> 0.079050568 | I16: =I15/$R$15 -> 0.06501548 | J16: =J15/$R$15 -> 0.072858617 | K16: =K15/$R$15 -> 0.058823529 | ... Q16: =Q15/$R$15 -> 0.04871001 | R16: =SUM(D16:Q16) -> 1
C18: Dados qualitativos padrões
C19: Característica | D19: 6 | E19: 7 | F19: 8 | G19: 9 | H19: 10 | I19: 11 | J19: 12 | K19: 13 | L19: 14 | M19: 15 | N19: 16 | O19: 17 | P19: 18 | Q19: 19 | R19: TOTAL | S19: %
C20: Mulher | D20: 12 | E20: 36 | F20: 24 | G20: 28 | H20: 19 | I20: 23 | J20: 19 | K20: 34 | L20: 14 | M20: 33 | N20: 39 | O20: 40 | P20: 30 | Q20: 21 | R20: =SUM(D20:Q20) -> 372 | S20: =R20/$R$15 -> 0.076780186
C21: Crianças e adolescentes | D21: 0 | E21: 1 | F21: 3 | G21: 2 | H21: 10 | I21: 12 | J21: 18 | K21: 3 | L21: 13 | M21: 12 | N21: 7 | O21: 5 | P21: 0 | Q21: 2 | R21: =SUM(D21:Q21) -> 88 | S21: =R21/$R$15 -> 0.018163055
C22: Capacete | D22: 10 | E22: 13 | F22: 3 | G22: 7 | H22: 6 | I22: 1 | J22: 6 | K22: 5 | L22: 2 | M22: 2 | N22: 6 | O22: 9 | P22: 11 | Q22: 9 | R22: =SUM(D22:Q22) -> 90 | S22: =R22/$R$15 -> 0.018575851
C23: Caronas | D23: =SUM(D32:D34) -> 7 | E23: =SUM(E32:E34) -> 16 | F23: =SUM(F32:F34) -> 6 | G23: =SUM(G32:G34) -> 10 | H23: =SUM(H32:H34) -> 10 | I23: =SUM(I32:I34) -> 27 | J23: =SUM(J32:J34) -> 16 | K23: =SUM(K32:K34) -> 21 | ... Q23: =SUM(Q32:Q34) -> 24 | R23: =SUM(D23:Q23) -> 236 | S23: =R23/$R$15 -> 0.04871001
C24: Cargueiras | D24: =SUM(D35:D36) -> 67 | E24: =SUM(E35:E36) -> 88 | F24: =SUM(F35:F36) -> 124 | G24: =SUM(G35:G36) -> 104 | H24: =SUM(H35:H36) -> 92 | I24: =SUM(I35:I36) -> 90 | J24: =SUM(J35:J36) -> 59 | K24: =SUM(K35:K36) -> 59 | ... Q24: =SUM(Q35:Q36) -> 35 | R24: =SUM(D24:Q24) -> 1088 | S24: =R24/$R$15 -> 0.2245614
C25: Serviço | D25: =SUM(D37:D38) -> 3 | E25: =SUM(E37:E38) -> 5 | F25: =SUM(F37:F38) -> 15 | G25: =SUM(G37:G38) -> 10 | H25: =SUM(H37:H38) -> 20 | I25: =SUM(I37:I38) -> 14 | J25: =SUM(J37:J38) -> 15 | K25: =SUM(K37:K38) -> 5 | ... Q25: =SUM(Q37:Q38) -> 3 | R25: =SUM(D25:Q25) -> 125 | S25: =R25/$R$15 -> 0.025799794
C26: Contramão | D26: =SUM(D39:D40) -> 61 | E26: =SUM(E39:E40) -> 85 | F26: =SUM(F39:F40) -> 57 | G26: =SUM(G39:G40) -> 71 | H26: =SUM(H39:H40) -> 60 | I26: =SUM(I39:I40) -> 70 | J26: =SUM(J39:J40) -> 60 | K26: =SUM(K39:K40) -> 44 | ... Q26: =SUM(Q39:Q40) -> 64 | R26: =SUM(D26:Q26) -> 1062 | S26: =R26/$R$15 -> 0.21919505
C27: Calçada | D27: 5 | E27: 12 | F27: 11 | G27: 9 | H27: 4 | I27: 2 | J27: 3 | K27: 4 | L27: 4 | M27: 4 | N27: 4 | O27: 10 | P27: 13 | Q27: 5 | R27: =SUM(D27:Q27) -> 90 | S27: =R27/$R$15 -> 0.018575851
C30: Dados qualitativos das observações
C31: Característica | D31: 6 | E31: 7 | F31: 8 | G31: 9 | H31: 10 | I31: 11 | J31: 12 | K31: 13 | L31: 14 | M31: 15 | N31: 16 | O31: 17 | P31: 18 | Q31: 19 | R31: TOTAL | S31: %
C32: Carona criança | D32: 5 | E32: 8 | F32: 4 | G32: 9 | H32: 5 | I32: 20 | J32: 11 | K32: 11 | L32: 4 | M32: 1 | N32: 12 | O32: 15 | P32: 9 | Q32: 9 | R32: =SUM(D32:Q32) -> 123 | S32: =R32/$R$15 -> 0.025386997
C33: Carona mulher | D33: 2 | E33: 7 | F33: 1 | G33: 0 | H33: 4 | I33: 5 | J33: 3 | K33: 6 | L33: 7 | M33: 8 | N33: 3 | O33: 18 | P33: 12 | Q33: 14 | R33: =SUM(D33:Q33) -> 90 | S33: =R33/$R$15 -> 0.018575851
C34: Carona homem | D34: 0 | E34: 1 | F34: 1 | G34: 1 | H34: 1 | I34: 2 | J34: 2 | K34: 4 | L34: 3 | M34: 3 | N34: 1 | O34: 1 | P34: 2 | Q34: 1 | R34: =SUM(D34:Q34) -> 23 | S34: =R34/$R$15 -> 0.004747162
C35: Cargueira tradicional | D35: 30 | E35: 49 | F35: 82 | G35: 73 | H35: 67 | I35: 69 | J35: 45 | K35: 44 | L35: 39 | M35: 63 | N35: 67 | O35: 57 | P35: 23 | Q35: 21 | R35: =SUM(D35:Q35) -> 729 | S35: =R35/$R$15 -> 0.1504644
C36: Adaptada a carga | D36: 37 | E36: 39 | F36: 42 | G36: 31 | H36: 25 | I36: 21 | J36: 14 | K36: 15 | L36: 22 | M36: 22 | N36: 32 | O36: 25 | P36: 20 | Q36: 14 | R36: =SUM(D36:Q36) -> 359 | S36: =R36/$R$15 -> 0.074097007
C37: Serviço | D37: 1 | E37: 1 | F37: 3 | G37: 6 | H37: 15 | I37: 12 | J37: 8 | K37: 1 | L37: 5 | M37: 6 | N37: 9 | O37: 1 | P37: 0 | Q37: 1 | R37: =SUM(D37:Q37) -> 69 | S37: =R37/$R$15 -> 0.014241486
C38: Serviço APP | D38: 2 | E38: 4 | F38: 12 | G38: 4 | H38: 5 | I38: 2 | J38: 7 | K38: 4 | L38: 3 | M38: 3 | N38: 1 | O38: 3 | P38: 4 | Q38: 2 | R38: =SUM(D38:Q38) -> 56 | S38: =R38/$R$15 -> 0.011558308
C39: Contramão | D39: 57 | E39: 70 | F39: 49 | G39: 60 | H39: 53 | I39: 66 | J39: 51 | K39: 44 | L39: 73 | M39: 89 | N39: 93 | O39: 114 | P39: 98 | Q39: 62 | R39: =SUM(D39:Q39) -> 979 | S39: =R39/$R$15 -> 0.20206398
C40: Contramão para conversão | D40: 4 | E40: 15 | F40: 8 | G40: 11 | H40: 7 | I40: 4 | J40: 9 | K40: 0 | L40: 8 | M40: 9 | N40: 6 | O40: 0 | P40: 0 | Q40: 2 | R40: =SUM(D40:Q40) -> 83 | S40: =R40/$R$15 -> 0.017131063
C41: Triciclo | D41: 0 | E41: 2 | F41: 1 | G41: 1 | H41: 1 | I41: 0 | J41: 0 | K41: 0 | L41: 1 | M41: 0 | N41: 0 | O41: 0 | P41: 1 | Q41: 1 | R41: =SUM(D41:Q41) -> 8 | S41: =R41/$R$15 -> 0.0016511868
C42: Carroça | D42: 0 | E42: 0 | F42: 0 | G42: 6 | H42: 5 | I42: 2 | J42: 1 | K42: 1 | L42: 13 | M42: 3 | N42: 5 | O42: 7 | P42: 0 | Q42: 3 | R42: =SUM(D42:Q42) -> 46 | S42: =R42/$R$15 -> 0.009494324
C43: Elétrica | D43: 0 | E43: 1 | F43: 0 | G43: 1 | H43: 0 | I43: 0 | J43: 2 | K43: 3 | L43: 1 | M43: 1 | N43: 0 | O43: 0 | P43: 0 | Q43: 0 | R43: =SUM(D43:Q43) -> 9 | S43: =R43/$R$15 -> 0.0018575851
...

Sheet CONFFLUXO
A1: =Fluxo!A2 -> TOTAL | F1: 2 | G1: {=TRANSPOSE(Dados!2:2)}
F2: 3 | G2: ORIGEM
A3: =Dados!B3 -> Caixa D'água | B3: =Dados!C3 -> Peixinhos | F3: 4 | G3: DESTINO | Q3: =HLOOKUP($A$1,Dados!$D$2:$S$14,F1,0) -> 551
A4: =Dados!B4 -> Caixa D'água | B4: =Dados!C4 -> Olinda | F4: 5 | G4: 6 | Q4: =HLOOKUP($A$1,Dados!$D$2:$S$14,F2,0) -> 676
A5: =Dados!B5 -> Caixa D'água | B5: =Dados!C5 -> Jardim Brasil | F5: 6 | G5: 7 | Q5: =HLOOKUP($A$1,Dados!$D$2:$S$14,F3,0) -> 151
A6: =Dados!B6 -> Jardim Brasil | B6: =Dados!C6 -> Caixa D'água | F6: 7 | G6: 8 | Q6: =HLOOKUP($A$1,Dados!$D$2:$S$14,F4,0) -> 190
A7: =Dados!B7 -> Jardim Brasil | B7: =Dados!C7 -> Peixinhos | F7: 8 | G7: 9 | Q7: =HLOOKUP($A$1,Dados!$D$2:$S$14,F5,0) -> 586
A8: =Dados!B8 -> Jardim Brasil | B8: =Dados!C8 -> Olinda | F8: 9 | G8: 10 | Q8: =HLOOKUP($A$1,Dados!$D$2:$S$14,F6,0) -> 240
A9: =Dados!B9 -> Olinda | B9: =Dados!C9 -> Jardim Brasil | F9: 10 | G9: 11 | Q9: =HLOOKUP($A$1,Dados!$D$2:$S$14,F7,0) -> 403
A10: =Dados!B10 -> Olinda | B10: =Dados!C10 -> Caixa D'água | F10: 11 | G10: 12 | Q10: =HLOOKUP($A$1,Dados!$D$2:$S$14,F8,0) -> 685
A11: =Dados!B11 -> Olinda | B11: =Dados!C11 -> Peixinhos | F11: 12 | G11: 13 | Q11: =HLOOKUP($A$1,Dados!$D$2:$S$14,F9,0) -> 237
A12: =Dados!B12 -> Peixinhos | B12: =Dados!C12 -> Olinda | F12: 13 | G12: 14 | Q12: =HLOOKUP($A$1,Dados!$D$2:$S$14,F10,0) -> 164
A13: =Dados!B13 -> Peixinhos | B13: =Dados!C13 -> Jardim Brasil | G13: 15 | Q13: =HLOOKUP($A$1,Dados!$D$2:$S$14,F11,0) -> 522
A14: =Dados!B14 -> Peixinhos | B14: =Dados!C14 -> Caixa D'água | G14: 16 | Q14: =HLOOKUP($A$1,Dados!$D$2:$S$14,F12,0) -> 440
G15: 17
G16: 18
G17: 19
G18: TOTAL
G19: %

Sheet Gráficos
A1: Ciclistas por hora
A2: Horário início | B2: =Dados!D2 -> 6 | C2: =Dados!E2 -> 7 | D2: =Dados!F2 -> 8 | E2: =Dados!G2 -> 9 | F2: =Dados!H2 -> 10 | G2: =Dados!I2 -> 11 | H2: =Dados!J2 -> 12 | I2: =Dados!K2 -> 13 | ... O2: =Dados!Q2 -> 19
A3: Homens | B3: =Dados!D15-B4-B5 -> 306 | C3: =Dados!E15-C4-C5 -> 364 | D3: =Dados!F15-D4-D5 -> 352 | E3: =Dados!G15-E4-E5 -> 285 | F3: =Dados!H15-F4-F5 -> 354 | G3: =Dados!I15-G4-G5 -> 280 | H3: =Dados!J15-H4-H5 -> 316 | I3: =Dados!K15-I4-I5 -> 248 | ... O3: =Dados!Q15-O4-O5 -> 213
A4: Mulheres | B4: =Dados!D20 -> 12 | C4: =Dados!E20 -> 36 | D4: =Dados!F20 -> 24 | E4: =Dados!G20 -> 28 | F4: =Dados!H20 -> 19 | G4: =Dados!I20 -> 23 | H4: =Dados!J20 -> 19 | I4: =Dados!K20 -> 34 | ... O4: =Dados!Q20 -> 21
A5: Crianças e adolescentes | B5: =Dados!D21 -> 0 | C5: =Dados!E21 -> 1 | D5: =Dados!F21 -> 3 | E5: =Dados!G21 -> 2 | F5: =Dados!H21 -> 10 | G5: =Dados!I21 -> 12 | H5: =Dados!J21 -> 18 | I5: =Dados!K21 -> 3 | ... O5: =Dados!Q21 -> 2
A7: Ciclistas por hora %
A8: Horário | B8: 6 | C8: 7 | D8: 8 | E8: 9 | F8: 10 | G8: 11 | H8: 12 | I8: 13 | J8: 14 | K8: 15 | L8: 16 | M8: 17 | N8: 18 | O8: 19
A9: Mulheres | B9: =B4/Dados!D$15 -> 0.037735849 | C9: =C4/Dados!E$15 -> 0.089775561 | D9: =D4/Dados!F$15 -> 0.063324538 | E9: =E4/Dados!G$15 -> 0.088888889 | F9: =F4/Dados!H$15 -> 0.049608355 | G9: =G4/Dados!I$15 -> 0.073015873 | H9: =H4/Dados!J$15 -> 0.053824363 | I9: =I4/Dados!K$15 -> 0.11929825 | ... O9: =O4/Dados!Q$15 -> 0.088983051
A10: Crianças e adolescentes | B10: =B5/Dados!D$15 -> 0 | C10: =C5/Dados!E$15 -> 0.0024937656 | D10: =D5/Dados!F$15 -> 0.0079155673 | E10: =E5/Dados!G$15 -> 0.0063492063 | F10: =F5/Dados!H$15 -> 0.026109661 | G10: =G5/Dados!I$15 -> 0.038095238 | H10: =H5/Dados!J$15 -> 0.050991501 | I10: =I5/Dados!K$15 -> 0.010526316 | ... O10: =O5/Dados!Q$15 -> 0.0084745763
A12: =Dados!C19 -> Característica | B12: =Dados!S19 -> %
A13: =Dados!C20 -> Mulher | B13: =Dados!S20 -> 0.076780186
A14: =Dados!C21 -> Crianças e adolescentes | B14: =Dados!S21 -> 0.018163055
A15: =Dados!C22 -> Capacete | B15: =Dados!S22 -> 0.018575851
A16: Caronas | B16: =SUM(Dados!S32:S34) -> 0.04871001
A17: =Dados!C35 -> Cargueira tradicional | B17: =Dados!S35 -> 0.1504644
A18: =Dados!C37 -> Serviço | B18: =Dados!S37 -> 0.014241486
A19: =Dados!C39 -> Contramão | B19: =Dados!S39 -> 0.20206398
A20: =Dados!C27 -> Calçada | B20: =Dados!S27 -> 0.018575851

Sheet Fluxo
A1: HORÁRIO | E1: =UPPER(CONFFLUXO!A3) -> CAIXA D'ÁGUA
A2: TOTAL | E2: =SUM(E3:G3) -> 1378
E3: =CONFFLUXO!Q3 -> 551 | F3: =CONFFLUXO!Q4 -> 676 | G3: =CONFFLUXO!Q5 -> 151
A5: =UPPER(CONFFLUXO!A12) -> PEIXINHOS | B5: =SUM(C5:C7) -> 1126 | C5: =CONFFLUXO!Q14 -> 440 | I5: =CONFFLUXO!Q6 -> 190 | J5: =SUM(I5:I7) -> 1016 | K5: =UPPER(CONFFLUXO!A6) -> JARDIM BRASIL
C6: =CONFFLUXO!Q13 -> 522 | F6: =SUM(E3:G3,I5:I7,E9:G9,C5:C7) -> 4845 | I6: =CONFFLUXO!Q7 -> 586
C7: =CONFFLUXO!Q12 -> 164 | I7: =CONFFLUXO!Q8 -> 240
E9: =CONFFLUXO!Q11 -> 237 | F9: =CONFFLUXO!Q10 -> 685 | G9: =CONFFLUXO!Q9 -> 403
E10: =SUM(E9:G9) -> 1325
E11: =UPPER(CONFFLUXO!A9) -> OLINDA | K11: =MAX(3:3,I:I,9:9,C:C) -> 685

Sheet Coordenadas
A1: Norte
A2: Leste
A3: Sul
A4: Oeste
F26: a
